Workbook

Sheet Справка
A1: Расчёт систем внутреннего водопровода В1 и канализации К1 жилого здания — курсовой проект, вариант 3 (НИУ МГСУ, кафедра «Водоснабжение и водоотведение»)
A3: Как пользоваться:
A4: 1. Жёлтые ячейки с синим шрифтом — исходные данные; их можно менять. Всё остальное считается формулами.
A5: 2. Лист «Исходные»: этажность, секции, заселённость, типы квартир и приборы, тип водопотребителей (выпадающий список по табл. А.2).
A6: 3. Лист «Расходы»: суточные, среднечасовые, секундные и часовые расходы общей, горячей и холодной воды (как на занятиях).
A7: 4. Лист «В1»: гидравлический расчёт по диктующему направлению — длины, числа приборов и диаметры вводятся, α, q, v, 1000i, потери считаются.
A8: 5. Лист «Напор»: подбор счётчиков, требуемый напор, напор и подача насосной установки, проверка гидростатического напора по этажам.
A9: 6. Лист «К1»: стояки, горизонтальные участки (K_s, q^sL, h/d, V, условие незасоряемости), отметки лотков и глубина колодцев.
A10: 7. Листы «ТаблА2», «ТаблБ1», «ТаблБ2», «Табл5_1», «Табл12_1», «Трубы», «Павловский» — справочные таблицы СП и вспомогательные расчёты.
A12: Нормативная база: СП 30.13330.2020 «Внутренний водопровод и канализация зданий» (с изменениями № 1–5); СП 32.13330.2018 «Канализация. Наружные сети и сооружения» (с изменениями);
A13: Ф.А. Шевелёв, А.Ф. Шевелёв «Таблицы для гидравлического расчёта водопроводных труб»; А.А. Лукиных, Н.А. Лукиных «Таблицы для гидравлического расчёта канализационных сетей и дюкеров».
A15: α определяется по табл. Б.2 (при P > 0,1 и N ≤ 200 — по табл. Б.1) с линейной интерполяцией между строками: y = y1 + (x − x1)·(y2 − y1)/(x2 − x1).
... A18: Условные обозначения: синий — исходные данные; чёрный — формулы; зелёный — ссылки на другие листы; светло-зелёная заливка — основные результаты.

Sheet Исходные
A1: Исходные данные (вариант 3). Жёлтые ячейки — вводимые данные, остальное считается формулами
A3: Этажность n_эт | B3: 11
A4: Число секций n_сек | B4: 2
A5: Заселённость N_кв.жит, чел./кв. | B5: 3.8
A6: Высота этажа, м | B6: 3.2
A7: Расчётное время T, ч | B7: 24
A8: Гарантийный напор H_гар, м | B8: 14
A9: Глубина промерзания, м | B9: 1.7
A11: Водопотребители (табл. А.2) | B11: ванны от 1500 мм с душами
A13: Квартиры на этаже одной секции
A14: Тип квартиры | B14: Квартир на этаже секции | C14: Приборов с холодной водой | D14: Приборов с горячей водой
A15: 3–4-комнатная (санузел + кухня: мойка, умывальник, ванна, унитаз) | B15: 3 | C15: 4 | D15: 3
A16: — | B16: 0 | C16: 0 | D16: 0
A17: — | B17: 0 | C17: 0 | D17: 0
A19: Квартир на этаже здания n_кв | B19: =SUM(B15:B17)*B4 -> 6 | C19: Σ квартир секции × n_сек
A20: Всего квартир | B20: =B19*B3 -> 66 | C20: n_кв · n_эт
A21: Число водопотребителей U, чел. | B21: =ROUNDUP(B5*B19*B3,0) -> 251 | C21: U = N_кв.жит · n_кв · n_эт (округление вверх)
A22: Число приборов N (холодная и общая вода) | B22: =SUMPRODUCT(B15:B17,C15:C17)*B4*B3 -> 264 | C22: N = Σ(n_пр · n_кв) · n_эт
A23: Число приборов N^h (горячая вода) | B23: =SUMPRODUCT(B15:B17,D15:D17)*B4*B3 -> 198 | C23: без унитазов
A25: Нормы по табл. А.2 для выбранных водопотребителей
A26: q_u^tot, л/сут | B26: =INDEX(A2_TAB,MATCH($B$11,A2_NAME,0),2) -> 180
A27: q_u^h, л/сут | B27: =INDEX(A2_TAB,MATCH($B$11,A2_NAME,0),3) -> 70
A28: q_hr,u^tot, л/ч | B28: =INDEX(A2_TAB,MATCH($B$11,A2_NAME,0),4) -> 11.6
A29: q_hr,u^h, л/ч | B29: =INDEX(A2_TAB,MATCH($B$11,A2_NAME,0),5) -> 6.5
A30: q_0^tot, л/с | B30: =INDEX(A2_TAB,MATCH($B$11,A2_NAME,0),6) -> 0.3
A31: q_0,hr^tot, л/ч | B31: =INDEX(A2_TAB,MATCH($B$11,A2_NAME,0),7) -> 300
A32: q_0^c=q_0^h, л/с | B32: =INDEX(A2_TAB,MATCH($B$11,A2_NAME,0),8) -> 0.2
A33: q_0,hr^c, л/ч | B33: =INDEX(A2_TAB,MATCH($B$11,A2_NAME,0),9) -> 200
A35: Условные обозначения: синий шрифт на жёлтом — исходные данные; чёрный — формулы; зелёный — ссылки на другие листы.

Sheet Расходы
A1: Расчёт расходов воды (СП 30.13330.2020, разд. 5): суточные, среднечасовые, секундные, часовые
A3: Вода | B3: T, ч | C3: U | D3: N | E3: q_u, л/сут | F3: q_hr,u, л/ч | G3: q_0, л/с | H3: q_0,hr, л/ч | I3: q_u,m, м³/сут | J3: q_T, м³/ч | K3: P | L3: NP | M3: α | N3: q, л/с | O3: P_hr | P3: NP_hr | Q3: α_hr | R3: q_hr, м³/ч
A4: tot | B4: =Исходные!$B$7 -> 24 | C4: =Исходные!$B$21 -> 251 | D4: =Исходные!B22 -> 264 | E4: =Исходные!B26 -> 180 | F4: =Исходные!B28 -> 11.6 | G4: =Исходные!B30 -> 0.3 | H4: =Исходные!B31 -> 300 | I4: =E4*C4/1000 -> 45.18 | J4: =I4/B4 -> 1.8825 | K4: =F4*C4/(G4*D4*3600) -> 0.010211841 | L4: =D4*K4 -> 2.6959259 | M4: =IF(AND(K4>0.1,D4<=200),((1-MIN(1,(MAX(D4,INDEX(B1_N,1))-INDEX(B1_N,MIN(MATCH(MAX(D4,INDEX(B1_N,1)),B1_N,1),ROWS(B1_N)-1)))/(INDEX(B1_N,MIN(MATCH(MAX(D4,INDEX(B1_N,1)),B1_N,1),ROWS(B1_N)-1)+1)-INDEX(B1_N,MIN(MATCH(MAX(D4,INDEX(B1_N,1)),B1_N,1),ROWS(B1_N)-1)))))*((1-MIN(1,(K4-INDEX(B1_P,1,MIN(MATCH(K4,B1_P,1),COLUMNS(B1_P)-1)))/(INDEX(B1_P,1,MIN(MATCH(K4,B1_P,1),COLUMNS(B1_P)-1)+1)-INDEX(B1_P,1,MIN(MATCH(K4,B1_P,1),COLUMNS(B1_P)-1)))))*INDEX(B1_G,MIN(MATCH(MAX(D4,INDEX(B1_N,1)),B1_N,1),ROWS(B1_N)-1),MIN(MATCH(K4,B1_P,1),COLUMNS(B1_P)-1))+MIN(1,(K4-INDEX(B1_P,1,MIN(MATCH(K4,B1_P,1),COLUMNS(B1_P)-1)))/(INDEX(B1_P,1,MIN(MATCH(K4,B1_P,1),COLUMNS(B1_P)-1)+1)-INDEX(B1_P,1,MIN(MATCH(K4,B1_P,1),COLUMNS(B1_P)-1))))*INDEX(B1_G,MIN(MATCH(MAX(D4,INDEX(B1_N,1)),B1_N,1),ROWS(B1_N)-1),MIN(MATCH(K4,B1_P,1),COLUMNS(B1_P)-1)+1))+MIN(1,(MAX(D4,INDEX(B1_N,1))-INDEX(B1_N,MIN(MATCH(MAX(D4,INDEX(B1_N,1)),B1_N,1),ROWS(B1_N)-1)))/(INDEX(B1_N,MIN(MATCH(MAX(D4,INDEX(B1_N,1)),B1_N,1),ROWS(B1_N)-1)+1)-INDEX(B1_N,MIN(MATCH(MAX(D4,INDEX(B1_N,1)),B1_N,1),ROWS(B1_N)-1))))*((1-MIN(1,(K4-INDEX(B1_P,1,MIN(MATCH(K4,B1_P,1),COLUMNS(B1_P)-1)))/(INDEX(B1_P,1,MIN(MATCH(K4,B1_P,1),COLUMNS(B1_P)-1)+1)-INDEX(B1_P,1,MIN(MATCH(K4,B1_P,1),COLUMNS(B1_P)-1)))))*INDEX(B1_G,MIN(MATCH(MAX(D4,INDEX(B1_N,1)),B1_N,1),ROWS(B1_N)-1)+1,MIN(MATCH(K4,B1_P,1),COLUMNS(B1_P)-1))+MIN(1,(K4-INDEX(B1_P,1,MIN(MATCH(K4,B1_P,1),COLUMNS(B1_P)-1)))/(INDEX(B1_P,1,MIN(MATCH(K4,B1_P,1),COLUMNS(B1_P)-1)+1)-INDEX(B1_P,1,MIN(MATCH(K4,B1_P,1),COLUMNS(B1_P)-1))))*INDEX(B1_G,MIN(MATCH(MAX(D4,INDEX(B1_N,1)),B1_N,1),ROWS(B1_N)-1)+1,MIN(MATCH(K4,B1_P,1),COLUMNS(B1_P)-1)+1))),IF((D4*K4)<INDEX(B2_NP,1),0.2,IF((D4*K4)>=INDEX(B2_NP,ROWS(B2_NP)),INDEX(B2_A,ROWS(B2_NP)),INDEX(B2_A,MATCH((D4*K4),B2_NP,1))+((D4*K4)-INDEX(B2_NP,MATCH((D4*K4),B2_NP,1)))*(INDEX(B2_A,MATCH((D4*K4),B2_NP,1)+1)-INDEX(B2_A,MATCH((D4*K4),B2_NP,1)))/(INDEX(B2_NP,MATCH((D4*K4),B2_NP,1)+1)-INDEX(B2_NP,MATCH((D4*K4),B2_NP,1)))))) -> 1.7223704 | N4: =5*G4*M4 -> 2.5835556 | O4: =3600*K4*G4/H4 -> 0.036762626 | P4: =D4*O4 -> 9.7053333 | Q4: =IF(AND(O4>0.1,D4<=200),((1-MIN(1,(MAX(D4,INDEX(B1_N,1))-INDEX(B1_N,MIN(MATCH(MAX(D4,INDEX(B1_N,1)),B1_N,1),ROWS(B1_N)-1)))/(INDEX(B1_N,MIN(MATCH(MAX(D4,INDEX(B1_N,1)),B1_N,1),ROWS(B1_N)-1)+1)-INDEX(B1_N,MIN(MATCH(MAX(D4,INDEX(B1_N,1)),B1_N,1),ROWS(B1_N)-1)))))*((1-MIN(1,(O4-INDEX(B1_P,1,MIN(MATCH(O4,B1_P,1),COLUMNS(B1_P)-1)))/(INDEX(B1_P,1,MIN(MATCH(O4,B1_P,1),COLUMNS(B1_P)-1)+1)-INDEX(B1_P,1,MIN(MATCH(O4,B1_P,1),COLUMNS(B1_P)-1)))))*INDEX(B1_G,MIN(MATCH(MAX(D4,INDEX(B1_N,1)),B1_N,1),ROWS(B1_N)-1),MIN(MATCH(O4,B1_P,1),COLUMNS(B1_P)-1))+MIN(1,(O4-INDEX(B1_P,1,MIN(MATCH(O4,B1_P,1),COLUMNS(B1_P)-1)))/(INDEX(B1_P,1,MIN(MATCH(O4,B1_P,1),COLUMNS(B1_P)-1)+1)-INDEX(B1_P,1,MIN(MATCH(O4,B1_P,1),COLUMNS(B1_P)-1))))*INDEX(B1_G,MIN(MATCH(MAX(D4,INDEX(B1_N,1)),B1_N,1),ROWS(B1_N)-1),MIN(MATCH(O4,B1_P,1),COLUMNS(B1_P)-1)+1))+MIN(1,(MAX(D4,INDEX(B1_N,1))-INDEX(B1_N,MIN(MATCH(MAX(D4,INDEX(B1_N,1)),B1_N,1),ROWS(B1_N)-1)))/(INDEX(B1_N,MIN(MATCH(MAX(D4,INDEX(B1_N,1)),B1_N,1),ROWS(B1_N)-1)+1)-INDEX(B1_N,MIN(MATCH(MAX(D4,INDEX(B1_N,1)),B1_N,1),ROWS(B1_N)-1))))*((1-MIN(1,(O4-INDEX(B1_P,1,MIN(MATCH(O4,B1_P,1),COLUMNS(B1_P)-1)))/(INDEX(B1_P,1,MIN(MATCH(O4,B1_P,1),COLUMNS(B1_P)-1)+1)-INDEX(B1_P,1,MIN(MATCH(O4,B1_P,1),COLUMNS(B1_P)-1)))))*INDEX(B1_G,MIN(MATCH(MAX(D4,INDEX(B1_N,1)),B1_N,1),ROWS(B1_N)-1)+1,MIN(MATCH(O4,B1_P,1),COLUMNS(B1_P)-1))+MIN(1,(O4-INDEX(B1_P,1,MIN(MATCH(O4,B1_P,1),COLUMNS(B1_P)-1)))/(INDEX(B1_P,1,MIN(MATCH(O4,B1_P,1),COLUMNS(B1_P)-1)+1)-INDEX(B1_P,1,MIN(MATCH(O4,B1_P,1),COLUMNS(B1_P)-1))))*INDEX(B1_G,MIN(MATCH(MAX(D4,INDEX(B1_N,1)),B1_N,1),ROWS(B1_N)-1)+1,MIN(MATCH(O4,B1_P,1),COLUMNS(B1_P)-1)+1))),IF((D4*O4)<INDEX(B2_NP,1),0.2,IF((D4*O4)>=INDEX(B2_NP,ROWS(B2_NP)),INDEX(B2_A,ROWS(B2_NP)),INDEX(B2_A,MATCH((D4*O4),B2_NP,1))+((D4*O4)-INDEX(B2_NP,MATCH((D4*O4),B2_NP,1)))*(INDEX(B2_A,MATCH((D4*O4),B2_NP,1)+1)-INDEX(B2_A,MATCH((D4*O4),B2_NP,1)))/(INDEX(B2_NP,MATCH((D4*O4),B2_NP,1)+1)-INDEX(B2_NP,MATCH((D4*O4),B2_NP,1)))))) -> 4.0386 | R4: =0.005*Q4*H4 -> 6.0579
A5: h | B5: =Исходные!$B$7 -> 24 | C5: =Исходные!$B$21 -> 251 | D5: =Исходные!B23 -> 198 | E5: =Исходные!B27 -> 70 | F5: =Исходные!B29 -> 6.5 | G5: =Исходные!B32 -> 0.2 | H5: =Исходные!B33 -> 200 | I5: =E5*C5/1000 -> 17.57 | J5: =I5/B5 -> 0.73208333 | K5: =F5*C5/(G5*D5*3600) -> 0.011444304 | L5: =D5*K5 -> 2.2659722 | M5: =IF(AND(K5>0.1,D5<=200),((1-MIN(1,(MAX(D5,INDEX(B1_N,1))-INDEX(B1_N,MIN(MATCH(MAX(D5,INDEX(B1_N,1)),B1_N,1),ROWS(B1_N)-1)))/(INDEX(B1_N,MIN(MATCH(MAX(D5,INDEX(B1_N,1)),B1_N,1),ROWS(B1_N)-1)+1)-INDEX(B1_N,MIN(MATCH(MAX(D5,INDEX(B1_N,1)),B1_N,1),ROWS(B1_N)-1)))))*((1-MIN(1,(K5-INDEX(B1_P,1,MIN(MATCH(K5,B1_P,1),COLUMNS(B1_P)-1)))/(INDEX(B1_P,1,MIN(MATCH(K5,B1_P,1),COLUMNS(B1_P)-1)+1)-INDEX(B1_P,1,MIN(MATCH(K5,B1_P,1),COLUMNS(B1_P)-1)))))*INDEX(B1_G,MIN(MATCH(MAX(D5,INDEX(B1_N,1)),B1_N,1),ROWS(B1_N)-1),MIN(MATCH(K5,B1_P,1),COLUMNS(B1_P)-1))+MIN(1,(K5-INDEX(B1_P,1,MIN(MATCH(K5,B1_P,1),COLUMNS(B1_P)-1)))/(INDEX(B1_P,1,MIN(MATCH(K5,B1_P,1),COLUMNS(B1_P)-1)+1)-INDEX(B1_P,1,MIN(MATCH(K5,B1_P,1),COLUMNS(B1_P)-1))))*INDEX(B1_G,MIN(MATCH(MAX(D5,INDEX(B1_N,1)),B1_N,1),ROWS(B1_N)-1),MIN(MATCH(K5,B1_P,1),COLUMNS(B1_P)-1)+1))+MIN(1,(MAX(D5,INDEX(B1_N,1))-INDEX(B1_N,MIN(MATCH(MAX(D5,INDEX(B1_N,1)),B1_N,1),ROWS(B1_N)-1)))/(INDEX(B1_N,MIN(MATCH(MAX(D5,INDEX(B1_N,1)),B1_N,1),ROWS(B1_N)-1)+1)-INDEX(B1_N,MIN(MATCH(MAX(D5,INDEX(B1_N,1)),B1_N,1),ROWS(B1_N)-1))))*((1-MIN(1,(K5-INDEX(B1_P,1,MIN(MATCH(K5,B1_P,1),COLUMNS(B1_P)-1)))/(INDEX(B1_P,1,MIN(MATCH(K5,B1_P,1),COLUMNS(B1_P)-1)+1)-INDEX(B1_P,1,MIN(MATCH(K5,B1_P,1),COLUMNS(B1_P)-1)))))*INDEX(B1_G,MIN(MATCH(MAX(D5,INDEX(B1_N,1)),B1_N,1),ROWS(B1_N)-1)+1,MIN(MATCH(K5,B1_P,1),COLUMNS(B1_P)-1))+MIN(1,(K5-INDEX(B1_P,1,MIN(MATCH(K5,B1_P,1),COLUMNS(B1_P)-1)))/(INDEX(B1_P,1,MIN(MATCH(K5,B1_P,1),COLUMNS(B1_P)-1)+1)-INDEX(B1_P,1,MIN(MATCH(K5,B1_P,1),COLUMNS(B1_P)-1))))*INDEX(B1_G,MIN(MATCH(MAX(D5,INDEX(B1_N,1)),B1_N,1),ROWS(B1_N)-1)+1,MIN(MATCH(K5,B1_P,1),COLUMNS(B1_P)-1)+1))),IF((D5*K5)<INDEX(B2_NP,1),0.2,IF((D5*K5)>=INDEX(B2_NP,ROWS(B2_NP)),INDEX(B2_A,ROWS(B2_NP)),INDEX(B2_A,MATCH((D5*K5),B2_NP,1))+((D5*K5)-INDEX(B2_NP,MATCH((D5*K5),B2_NP,1)))*(INDEX(B2_A,MATCH((D5*K5),B2_NP,1)+1)-INDEX(B2_A,MATCH((D5*K5),B2_NP,1)))/(INDEX(B2_NP,MATCH((D5*K5),B2_NP,1)+1)-INDEX(B2_NP,MATCH((D5*K5),B2_NP,1)))))) -> 1.5487083 | N5: =5*G5*M5 -> 1.5487083 | O5: =3600*K5*G5/H5 -> 0.041199495 | P5: =D5*O5 -> 8.1575 | Q5: =IF(AND(O5>0.1,D5<=200),((1-MIN(1,(MAX(D5,INDEX(B1_N,1))-INDEX(B1_N,MIN(MATCH(MAX(D5,INDEX(B1_N,1)),B1_N,1),ROWS(B1_N)-1)))/(INDEX(B1_N,MIN(MATCH(MAX(D5,INDEX(B1_N,1)),B1_N,1),ROWS(B1_N)-1)+1)-INDEX(B1_N,MIN(MATCH(MAX(D5,INDEX(B1_N,1)),B1_N,1),ROWS(B1_N)-1)))))*((1-MIN(1,(O5-INDEX(B1_P,1,MIN(MATCH(O5,B1_P,1),COLUMNS(B1_P)-1)))/(INDEX(B1_P,1,MIN(MATCH(O5,B1_P,1),COLUMNS(B1_P)-1)+1)-INDEX(B1_P,1,MIN(MATCH(O5,B1_P,1),COLUMNS(B1_P)-1)))))*INDEX(B1_G,MIN(MATCH(MAX(D5,INDEX(B1_N,1)),B1_N,1),ROWS(B1_N)-1),MIN(MATCH(O5,B1_P,1),COLUMNS(B1_P)-1))+MIN(1,(O5-INDEX(B1_P,1,MIN(MATCH(O5,B1_P,1),COLUMNS(B1_P)-1)))/(INDEX(B1_P,1,MIN(MATCH(O5,B1_P,1),COLUMNS(B1_P)-1)+1)-INDEX(B1_P,1,MIN(MATCH(O5,B1_P,1),COLUMNS(B1_P)-1))))*INDEX(B1_G,MIN(MATCH(MAX(D5,INDEX(B1_N,1)),B1_N,1),ROWS(B1_N)-1),MIN(MATCH(O5,B1_P,1),COLUMNS(B1_P)-1)+1))+MIN(1,(MAX(D5,INDEX(B1_N,1))-INDEX(B1_N,MIN(MATCH(MAX(D5,INDEX(B1_N,1)),B1_N,1),ROWS(B1_N)-1)))/(INDEX(B1_N,MIN(MATCH(MAX(D5,INDEX(B1_N,1)),B1_N,1),ROWS(B1_N)-1)+1)-INDEX(B1_N,MIN(MATCH(MAX(D5,INDEX(B1_N,1)),B1_N,1),ROWS(B1_N)-1))))*((1-MIN(1,(O5-INDEX(B1_P,1,MIN(MATCH(O5,B1_P,1),COLUMNS(B1_P)-1)))/(INDEX(B1_P,1,MIN(MATCH(O5,B1_P,1),COLUMNS(B1_P)-1)+1)-INDEX(B1_P,1,MIN(MATCH(O5,B1_P,1),COLUMNS(B1_P)-1)))))*INDEX(B1_G,MIN(MATCH(MAX(D5,INDEX(B1_N,1)),B1_N,1),ROWS(B1_N)-1)+1,MIN(MATCH(O5,B1_P,1),COLUMNS(B1_P)-1))+MIN(1,(O5-INDEX(B1_P,1,MIN(MATCH(O5,B1_P,1),COLUMNS(B1_P)-1)))/(INDEX(B1_P,1,MIN(MATCH(O5,B1_P,1),COLUMNS(B1_P)-1)+1)-INDEX(B1_P,1,MIN(MATCH(O5,B1_P,1),COLUMNS(B1_P)-1))))*INDEX(B1_G,MIN(MATCH(MAX(D5,INDEX(B1_N,1)),B1_N,1),ROWS(B1_N)-1)+1,MIN(MATCH(O5,B1_P,1),COLUMNS(B1_P)-1)+1))),IF((D5*O5)<INDEX(B2_NP,1),0.2,IF((D5*O5)>=INDEX(B2_NP,ROWS(B2_NP)),INDEX(B2_A,ROWS(B2_NP)),INDEX(B2_A,MATCH((D5*O5),B2_NP,1))+((D5*O5)-INDEX(B2_NP,MATCH((D5*O5),B2_NP,1)))*(INDEX(B2_A,MATCH((D5*O5),B2_NP,1)+1)-INDEX(B2_A,MATCH((D5*O5),B2_NP,1)))/(INDEX(B2_NP,MATCH((D5*O5),B2_NP,1)+1)-INDEX(B2_NP,MATCH((D5*O5),B2_NP,1)))))) -> 3.57225 | R5: =0.005*Q5*H5 -> 3.57225
A6: c | B6: =Исходные!$B$7 -> 24 | C6: =Исходные!$B$21 -> 251 | D6: =Исходные!B22 -> 264 | E6: =Исходные!B26-Исходные!B27 -> 110 | F6: =Исходные!B28-Исходные!B29 -> 5.1 | G6: =Исходные!B32 -> 0.2 | H6: =Исходные!B33 -> 200 | I6: =E6*C6/1000 -> 27.61 | J6: =I6/B6 -> 1.1504167 | K6: =F6*C6/(G6*D6*3600) -> 0.0067345328 | L6: =D6*K6 -> 1.7779167 | M6: =IF(AND(K6>0.1,D6<=200),((1-MIN(1,(MAX(D6,INDEX(B1_N,1))-INDEX(B1_N,MIN(MATCH(MAX(D6,INDEX(B1_N,1)),B1_N,1),ROWS(B1_N)-1)))/(INDEX(B1_N,MIN(MATCH(MAX(D6,INDEX(B1_N,1)),B1_N,1),ROWS(B1_N)-1)+1)-INDEX(B1_N,MIN(MATCH(MAX(D6,INDEX(B1_N,1)),B1_N,1),ROWS(B1_N)-1)))))*((1-MIN(1,(K6-INDEX(B1_P,1,MIN(MATCH(K6,B1_P,1),COLUMNS(B1_P)-1)))/(INDEX(B1_P,1,MIN(MATCH(K6,B1_P,1),COLUMNS(B1_P)-1)+1)-INDEX(B1_P,1,MIN(MATCH(K6,B1_P,1),COLUMNS(B1_P)-1)))))*INDEX(B1_G,MIN(MATCH(MAX(D6,INDEX(B1_N,1)),B1_N,1),ROWS(B1_N)-1),MIN(MATCH(K6,B1_P,1),COLUMNS(B1_P)-1))+MIN(1,(K6-INDEX(B1_P,1,MIN(MATCH(K6,B1_P,1),COLUMNS(B1_P)-1)))/(INDEX(B1_P,1,MIN(MATCH(K6,B1_P,1),COLUMNS(B1_P)-1)+1)-INDEX(B1_P,1,MIN(MATCH(K6,B1_P,1),COLUMNS(B1_P)-1))))*INDEX(B1_G,MIN(MATCH(MAX(D6,INDEX(B1_N,1)),B1_N,1),ROWS(B1_N)-1),MIN(MATCH(K6,B1_P,1),COLUMNS(B1_P)-1)+1))+MIN(1,(MAX(D6,INDEX(B1_N,1))-INDEX(B1_N,MIN(MATCH(MAX(D6,INDEX(B1_N,1)),B1_N,1),ROWS(B1_N)-1)))/(INDEX(B1_N,MIN(MATCH(MAX(D6,INDEX(B1_N,1)),B1_N,1),ROWS(B1_N)-1)+1)-INDEX(B1_N,MIN(MATCH(MAX(D6,INDEX(B1_N,1)),B1_N,1),ROWS(B1_N)-1))))*((1-MIN(1,(K6-INDEX(B1_P,1,MIN(MATCH(K6,B1_P,1),COLUMNS(B1_P)-1)))/(INDEX(B1_P,1,MIN(MATCH(K6,B1_P,1),COLUMNS(B1_P)-1)+1)-INDEX(B1_P,1,MIN(MATCH(K6,B1_P,1),COLUMNS(B1_P)-1)))))*INDEX(B1_G,MIN(MATCH(MAX(D6,INDEX(B1_N,1)),B1_N,1),ROWS(B1_N)-1)+1,MIN(MATCH(K6,B1_P,1),COLUMNS(B1_P)-1))+MIN(1,(K6-INDEX(B1_P,1,MIN(MATCH(K6,B1_P,1),COLUMNS(B1_P)-1)))/(INDEX(B1_P,1,MIN(MATCH(K6,B1_P,1),COLUMNS(B1_P)-1)+1)-INDEX(B1_P,1,MIN(MATCH(K6,B1_P,1),COLUMNS(B1_P)-1))))*INDEX(B1_G,MIN(MATCH(MAX(D6,INDEX(B1_N,1)),B1_N,1),ROWS(B1_N)-1)+1,MIN(MATCH(K6,B1_P,1),COLUMNS(B1_P)-1)+1))),IF((D6*K6)<INDEX(B2_NP,1),0.2,IF((D6*K6)>=INDEX(B2_NP,ROWS(B2_NP)),INDEX(B2_A,ROWS(B2_NP)),INDEX(B2_A,MATCH((D6*K6),B2_NP,1))+((D6*K6)-INDEX(B2_NP,MATCH((D6*K6),B2_NP,1)))*(INDEX(B2_A,MATCH((D6*K6),B2_NP,1)+1)-INDEX(B2_A,MATCH((D6*K6),B2_NP,1)))/(INDEX(B2_NP,MATCH((D6*K6),B2_NP,1)+1)-INDEX(B2_NP,MATCH((D6*K6),B2_NP,1)))))) -> 1.3402833 | N6: =5*G6*M6 -> 1.3402833 | O6: =3600*K6*G6/H6 -> 0.024244318 | P6: =D6*O6 -> 6.4005 | Q6: =IF(AND(O6>0.1,D6<=200),((1-MIN(1,(MAX(D6,INDEX(B1_N,1))-INDEX(B1_N,MIN(MATCH(MAX(D6,INDEX(B1_N,1)),B1_N,1),ROWS(B1_N)-1)))/(INDEX(B1_N,MIN(MATCH(MAX(D6,INDEX(B1_N,1)),B1_N,1),ROWS(B1_N)-1)+1)-INDEX(B1_N,MIN(MATCH(MAX(D6,INDEX(B1_N,1)),B1_N,1),ROWS(B1_N)-1)))))*((1-MIN(1,(O6-INDEX(B1_P,1,MIN(MATCH(O6,B1_P,1),COLUMNS(B1_P)-1)))/(INDEX(B1_P,1,MIN(MATCH(O6,B1_P,1),COLUMNS(B1_P)-1)+1)-INDEX(B1_P,1,MIN(MATCH(O6,B1_P,1),COLUMNS(B1_P)-1)))))*INDEX(B1_G,MIN(MATCH(MAX(D6,INDEX(B1_N,1)),B1_N,1),ROWS(B1_N)-1),MIN(MATCH(O6,B1_P,1),COLUMNS(B1_P)-1))+MIN(1,(O6-INDEX(B1_P,1,MIN(MATCH(O6,B1_P,1),COLUMNS(B1_P)-1)))/(INDEX(B1_P,1,MIN(MATCH(O6,B1_P,1),COLUMNS(B1_P)-1)+1)-INDEX(B1_P,1,MIN(MATCH(O6,B1_P,1),COLUMNS(B1_P)-1))))*INDEX(B1_G,MIN(MATCH(MAX(D6,INDEX(B1_N,1)),B1_N,1),ROWS(B1_N)-1),MIN(MATCH(O6,B1_P,1),COLUMNS(B1_P)-1)+1))+MIN(1,(MAX(D6,INDEX(B1_N,1))-INDEX(B1_N,MIN(MATCH(MAX(D6,INDEX(B1_N,1)),B1_N,1),ROWS(B1_N)-1)))/(INDEX(B1_N,MIN(MATCH(MAX(D6,INDEX(B1_N,1)),B1_N,1),ROWS(B1_N)-1)+1)-INDEX(B1_N,MIN(MATCH(MAX(D6,INDEX(B1_N,1)),B1_N,1),ROWS(B1_N)-1))))*((1-MIN(1,(O6-INDEX(B1_P,1,MIN(MATCH(O6,B1_P,1),COLUMNS(B1_P)-1)))/(INDEX(B1_P,1,MIN(MATCH(O6,B1_P,1),COLUMNS(B1_P)-1)+1)-INDEX(B1_P,1,MIN(MATCH(O6,B1_P,1),COLUMNS(B1_P)-1)))))*INDEX(B1_G,MIN(MATCH(MAX(D6,INDEX(B1_N,1)),B1_N,1),ROWS(B1_N)-1)+1,MIN(MATCH(O6,B1_P,1),COLUMNS(B1_P)-1))+MIN(1,(O6-INDEX(B1_P,1,MIN(MATCH(O6,B1_P,1),COLUMNS(B1_P)-1)))/(INDEX(B1_P,1,MIN(MATCH(O6,B1_P,1),COLUMNS(B1_P)-1)+1)-INDEX(B1_P,1,MIN(MATCH(O6,B1_P,1),COLUMNS(B1_P)-1))))*INDEX(B1_G,MIN(MATCH(MAX(D6,INDEX(B1_N,1)),B1_N,1),ROWS(B1_N)-1)+1,MIN(MATCH(O6,B1_P,1),COLUMNS(B1_P)-1)+1))),IF((D6*O6)<INDEX(B2_NP,1),0.2,IF((D6*O6)>=INDEX(B2_NP,ROWS(B2_NP)),INDEX(B2_A,ROWS(B2_NP)),INDEX(B2_A,MATCH((D6*O6),B2_NP,1))+((D6*O6)-INDEX(B2_NP,MATCH((D6*O6),B2_NP,1)))*(INDEX(B2_A,MATCH((D6*O6),B2_NP,1)+1)-INDEX(B2_A,MATCH((D6*O6),B2_NP,1)))/(INDEX(B2_NP,MATCH((D6*O6),B2_NP,1)+1)-INDEX(B2_NP,MATCH((D6*O6),B2_NP,1)))))) -> 3.02116 | R6: =0.005*Q6*H6 -> 3.02116
A9: Формулы (п. 5 СП 30.13330.2020):
A10: q_u,m = q_u·U/1000 — суточный расход; для холодной воды q_u^c = q_u^tot − q_u^h, q_hr,u^c = q_hr,u^tot − q_hr,u^h.
A11: q_T = q_u,m / T — среднечасовой расход.
A12: P = q_hr,u·U / (q_0·N·3600) — вероятность действия приборов (п. 5.4); q = 5·q_0·α (п. 5.3).
A13: α = f(NP): табл. Б.2 с линейной интерполяцией y = y1 + (x − x1)·(y2 − y1)/(x2 − x1); при P > 0,1 и N ≤ 200 — табл. Б.1 (интерполяция по N и P).
A14: P_hr = 3600·P·q_0 / q_0,hr (п. 5.9); q_hr = 0,005·α_hr·q_0,hr, м³/ч (п. 5.10).
A15: Для горячей воды N^h — число приборов с горячей водой (без унитазов).

Sheet В1
A1: Гидравлический расчёт сети В1 по диктующему направлению (диктующий прибор — душевая сетка над ванной, 11 этаж, Ст.В1-4)
B3: P^c | C3: =Расходы!K6 -> 0.0067345328
B4: q_0^c, л/с | C4: =Расходы!G6 -> 0.2
B5: K_м.с (хоз-питьевой водопровод жилого здания) | C5: 0.3
A7: № | B7: Участок | C7: L, м | D7: N | E7: NP | F7: α | G7: q, л/с | H7: DN | I7: d_расч, мм | J7: v, м/с | K7: 1000i | L7: iL, м | M7: h, м | N7: v в норме?
A8: 1 | B8: квартирная разводка | C8: 1.65 | D8: 1 | E8: =D8*$C$3 -> 0.0067345328 | F8: =IF(AND($C$3>0.1,D8<=200),((1-MIN(1,(MAX(D8,INDEX(B1_N,1))-INDEX(B1_N,MIN(MATCH(MAX(D8,INDEX(B1_N,1)),B1_N,1),ROWS(B1_N)-1)))/(INDEX(B1_N,MIN(MATCH(MAX(D8,INDEX(B1_N,1)),B1_N,1),ROWS(B1_N)-1)+1)-INDEX(B1_N,MIN(MATCH(MAX(D8,INDEX(B1_N,1)),B1_N,1),ROWS(B1_N)-1)))))*((1-MIN(1,($C$3-INDEX(B1_P,1,MIN(MATCH($C$3,B1_P,1),COLUMNS(B1_P)-1)))/(INDEX(B1_P,1,MIN(MATCH($C$3,B1_P,1),COLUMNS(B1_P)-1)+1)-INDEX(B1_P,1,MIN(MATCH($C$3,B1_P,1),COLUMNS(B1_P)-1)))))*INDEX(B1_G,MIN(MATCH(MAX(D8,INDEX(B1_N,1)),B1_N,1),ROWS(B1_N)-1),MIN(MATCH($C$3,B1_P,1),COLUMNS(B1_P)-1))+MIN(1,($C$3-INDEX(B1_P,1,MIN(MATCH($C$3,B1_P,1),COLUMNS(B1_P)-1)))/(INDEX(B1_P,1,MIN(MATCH($C$3,B1_P,1),COLUMNS(B1_P)-1)+1)-INDEX(B1_P,1,MIN(MATCH($C$3,B1_P,1),COLUMNS(B1_P)-1))))*INDEX(B1_G,MIN(MATCH(MAX(D8,INDEX(B1_N,1)),B1_N,1),ROWS(B1_N)-1),MIN(MATCH($C$3,B1_P,1),COLUMNS(B1_P)-1)+1))+MIN(1,(MAX(D8,INDEX(B1_N,1))-INDEX(B1_N,MIN(MATCH(MAX(D8,INDEX(B1_N,1)),B1_N,1),ROWS(B1_N)-1)))/(INDEX(B1_N,MIN(MATCH(MAX(D8,INDEX(B1_N,1)),B1_N,1),ROWS(B1_N)-1)+1)-INDEX(B1_N,MIN(MATCH(MAX(D8,INDEX(B1_N,1)),B1_N,1),ROWS(B1_N)-1))))*((1-MIN(1,($C$3-INDEX(B1_P,1,MIN(MATCH($C$3,B1_P,1),COLUMNS(B1_P)-1)))/(INDEX(B1_P,1,MIN(MATCH($C$3,B1_P,1),COLUMNS(B1_P)-1)+1)-INDEX(B1_P,1,MIN(MATCH($C$3,B1_P,1),COLUMNS(B1_P)-1)))))*INDEX(B1_G,MIN(MATCH(MAX(D8,INDEX(B1_N,1)),B1_N,1),ROWS(B1_N)-1)+1,MIN(MATCH($C$3,B1_P,1),COLUMNS(B1_P)-1))+MIN(1,($C$3-INDEX(B1_P,1,MIN(MATCH($C$3,B1_P,1),COLUMNS(B1_P)-1)))/(INDEX(B1_P,1,MIN(MATCH($C$3,B1_P,1),COLUMNS(B1_P)-1)+1)-INDEX(B1_P,1,MIN(MATCH($C$3,B1_P,1),COLUMNS(B1_P)-1))))*INDEX(B1_G,MIN(MATCH(MAX(D8,INDEX(B1_N,1)),B1_N,1),ROWS(B1_N)-1)+1,MIN(MATCH($C$3,B1_P,1),COLUMNS(B1_P)-1)+1))),IF((D8*$C$3)<INDEX(B2_NP,1),0.2,IF((D8*$C$3)>=INDEX(B2_NP,ROWS(B2_NP)),INDEX(B2_A,ROWS(B2_NP)),INDEX(B2_A,MATCH((D8*$C$3),B2_NP,1))+((D8*$C$3)-INDEX(B2_NP,MATCH((D8*$C$3),B2_NP,1)))*(INDEX(B2_A,MATCH((D8*$C$3),B2_NP,1)+1)-INDEX(B2_A,MATCH((D8*$C$3),B2_NP,1)))/(INDEX(B2_NP,MATCH((D8*$C$3),B2_NP,1)+1)-INDEX(B2_NP,MATCH((D8*$C$3),B2_NP,1)))))) -> 0.2 | G8: =5*$C$4*F8 -> 0.2 | H8: 15 | I8: =INDEX(VGP_DR,MATCH(H8,VGP_DN,0)) -> 14.7 | J8: =G8/1000/(PI()*(I8/1000)^2/4) -> 1.1784345 | K8: =1000*IF(J8<1.2,0.000912*J8^2/(I8/1000)^1.3*(1+0.867/J8)^0.3,0.00107*J8^2/(I8/1000)^1.3) -> 360.52653 | L8: =K8/1000*C8 -> 0.59486878 | M8: =L8*(1+$C$5) -> 0.77332941 | N8: =IF(AND(J8>=0.3,J8<=1.5),"да","нет") -> да
A9: 2 | B9: квартирная разводка | C9: 0.95 | D9: 3 | E9: =D9*$C$3 -> 0.020203598 | F9: =IF(AND($C$3>0.1,D9<=200),((1-MIN(1,(MAX(D9,INDEX(B1_N,1))-INDEX(B1_N,MIN(MATCH(MAX(D9,INDEX(B1_N,1)),B1_N,1),ROWS(B1_N)-1)))/(INDEX(B1_N,MIN(MATCH(MAX(D9,INDEX(B1_N,1)),B1_N,1),ROWS(B1_N)-1)+1)-INDEX(B1_N,MIN(MATCH(MAX(D9,INDEX(B1_N,1)),B1_N,1),ROWS(B1_N)-1)))))*((1-MIN(1,($C$3-INDEX(B1_P,1,MIN(MATCH($C$3,B1_P,1),COLUMNS(B1_P)-1)))/(INDEX(B1_P,1,MIN(MATCH($C$3,B1_P,1),COLUMNS(B1_P)-1)+1)-INDEX(B1_P,1,MIN(MATCH($C$3,B1_P,1),COLUMNS(B1_P)-1)))))*INDEX(B1_G,MIN(MATCH(MAX(D9,INDEX(B1_N,1)),B1_N,1),ROWS(B1_N)-1),MIN(MATCH($C$3,B1_P,1),COLUMNS(B1_P)-1))+MIN(1,($C$3-INDEX(B1_P,1,MIN(MATCH($C$3,B1_P,1),COLUMNS(B1_P)-1)))/(INDEX(B1_P,1,MIN(MATCH($C$3,B1_P,1),COLUMNS(B1_P)-1)+1)-INDEX(B1_P,1,MIN(MATCH($C$3,B1_P,1),COLUMNS(B1_P)-1))))*INDEX(B1_G,MIN(MATCH(MAX(D9,INDEX(B1_N,1)),B1_N,1),ROWS(B1_N)-1),MIN(MATCH($C$3,B1_P,1),COLUMNS(B1_P)-1)+1))+MIN(1,(MAX(D9,INDEX(B1_N,1))-INDEX(B1_N,MIN(MATCH(MAX(D9,INDEX(B1_N,1)),B1_N,1),ROWS(B1_N)-1)))/(INDEX(B1_N,MIN(MATCH(MAX(D9,INDEX(B1_N,1)),B1_N,1),ROWS(B1_N)-1)+1)-INDEX(B1_N,MIN(MATCH(MAX(D9,INDEX(B1_N,1)),B1_N,1),ROWS(B1_N)-1))))*((1-MIN(1,($C$3-INDEX(B1_P,1,MIN(MATCH($C$3,B1_P,1),COLUMNS(B1_P)-1)))/(INDEX(B1_P,1,MIN(MATCH($C$3,B1_P,1),COLUMNS(B1_P)-1)+1)-INDEX(B1_P,1,MIN(MATCH($C$3,B1_P,1),COLUMNS(B1_P)-1)))))*INDEX(B1_G,MIN(MATCH(MAX(D9,INDEX(B1_N,1)),B1_N,1),ROWS(B1_N)-1)+1,MIN(MATCH($C$3,B1_P,1),COLUMNS(B1_P)-1))+MIN(1,($C$3-INDEX(B1_P,1,MIN(MATCH($C$3,B1_P,1),COLUMNS(B1_P)-1)))/(INDEX(B1_P,1,MIN(MATCH($C$3,B1_P,1),COLUMNS(B1_P)-1)+1)-INDEX(B1_P,1,MIN(MATCH($C$3,B1_P,1),COLUMNS(B1_P)-1))))*INDEX(B1_G,MIN(MATCH(MAX(D9,INDEX(B1_N,1)),B1_N,1),ROWS(B1_N)-1)+1,MIN(MATCH($C$3,B1_P,1),COLUMNS(B1_P)-1)+1))),IF((D9*$C$3)<INDEX(B2_NP,1),0.2,IF((D9*$C$3)>=INDEX(B2_NP,ROWS(B2_NP)),INDEX(B2_A,ROWS(B2_NP)),INDEX(B2_A,MATCH((D9*$C$3),B2_NP,1))+((D9*$C$3)-INDEX(B2_NP,MATCH((D9*$C$3),B2_NP,1)))*(INDEX(B2_A,MATCH((D9*$C$3),B2_NP,1)+1)-INDEX(B2_A,MATCH((D9*$C$3),B2_NP,1)))/(INDEX(B2_NP,MATCH((D9*$C$3),B2_NP,1)+1)-INDEX(B2_NP,MATCH((D9*$C$3),B2_NP,1)))))) -> 0.2154072 | G9: =5*$C$4*F9 -> 0.2154072 | H9: 15 | I9: =INDEX(VGP_DR,MATCH(H9,VGP_DN,0)) -> 14.7 | J9: =G9/1000/(PI()*(I9/1000)^2/4) -> 1.2692164 | K9: =1000*IF(J9<1.2,0.000912*J9^2/(I9/1000)^1.3*(1+0.867/J9)^0.3,0.00107*J9^2/(I9/1000)^1.3) -> 415.85561 | L9: =K9/1000*C9 -> 0.39506282 | M9: =L9*(1+$C$5) -> 0.51358167 | N9: =IF(AND(J9>=0.3,J9<=1.5),"да","нет") -> да
A10: 3 | B10: квартирная разводка | C10: 1.2 | D10: 4 | E10: =D10*$C$3 -> 0.026938131 | F10: =IF(AND($C$3>0.1,D10<=200),((1-MIN(1,(MAX(D10,INDEX(B1_N,1))-INDEX(B1_N,MIN(MATCH(MAX(D10,INDEX(B1_N,1)),B1_N,1),ROWS(B1_N)-1)))/(INDEX(B1_N,MIN(MATCH(MAX(D10,INDEX(B1_N,1)),B1_N,1),ROWS(B1_N)-1)+1)-INDEX(B1_N,MIN(MATCH(MAX(D10,INDEX(B1_N,1)),B1_N,1),ROWS(B1_N)-1)))))*((1-MIN(1,($C$3-INDEX(B1_P,1,MIN(MATCH($C$3,B1_P,1),COLUMNS(B1_P)-1)))/(INDEX(B1_P,1,MIN(MATCH($C$3,B1_P,1),COLUMNS(B1_P)-1)+1)-INDEX(B1_P,1,MIN(MATCH($C$3,B1_P,1),COLUMNS(B1_P)-1)))))*INDEX(B1_G,MIN(MATCH(MAX(D10,INDEX(B1_N,1)),B1_N,1),ROWS(B1_N)-1),MIN(MATCH($C$3,B1_P,1),COLUMNS(B1_P)-1))+MIN(1,($C$3-INDEX(B1_P,1,MIN(MATCH($C$3,B1_P,1),COLUMNS(B1_P)-1)))/(INDEX(B1_P,1,MIN(MATCH($C$3,B1_P,1),COLUMNS(B1_P)-1)+1)-INDEX(B1_P,1,MIN(MATCH($C$3,B1_P,1),COLUMNS(B1_P)-1))))*INDEX(B1_G,MIN(MATCH(MAX(D10,INDEX(B1_N,1)),B1_N,1),ROWS(B1_N)-1),MIN(MATCH($C$3,B1_P,1),COLUMNS(B1_P)-1)+1))+MIN(1,(MAX(D10,INDEX(B1_N,1))-INDEX(B1_N,MIN(MATCH(MAX(D10,INDEX(B1_N,1)),B1_N,1),ROWS(B1_N)-1)))/(INDEX(B1_N,MIN(MATCH(MAX(D10,INDEX(B1_N,1)),B1_N,1),ROWS(B1_N)-1)+1)-INDEX(B1_N,MIN(MATCH(MAX(D10,INDEX(B1_N,1)),B1_N,1),ROWS(B1_N)-1))))*((1-MIN(1,($C$3-INDEX(B1_P,1,MIN(MATCH($C$3,B1_P,1),COLUMNS(B1_P)-1)))/(INDEX(B1_P,1,MIN(MATCH($C$3,B1_P,1),COLUMNS(B1_P)-1)+1)-INDEX(B1_P,1,MIN(MATCH($C$3,B1_P,1),COLUMNS(B1_P)-1)))))*INDEX(B1_G,MIN(MATCH(MAX(D10,INDEX(B1_N,1)),B1_N,1),ROWS(B1_N)-1)+1,MIN(MATCH($C$3,B1_P,1),COLUMNS(B1_P)-1))+MIN(1,($C$3-INDEX(B1_P,1,MIN(MATCH($C$3,B1_P,1),COLUMNS(B1_P)-1)))/(INDEX(B1_P,1,MIN(MATCH($C$3,B1_P,1),COLUMNS(B1_P)-1)+1)-INDEX(B1_P,1,MIN(MATCH($C$3,B1_P,1),COLUMNS(B1_P)-1))))*INDEX(B1_G,MIN(MATCH(MAX(D10,INDEX(B1_N,1)),B1_N,1),ROWS(B1_N)-1)+1,MIN(MATCH($C$3,B1_P,1),COLUMNS(B1_P)-1)+1))),IF((D10*$C$3)<INDEX(B2_NP,1),0.2,IF((D10*$C$3)>=INDEX(B2_NP,ROWS(B2_NP)),INDEX(B2_A,ROWS(B2_NP)),INDEX(B2_A,MATCH((D10*$C$3),B2_NP,1))+((D10*$C$3)-INDEX(B2_NP,MATCH((D10*$C$3),B2_NP,1)))*(INDEX(B2_A,MATCH((D10*$C$3),B2_NP,1)+1)-INDEX(B2_A,MATCH((D10*$C$3),B2_NP,1)))/(INDEX(B2_NP,MATCH((D10*$C$3),B2_NP,1)+1)-INDEX(B2_NP,MATCH((D10*$C$3),B2_NP,1)))))) -> 0.22987626 | G10: =5*$C$4*F10 -> 0.22987626 | H10: 15 | I10: =INDEX(VGP_DR,MATCH(H10,VGP_DN,0)) -> 14.7 | J10: =G10/1000/(PI()*(I10/1000)^2/4) -> 1.3544706 | K10: =1000*IF(J10<1.2,0.000912*J10^2/(I10/1000)^1.3*(1+0.867/J10)^0.3,0.00107*J10^2/(I10/1000)^1.3) -> 473.59858 | L10: =K10/1000*C10 -> 0.5683183 | M10: =L10*(1+$C$5) -> 0.73881379 | N10: =IF(AND(J10>=0.3,J10<=1.5),"да","нет") -> да
A11: 4 | B11: Ст.В1-4, эт. 11-10 | C11: 3.2 | D11: 8 | E11: =D11*$C$3 -> 0.053876263 | F11: =IF(AND($C$3>0.1,D11<=200),((1-MIN(1,(MAX(D11,INDEX(B1_N,1))-INDEX(B1_N,MIN(MATCH(MAX(D11,INDEX(B1_N,1)),B1_N,1),ROWS(B1_N)-1)))/(INDEX(B1_N,MIN(MATCH(MAX(D11,INDEX(B1_N,1)),B1_N,1),ROWS(B1_N)-1)+1)-INDEX(B1_N,MIN(MATCH(MAX(D11,INDEX(B1_N,1)),B1_N,1),ROWS(B1_N)-1)))))*((1-MIN(1,($C$3-INDEX(B1_P,1,MIN(MATCH($C$3,B1_P,1),COLUMNS(B1_P)-1)))/(INDEX(B1_P,1,MIN(MATCH($C$3,B1_P,1),COLUMNS(B1_P)-1)+1)-INDEX(B1_P,1,MIN(MATCH($C$3,B1_P,1),COLUMNS(B1_P)-1)))))*INDEX(B1_G,MIN(MATCH(MAX(D11,INDEX(B1_N,1)),B1_N,1),ROWS(B1_N)-1),MIN(MATCH($C$3,B1_P,1),COLUMNS(B1_P)-1))+MIN(1,($C$3-INDEX(B1_P,1,MIN(MATCH($C$3,B1_P,1),COLUMNS(B1_P)-1)))/(INDEX(B1_P,1,MIN(MATCH($C$3,B1_P,1),COLUMNS(B1_P)-1)+1)-INDEX(B1_P,1,MIN(MATCH($C$3,B1_P,1),COLUMNS(B1_P)-1))))*INDEX(B1_G,MIN(MATCH(MAX(D11,INDEX(B1_N,1)),B1_N,1),ROWS(B1_N)-1),MIN(MATCH($C$3,B1_P,1),COLUMNS(B1_P)-1)+1))+MIN(1,(MAX(D11,INDEX(B1_N,1))-INDEX(B1_N,MIN(MATCH(MAX(D11,INDEX(B1_N,1)),B1_N,1),ROWS(B1_N)-1)))/(INDEX(B1_N,MIN(MATCH(MAX(D11,INDEX(B1_N,1)),B1_N,1),ROWS(B1_N)-1)+1)-INDEX(B1_N,MIN(MATCH(MAX(D11,INDEX(B1_N,1)),B1_N,1),ROWS(B1_N)-1))))*((1-MIN(1,($C$3-INDEX(B1_P,1,MIN(MATCH($C$3,B1_P,1),COLUMNS(B1_P)-1)))/(INDEX(B1_P,1,MIN(MATCH($C$3,B1_P,1),COLUMNS(B1_P)-1)+1)-INDEX(B1_P,1,MIN(MATCH($C$3,B1_P,1),COLUMNS(B1_P)-1)))))*INDEX(B1_G,MIN(MATCH(MAX(D11,INDEX(B1_N,1)),B1_N,1),ROWS(B1_N)-1)+1,MIN(MATCH($C$3,B1_P,1),COLUMNS(B1_P)-1))+MIN(1,($C$3-INDEX(B1_P,1,MIN(MATCH($C$3,B1_P,1),COLUMNS(B1_P)-1)))/(INDEX(B1_P,1,MIN(MATCH($C$3,B1_P,1),COLUMNS(B1_P)-1)+1)-INDEX(B1_P,1,MIN(MATCH($C$3,B1_P,1),COLUMNS(B1_P)-1))))*INDEX(B1_G,MIN(MATCH(MAX(D11,INDEX(B1_N,1)),B1_N,1),ROWS(B1_N)-1)+1,MIN(MATCH($C$3,B1_P,1),COLUMNS(B1_P)-1)+1))),IF((D11*$C$3)<INDEX(B2_NP,1),0.2,IF((D11*$C$3)>=INDEX(B2_NP,ROWS(B2_NP)),INDEX(B2_A,ROWS(B2_NP)),INDEX(B2_A,MATCH((D11*$C$3),B2_NP,1))+((D11*$C$3)-INDEX(B2_NP,MATCH((D11*$C$3),B2_NP,1)))*(INDEX(B2_A,MATCH((D11*$C$3),B2_NP,1)+1)-INDEX(B2_A,MATCH((D11*$C$3),B2_NP,1)))/(INDEX(B2_NP,MATCH((D11*$C$3),B2_NP,1)+1)-INDEX(B2_NP,MATCH((D11*$C$3),B2_NP,1)))))) -> 0.27975253 | G11: =5*$C$4*F11 -> 0.27975253 | H11: 25 | I11: =INDEX(VGP_DR,MATCH(H11,VGP_DN,0)) -> 26.1 | J11: =G11/1000/(PI()*(I11/1000)^2/4) -> 0.52288131 | K11: =1000*IF(J11<1.2,0.000912*J11^2/(I11/1000)^1.3*(1+0.867/J11)^0.3,0.00107*J11^2/(I11/1000)^1.3) -> 38.242018 | L11: =K11/1000*C11 -> 0.12237446 | M11: =L11*(1+$C$5) -> 0.15908679 | N11: =IF(AND(J11>=0.3,J11<=1.2),"да","нет") -> да
A12: 5 | B12: Ст.В1-4, эт. 10-9 | C12: 3.2 | D12: 16 | E12: =D12*$C$3 -> 0.10775253 | F12: =IF(AND($C$3>0.1,D12<=200),((1-MIN(1,(MAX(D12,INDEX(B1_N,1))-INDEX(B1_N,MIN(MATCH(MAX(D12,INDEX(B1_N,1)),B1_N,1),ROWS(B1_N)-1)))/(INDEX(B1_N,MIN(MATCH(MAX(D12,INDEX(B1_N,1)),B1_N,1),ROWS(B1_N)-1)+1)-INDEX(B1_N,MIN(MATCH(MAX(D12,INDEX(B1_N,1)),B1_N,1),ROWS(B1_N)-1)))))*((1-MIN(1,($C$3-INDEX(B1_P,1,MIN(MATCH($C$3,B1_P,1),COLUMNS(B1_P)-1)))/(INDEX(B1_P,1,MIN(MATCH($C$3,B1_P,1),COLUMNS(B1_P)-1)+1)-INDEX(B1_P,1,MIN(MATCH($C$3,B1_P,1),COLUMNS(B1_P)-1)))))*INDEX(B1_G,MIN(MATCH(MAX(D12,INDEX(B1_N,1)),B1_N,1),ROWS(B1_N)-1),MIN(MATCH($C$3,B1_P,1),COLUMNS(B1_P)-1))+MIN(1,($C$3-INDEX(B1_P,1,MIN(MATCH($C$3,B1_P,1),COLUMNS(B1_P)-1)))/(INDEX(B1_P,1,MIN(MATCH($C$3,B1_P,1),COLUMNS(B1_P)-1)+1)-INDEX(B1_P,1,MIN(MATCH($C$3,B1_P,1),COLUMNS(B1_P)-1))))*INDEX(B1_G,MIN(MATCH(MAX(D12,INDEX(B1_N,1)),B1_N,1),ROWS(B1_N)-1),MIN(MATCH($C$3,B1_P,1),COLUMNS(B1_P)-1)+1))+MIN(1,(MAX(D12,INDEX(B1_N,1))-INDEX(B1_N,MIN(MATCH(MAX(D12,INDEX(B1_N,1)),B1_N,1),ROWS(B1_N)-1)))/(INDEX(B1_N,MIN(MATCH(MAX(D12,INDEX(B1_N,1)),B1_N,1),ROWS(B1_N)-1)+1)-INDEX(B1_N,MIN(MATCH(MAX(D12,INDEX(B1_N,1)),B1_N,1),ROWS(B1_N)-1))))*((1-MIN(1,($C$3-INDEX(B1_P,1,MIN(MATCH($C$3,B1_P,1),COLUMNS(B1_P)-1)))/(INDEX(B1_P,1,MIN(MATCH($C$3,B1_P,1),COLUMNS(B1_P)-1)+1)-INDEX(B1_P,1,MIN(MATCH($C$3,B1_P,1),COLUMNS(B1_P)-1)))))*INDEX(B1_G,MIN(MATCH(MAX(D12,INDEX(B1_N,1)),B1_N,1),ROWS(B1_N)-1)+1,MIN(MATCH($C$3,B1_P,1),COLUMNS(B1_P)-1))+MIN(1,($C$3-INDEX(B1_P,1,MIN(MATCH($C$3,B1_P,1),COLUMNS(B1_P)-1)))/(INDEX(B1_P,1,MIN(MATCH($C$3,B1_P,1),COLUMNS(B1_P)-1)+1)-INDEX(B1_P,1,MIN(MATCH($C$3,B1_P,1),COLUMNS(B1_P)-1))))*INDEX(B1_G,MIN(MATCH(MAX(D12,INDEX(B1_N,1)),B1_N,1),ROWS(B1_N)-1)+1,MIN(MATCH($C$3,B1_P,1),COLUMNS(B1_P)-1)+1))),IF((D12*$C$3)<INDEX(B2_NP,1),0.2,IF((D12*$C$3)>=INDEX(B2_NP,ROWS(B2_NP)),INDEX(B2_A,ROWS(B2_NP)),INDEX(B2_A,MATCH((D12*$C$3),B2_NP,1))+((D12*$C$3)-INDEX(B2_NP,MATCH((D12*$C$3),B2_NP,1)))*(INDEX(B2_A,MATCH((D12*$C$3),B2_NP,1)+1)-INDEX(B2_A,MATCH((D12*$C$3),B2_NP,1)))/(INDEX(B2_NP,MATCH((D12*$C$3),B2_NP,1)+1)-INDEX(B2_NP,MATCH((D12*$C$3),B2_NP,1)))))) -> 0.35230303 | G12: =5*$C$4*F12 -> 0.35230303 | H12: 25 | I12: =INDEX(VGP_DR,MATCH(H12,VGP_DN,0)) -> 26.1 | J12: =G12/1000/(PI()*(I12/1000)^2/4) -> 0.65848439 | K12: =1000*IF(J12<1.2,0.000912*J12^2/(I12/1000)^1.3*(1+0.867/J12)^0.3,0.00107*J12^2/(I12/1000)^1.3) -> 58.198505 | L12: =K12/1000*C12 -> 0.18623522 | M12: =L12*(1+$C$5) -> 0.24210578 | N12: =IF(AND(J12>=0.3,J12<=1.2),"да","нет") -> да
A13: 6 | B13: Ст.В1-4, эт. 9-8 | C13: 3.2 | D13: 24 | E13: =D13*$C$3 -> 0.16162879 | F13: =IF(AND($C$3>0.1,D13<=200),((1-MIN(1,(MAX(D13,INDEX(B1_N,1))-INDEX(B1_N,MIN(MATCH(MAX(D13,INDEX(B1_N,1)),B1_N,1),ROWS(B1_N)-1)))/(INDEX(B1_N,MIN(MATCH(MAX(D13,INDEX(B1_N,1)),B1_N,1),ROWS(B1_N)-1)+1)-INDEX(B1_N,MIN(MATCH(MAX(D13,INDEX(B1_N,1)),B1_N,1),ROWS(B1_N)-1)))))*((1-MIN(1,($C$3-INDEX(B1_P,1,MIN(MATCH($C$3,B1_P,1),COLUMNS(B1_P)-1)))/(INDEX(B1_P,1,MIN(MATCH($C$3,B1_P,1),COLUMNS(B1_P)-1)+1)-INDEX(B1_P,1,MIN(MATCH($C$3,B1_P,1),COLUMNS(B1_P)-1)))))*INDEX(B1_G,MIN(MATCH(MAX(D13,INDEX(B1_N,1)),B1_N,1),ROWS(B1_N)-1),MIN(MATCH($C$3,B1_P,1),COLUMNS(B1_P)-1))+MIN(1,($C$3-INDEX(B1_P,1,MIN(MATCH($C$3,B1_P,1),COLUMNS(B1_P)-1)))/(INDEX(B1_P,1,MIN(MATCH($C$3,B1_P,1),COLUMNS(B1_P)-1)+1)-INDEX(B1_P,1,MIN(MATCH($C$3,B1_P,1),COLUMNS(B1_P)-1))))*INDEX(B1_G,MIN(MATCH(MAX(D13,INDEX(B1_N,1)),B1_N,1),ROWS(B1_N)-1),MIN(MATCH($C$3,B1_P,1),COLUMNS(B1_P)-1)+1))+MIN(1,(MAX(D13,INDEX(B1_N,1))-INDEX(B1_N,MIN(MATCH(MAX(D13,INDEX(B1_N,1)),B1_N,1),ROWS(B1_N)-1)))/(INDEX(B1_N,MIN(MATCH(MAX(D13,INDEX(B1_N,1)),B1_N,1),ROWS(B1_N)-1)+1)-INDEX(B1_N,MIN(MATCH(MAX(D13,INDEX(B1_N,1)),B1_N,1),ROWS(B1_N)-1))))*((1-MIN(1,($C$3-INDEX(B1_P,1,MIN(MATCH($C$3,B1_P,1),COLUMNS(B1_P)-1)))/(INDEX(B1_P,1,MIN(MATCH($C$3,B1_P,1),COLUMNS(B1_P)-1)+1)-INDEX(B1_P,1,MIN(MATCH($C$3,B1_P,1),COLUMNS(B1_P)-1)))))*INDEX(B1_G,MIN(MATCH(MAX(D13,INDEX(B1_N,1)),B1_N,1),ROWS(B1_N)-1)+1,MIN(MATCH($C$3,B1_P,1),COLUMNS(B1_P)-1))+MIN(1,($C$3-INDEX(B1_P,1,MIN(MATCH($C$3,B1_P,1),COLUMNS(B1_P)-1)))/(INDEX(B1_P,1,MIN(MATCH($C$3,B1_P,1),COLUMNS(B1_P)-1)+1)-INDEX(B1_P,1,MIN(MATCH($C$3,B1_P,1),COLUMNS(B1_P)-1))))*INDEX(B1_G,MIN(MATCH(MAX(D13,INDEX(B1_N,1)),B1_N,1),ROWS(B1_N)-1)+1,MIN(MATCH($C$3,B1_P,1),COLUMNS(B1_P)-1)+1))),IF((D13*$C$3)<INDEX(B2_NP,1),0.2,IF((D13*$C$3)>=INDEX(B2_NP,ROWS(B2_NP)),INDEX(B2_A,ROWS(B2_NP)),INDEX(B2_A,MATCH((D13*$C$3),B2_NP,1))+((D13*$C$3)-INDEX(B2_NP,MATCH((D13*$C$3),B2_NP,1)))*(INDEX(B2_A,MATCH((D13*$C$3),B2_NP,1)+1)-INDEX(B2_A,MATCH((D13*$C$3),B2_NP,1)))/(INDEX(B2_NP,MATCH((D13*$C$3),B2_NP,1)+1)-INDEX(B2_NP,MATCH((D13*$C$3),B2_NP,1)))))) -> 0.41162879 | G13: =5*$C$4*F13 -> 0.41162879 | H13: 25 | I13: =INDEX(VGP_DR,MATCH(H13,VGP_DN,0)) -> 26.1 | J13: =G13/1000/(PI()*(I13/1000)^2/4) -> 0.76936928 | K13: =1000*IF(J13<1.2,0.000912*J13^2/(I13/1000)^1.3*(1+0.867/J13)^0.3,0.00107*J13^2/(I13/1000)^1.3) -> 77.4383 | L13: =K13/1000*C13 -> 0.24780256 | M13: =L13*(1+$C$5) -> 0.32214333 | N13: =IF(AND(J13>=0.3,J13<=1.2),"да","нет") -> да
A14: 7 | B14: Ст.В1-4, эт. 8-7 | C14: 3.2 | D14: 32 | E14: =D14*$C$3 -> 0.21550505 | F14: =IF(AND($C$3>0.1,D14<=200),((1-MIN(1,(MAX(D14,INDEX(B1_N,1))-INDEX(B1_N,MIN(MATCH(MAX(D14,INDEX(B1_N,1)),B1_N,1),ROWS(B1_N)-1)))/(INDEX(B1_N,MIN(MATCH(MAX(D14,INDEX(B1_N,1)),B1_N,1),ROWS(B1_N)-1)+1)-INDEX(B1_N,MIN(MATCH(MAX(D14,INDEX(B1_N,1)),B1_N,1),ROWS(B1_N)-1)))))*((1-MIN(1,($C$3-INDEX(B1_P,1,MIN(MATCH($C$3,B1_P,1),COLUMNS(B1_P)-1)))/(INDEX(B1_P,1,MIN(MATCH($C$3,B1_P,1),COLUMNS(B1_P)-1)+1)-INDEX(B1_P,1,MIN(MATCH($C$3,B1_P,1),COLUMNS(B1_P)-1)))))*INDEX(B1_G,MIN(MATCH(MAX(D14,INDEX(B1_N,1)),B1_N,1),ROWS(B1_N)-1),MIN(MATCH($C$3,B1_P,1),COLUMNS(B1_P)-1))+MIN(1,($C$3-INDEX(B1_P,1,MIN(MATCH($C$3,B1_P,1),COLUMNS(B1_P)-1)))/(INDEX(B1_P,1,MIN(MATCH($C$3,B1_P,1),COLUMNS(B1_P)-1)+1)-INDEX(B1_P,1,MIN(MATCH($C$3,B1_P,1),COLUMNS(B1_P)-1))))*INDEX(B1_G,MIN(MATCH(MAX(D14,INDEX(B1_N,1)),B1_N,1),ROWS(B1_N)-1),MIN(MATCH($C$3,B1_P,1),COLUMNS(B1_P)-1)+1))+MIN(1,(MAX(D14,INDEX(B1_N,1))-INDEX(B1_N,MIN(MATCH(MAX(D14,INDEX(B1_N,1)),B1_N,1),ROWS(B1_N)-1)))/(INDEX(B1_N,MIN(MATCH(MAX(D14,INDEX(B1_N,1)),B1_N,1),ROWS(B1_N)-1)+1)-INDEX(B1_N,MIN(MATCH(MAX(D14,INDEX(B1_N,1)),B1_N,1),ROWS(B1_N)-1))))*((1-MIN(1,($C$3-INDEX(B1_P,1,MIN(MATCH($C$3,B1_P,1),COLUMNS(B1_P)-1)))/(INDEX(B1_P,1,MIN(MATCH($C$3,B1_P,1),COLUMNS(B1_P)-1)+1)-INDEX(B1_P,1,MIN(MATCH($C$3,B1_P,1),COLUMNS(B1_P)-1)))))*INDEX(B1_G,MIN(MATCH(MAX(D14,INDEX(B1_N,1)),B1_N,1),ROWS(B1_N)-1)+1,MIN(MATCH($C$3,B1_P,1),COLUMNS(B1_P)-1))+MIN(1,($C$3-INDEX(B1_P,1,MIN(MATCH($C$3,B1_P,1),COLUMNS(B1_P)-1)))/(INDEX(B1_P,1,MIN(MATCH($C$3,B1_P,1),COLUMNS(B1_P)-1)+1)-INDEX(B1_P,1,MIN(MATCH($C$3,B1_P,1),COLUMNS(B1_P)-1))))*INDEX(B1_G,MIN(MATCH(MAX(D14,INDEX(B1_N,1)),B1_N,1),ROWS(B1_N)-1)+1,MIN(MATCH($C$3,B1_P,1),COLUMNS(B1_P)-1)+1))),IF((D14*$C$3)<INDEX(B2_NP,1),0.2,IF((D14*$C$3)>=INDEX(B2_NP,ROWS(B2_NP)),INDEX(B2_A,ROWS(B2_NP)),INDEX(B2_A,MATCH((D14*$C$3),B2_NP,1))+((D14*$C$3)-INDEX(B2_NP,MATCH((D14*$C$3),B2_NP,1)))*(INDEX(B2_A,MATCH((D14*$C$3),B2_NP,1)+1)-INDEX(B2_A,MATCH((D14*$C$3),B2_NP,1)))/(INDEX(B2_NP,MATCH((D14*$C$3),B2_NP,1)+1)-INDEX(B2_NP,MATCH((D14*$C$3),B2_NP,1)))))) -> 0.46295455 | G14: =5*$C$4*F14 -> 0.46295455 | H14: 25 | I14: =INDEX(VGP_DR,MATCH(H14,VGP_DN,0)) -> 26.1 | J14: =G14/1000/(PI()*(I14/1000)^2/4) -> 0.8653015 | K14: =1000*IF(J14<1.2,0.000912*J14^2/(I14/1000)^1.3*(1+0.867/J14)^0.3,0.00107*J14^2/(I14/1000)^1.3) -> 96.19088 | L14: =K14/1000*C14 -> 0.30781082 | M14: =L14*(1+$C$5) -> 0.40015406 | N14: =IF(AND(J14>=0.3,J14<=1.2),"да","нет") -> да
A15: 8 | B15: Ст.В1-4, эт. 7-6 | C15: 3.2 | D15: 40 | E15: =D15*$C$3 -> 0.26938131 | F15: =IF(AND($C$3>0.1,D15<=200),((1-MIN(1,(MAX(D15,INDEX(B1_N,1))-INDEX(B1_N,MIN(MATCH(MAX(D15,INDEX(B1_N,1)),B1_N,1),ROWS(B1_N)-1)))/(INDEX(B1_N,MIN(MATCH(MAX(D15,INDEX(B1_N,1)),B1_N,1),ROWS(B1_N)-1)+1)-INDEX(B1_N,MIN(MATCH(MAX(D15,INDEX(B1_N,1)),B1_N,1),ROWS(B1_N)-1)))))*((1-MIN(1,($C$3-INDEX(B1_P,1,MIN(MATCH($C$3,B1_P,1),COLUMNS(B1_P)-1)))/(INDEX(B1_P,1,MIN(MATCH($C$3,B1_P,1),COLUMNS(B1_P)-1)+1)-INDEX(B1_P,1,MIN(MATCH($C$3,B1_P,1),COLUMNS(B1_P)-1)))))*INDEX(B1_G,MIN(MATCH(MAX(D15,INDEX(B1_N,1)),B1_N,1),ROWS(B1_N)-1),MIN(MATCH($C$3,B1_P,1),COLUMNS(B1_P)-1))+MIN(1,($C$3-INDEX(B1_P,1,MIN(MATCH($C$3,B1_P,1),COLUMNS(B1_P)-1)))/(INDEX(B1_P,1,MIN(MATCH($C$3,B1_P,1),COLUMNS(B1_P)-1)+1)-INDEX(B1_P,1,MIN(MATCH($C$3,B1_P,1),COLUMNS(B1_P)-1))))*INDEX(B1_G,MIN(MATCH(MAX(D15,INDEX(B1_N,1)),B1_N,1),ROWS(B1_N)-1),MIN(MATCH($C$3,B1_P,1),COLUMNS(B1_P)-1)+1))+MIN(1,(MAX(D15,INDEX(B1_N,1))-INDEX(B1_N,MIN(MATCH(MAX(D15,INDEX(B1_N,1)),B1_N,1),ROWS(B1_N)-1)))/(INDEX(B1_N,MIN(MATCH(MAX(D15,INDEX(B1_N,1)),B1_N,1),ROWS(B1_N)-1)+1)-INDEX(B1_N,MIN(MATCH(MAX(D15,INDEX(B1_N,1)),B1_N,1),ROWS(B1_N)-1))))*((1-MIN(1,($C$3-INDEX(B1_P,1,MIN(MATCH($C$3,B1_P,1),COLUMNS(B1_P)-1)))/(INDEX(B1_P,1,MIN(MATCH($C$3,B1_P,1),COLUMNS(B1_P)-1)+1)-INDEX(B1_P,1,MIN(MATCH($C$3,B1_P,1),COLUMNS(B1_P)-1)))))*INDEX(B1_G,MIN(MATCH(MAX(D15,INDEX(B1_N,1)),B1_N,1),ROWS(B1_N)-1)+1,MIN(MATCH($C$3,B1_P,1),COLUMNS(B1_P)-1))+MIN(1,($C$3-INDEX(B1_P,1,MIN(MATCH($C$3,B1_P,1),COLUMNS(B1_P)-1)))/(INDEX(B1_P,1,MIN(MATCH($C$3,B1_P,1),COLUMNS(B1_P)-1)+1)-INDEX(B1_P,1,MIN(MATCH($C$3,B1_P,1),COLUMNS(B1_P)-1))))*INDEX(B1_G,MIN(MATCH(MAX(D15,INDEX(B1_N,1)),B1_N,1),ROWS(B1_N)-1)+1,MIN(MATCH($C$3,B1_P,1),COLUMNS(B1_P)-1)+1))),IF((D15*$C$3)<INDEX(B2_NP,1),0.2,IF((D15*$C$3)>=INDEX(B2_NP,ROWS(B2_NP)),INDEX(B2_A,ROWS(B2_NP)),INDEX(B2_A,MATCH((D15*$C$3),B2_NP,1))+((D15*$C$3)-INDEX(B2_NP,MATCH((D15*$C$3),B2_NP,1)))*(INDEX(B2_A,MATCH((D15*$C$3),B2_NP,1)+1)-INDEX(B2_A,MATCH((D15*$C$3),B2_NP,1)))/(INDEX(B2_NP,MATCH((D15*$C$3),B2_NP,1)+1)-INDEX(B2_NP,MATCH((D15*$C$3),B2_NP,1)))))) -> 0.50950505 | G15: =5*$C$4*F15 -> 0.50950505 | H15: 25 | I15: =INDEX(VGP_DR,MATCH(H15,VGP_DN,0)) -> 26.1 | J15: =G15/1000/(PI()*(I15/1000)^2/4) -> 0.95230836 | K15: =1000*IF(J15<1.2,0.000912*J15^2/(I15/1000)^1.3*(1+0.867/J15)^0.3,0.00107*J15^2/(I15/1000)^1.3) -> 114.88306 | L15: =K15/1000*C15 -> 0.36762579 | M15: =L15*(1+$C$5) -> 0.47791352 | N15: =IF(AND(J15>=0.3,J15<=1.2),"да","нет") -> да
A16: 9 | B16: Ст.В1-4, эт. 6-5 | C16: 3.2 | D16: 48 | E16: =D16*$C$3 -> 0.32325758 | F16: =IF(AND($C$3>0.1,D16<=200),((1-MIN(1,(MAX(D16,INDEX(B1_N,1))-INDEX(B1_N,MIN(MATCH(MAX(D16,INDEX(B1_N,1)),B1_N,1),ROWS(B1_N)-1)))/(INDEX(B1_N,MIN(MATCH(MAX(D16,INDEX(B1_N,1)),B1_N,1),ROWS(B1_N)-1)+1)-INDEX(B1_N,MIN(MATCH(MAX(D16,INDEX(B1_N,1)),B1_N,1),ROWS(B1_N)-1)))))*((1-MIN(1,($C$3-INDEX(B1_P,1,MIN(MATCH($C$3,B1_P,1),COLUMNS(B1_P)-1)))/(INDEX(B1_P,1,MIN(MATCH($C$3,B1_P,1),COLUMNS(B1_P)-1)+1)-INDEX(B1_P,1,MIN(MATCH($C$3,B1_P,1),COLUMNS(B1_P)-1)))))*INDEX(B1_G,MIN(MATCH(MAX(D16,INDEX(B1_N,1)),B1_N,1),ROWS(B1_N)-1),MIN(MATCH($C$3,B1_P,1),COLUMNS(B1_P)-1))+MIN(1,($C$3-INDEX(B1_P,1,MIN(MATCH($C$3,B1_P,1),COLUMNS(B1_P)-1)))/(INDEX(B1_P,1,MIN(MATCH($C$3,B1_P,1),COLUMNS(B1_P)-1)+1)-INDEX(B1_P,1,MIN(MATCH($C$3,B1_P,1),COLUMNS(B1_P)-1))))*INDEX(B1_G,MIN(MATCH(MAX(D16,INDEX(B1_N,1)),B1_N,1),ROWS(B1_N)-1),MIN(MATCH($C$3,B1_P,1),COLUMNS(B1_P)-1)+1))+MIN(1,(MAX(D16,INDEX(B1_N,1))-INDEX(B1_N,MIN(MATCH(MAX(D16,INDEX(B1_N,1)),B1_N,1),ROWS(B1_N)-1)))/(INDEX(B1_N,MIN(MATCH(MAX(D16,INDEX(B1_N,1)),B1_N,1),ROWS(B1_N)-1)+1)-INDEX(B1_N,MIN(MATCH(MAX(D16,INDEX(B1_N,1)),B1_N,1),ROWS(B1_N)-1))))*((1-MIN(1,($C$3-INDEX(B1_P,1,MIN(MATCH($C$3,B1_P,1),COLUMNS(B1_P)-1)))/(INDEX(B1_P,1,MIN(MATCH($C$3,B1_P,1),COLUMNS(B1_P)-1)+1)-INDEX(B1_P,1,MIN(MATCH($C$3,B1_P,1),COLUMNS(B1_P)-1)))))*INDEX(B1_G,MIN(MATCH(MAX(D16,INDEX(B1_N,1)),B1_N,1),ROWS(B1_N)-1)+1,MIN(MATCH($C$3,B1_P,1),COLUMNS(B1_P)-1))+MIN(1,($C$3-INDEX(B1_P,1,MIN(MATCH($C$3,B1_P,1),COLUMNS(B1_P)-1)))/(INDEX(B1_P,1,MIN(MATCH($C$3,B1_P,1),COLUMNS(B1_P)-1)+1)-INDEX(B1_P,1,MIN(MATCH($C$3,B1_P,1),COLUMNS(B1_P)-1))))*INDEX(B1_G,MIN(MATCH(MAX(D16,INDEX(B1_N,1)),B1_N,1),ROWS(B1_N)-1)+1,MIN(MATCH($C$3,B1_P,1),COLUMNS(B1_P)-1)+1))),IF((D16*$C$3)<INDEX(B2_NP,1),0.2,IF((D16*$C$3)>=INDEX(B2_NP,ROWS(B2_NP)),INDEX(B2_A,ROWS(B2_NP)),INDEX(B2_A,MATCH((D16*$C$3),B2_NP,1))+((D16*$C$3)-INDEX(B2_NP,MATCH((D16*$C$3),B2_NP,1)))*(INDEX(B2_A,MATCH((D16*$C$3),B2_NP,1)+1)-INDEX(B2_A,MATCH((D16*$C$3),B2_NP,1)))/(INDEX(B2_NP,MATCH((D16*$C$3),B2_NP,1)+1)-INDEX(B2_NP,MATCH((D16*$C$3),B2_NP,1)))))) -> 0.55260606 | G16: =5*$C$4*F16 -> 0.55260606 | H16: 25 | I16: =INDEX(VGP_DR,MATCH(H16,VGP_DN,0)) -> 26.1 | J16: =G16/1000/(PI()*(I16/1000)^2/4) -> 1.0328678 | K16: =1000*IF(J16<1.2,0.000912*J16^2/(I16/1000)^1.3*(1+0.867/J16)^0.3,0.00107*J16^2/(I16/1000)^1.3) -> 133.61502 | L16: =K16/1000*C16 -> 0.42756805 | M16: =L16*(1+$C$5) -> 0.55583846 | N16: =IF(AND(J16>=0.3,J16<=1.2),"да","нет") -> да
A17: 10 | B17: Ст.В1-4, эт. 5-4 | C17: 3.2 | D17: 56 | E17: =D17*$C$3 -> 0.37713384 | F17: =IF(AND($C$3>0.1,D17<=200),((1-MIN(1,(MAX(D17,INDEX(B1_N,1))-INDEX(B1_N,MIN(MATCH(MAX(D17,INDEX(B1_N,1)),B1_N,1),ROWS(B1_N)-1)))/(INDEX(B1_N,MIN(MATCH(MAX(D17,INDEX(B1_N,1)),B1_N,1),ROWS(B1_N)-1)+1)-INDEX(B1_N,MIN(MATCH(MAX(D17,INDEX(B1_N,1)),B1_N,1),ROWS(B1_N)-1)))))*((1-MIN(1,($C$3-INDEX(B1_P,1,MIN(MATCH($C$3,B1_P,1),COLUMNS(B1_P)-1)))/(INDEX(B1_P,1,MIN(MATCH($C$3,B1_P,1),COLUMNS(B1_P)-1)+1)-INDEX(B1_P,1,MIN(MATCH($C$3,B1_P,1),COLUMNS(B1_P)-1)))))*INDEX(B1_G,MIN(MATCH(MAX(D17,INDEX(B1_N,1)),B1_N,1),ROWS(B1_N)-1),MIN(MATCH($C$3,B1_P,1),COLUMNS(B1_P)-1))+MIN(1,($C$3-INDEX(B1_P,1,MIN(MATCH($C$3,B1_P,1),COLUMNS(B1_P)-1)))/(INDEX(B1_P,1,MIN(MATCH($C$3,B1_P,1),COLUMNS(B1_P)-1)+1)-INDEX(B1_P,1,MIN(MATCH($C$3,B1_P,1),COLUMNS(B1_P)-1))))*INDEX(B1_G,MIN(MATCH(MAX(D17,INDEX(B1_N,1)),B1_N,1),ROWS(B1_N)-1),MIN(MATCH($C$3,B1_P,1),COLUMNS(B1_P)-1)+1))+MIN(1,(MAX(D17,INDEX(B1_N,1))-INDEX(B1_N,MIN(MATCH(MAX(D17,INDEX(B1_N,1)),B1_N,1),ROWS(B1_N)-1)))/(INDEX(B1_N,MIN(MATCH(MAX(D17,INDEX(B1_N,1)),B1_N,1),ROWS(B1_N)-1)+1)-INDEX(B1_N,MIN(MATCH(MAX(D17,INDEX(B1_N,1)),B1_N,1),ROWS(B1_N)-1))))*((1-MIN(1,($C$3-INDEX(B1_P,1,MIN(MATCH($C$3,B1_P,1),COLUMNS(B1_P)-1)))/(INDEX(B1_P,1,MIN(MATCH($C$3,B1_P,1),COLUMNS(B1_P)-1)+1)-INDEX(B1_P,1,MIN(MATCH($C$3,B1_P,1),COLUMNS(B1_P)-1)))))*INDEX(B1_G,MIN(MATCH(MAX(D17,INDEX(B1_N,1)),B1_N,1),ROWS(B1_N)-1)+1,MIN(MATCH($C$3,B1_P,1),COLUMNS(B1_P)-1))+MIN(1,($C$3-INDEX(B1_P,1,MIN(MATCH($C$3,B1_P,1),COLUMNS(B1_P)-1)))/(INDEX(B1_P,1,MIN(MATCH($C$3,B1_P,1),COLUMNS(B1_P)-1)+1)-INDEX(B1_P,1,MIN(MATCH($C$3,B1_P,1),COLUMNS(B1_P)-1))))*INDEX(B1_G,MIN(MATCH(MAX(D17,INDEX(B1_N,1)),B1_N,1),ROWS(B1_N)-1)+1,MIN(MATCH($C$3,B1_P,1),COLUMNS(B1_P)-1)+1))),IF((D17*$C$3)<INDEX(B2_NP,1),0.2,IF((D17*$C$3)>=INDEX(B2_NP,ROWS(B2_NP)),INDEX(B2_A,ROWS(B2_NP)),INDEX(B2_A,MATCH((D17*$C$3),B2_NP,1))+((D17*$C$3)-INDEX(B2_NP,MATCH((D17*$C$3),B2_NP,1)))*(INDEX(B2_A,MATCH((D17*$C$3),B2_NP,1)+1)-INDEX(B2_A,MATCH((D17*$C$3),B2_NP,1)))/(INDEX(B2_NP,MATCH((D17*$C$3),B2_NP,1)+1)-INDEX(B2_NP,MATCH((D17*$C$3),B2_NP,1)))))) -> 0.59299369 | G17: =5*$C$4*F17 -> 0.59299369 | H17: 25 | I17: =INDEX(VGP_DR,MATCH(H17,VGP_DN,0)) -> 26.1 | J17: =G17/1000/(PI()*(I17/1000)^2/4) -> 1.1083557 | K17: =1000*IF(J17<1.2,0.000912*J17^2/(I17/1000)^1.3*(1+0.867/J17)^0.3,0.00107*J17^2/(I17/1000)^1.3) -> 152.40891 | L17: =K17/1000*C17 -> 0.48770853 | M17: =L17*(1+$C$5) -> 0.63402108 | N17: =IF(AND(J17>=0.3,J17<=1.2),"да","нет") -> да
A18: 11 | B18: Ст.В1-4, эт. 4-3 | C18: 3.2 | D18: 64 | E18: =D18*$C$3 -> 0.4310101 | F18: =IF(AND($C$3>0.1,D18<=200),((1-MIN(1,(MAX(D18,INDEX(B1_N,1))-INDEX(B1_N,MIN(MATCH(MAX(D18,INDEX(B1_N,1)),B1_N,1),ROWS(B1_N)-1)))/(INDEX(B1_N,MIN(MATCH(MAX(D18,INDEX(B1_N,1)),B1_N,1),ROWS(B1_N)-1)+1)-INDEX(B1_N,MIN(MATCH(MAX(D18,INDEX(B1_N,1)),B1_N,1),ROWS(B1_N)-1)))))*((1-MIN(1,($C$3-INDEX(B1_P,1,MIN(MATCH($C$3,B1_P,1),COLUMNS(B1_P)-1)))/(INDEX(B1_P,1,MIN(MATCH($C$3,B1_P,1),COLUMNS(B1_P)-1)+1)-INDEX(B1_P,1,MIN(MATCH($C$3,B1_P,1),COLUMNS(B1_P)-1)))))*INDEX(B1_G,MIN(MATCH(MAX(D18,INDEX(B1_N,1)),B1_N,1),ROWS(B1_N)-1),MIN(MATCH($C$3,B1_P,1),COLUMNS(B1_P)-1))+MIN(1,($C$3-INDEX(B1_P,1,MIN(MATCH($C$3,B1_P,1),COLUMNS(B1_P)-1)))/(INDEX(B1_P,1,MIN(MATCH($C$3,B1_P,1),COLUMNS(B1_P)-1)+1)-INDEX(B1_P,1,MIN(MATCH($C$3,B1_P,1),COLUMNS(B1_P)-1))))*INDEX(B1_G,MIN(MATCH(MAX(D18,INDEX(B1_N,1)),B1_N,1),ROWS(B1_N)-1),MIN(MATCH($C$3,B1_P,1),COLUMNS(B1_P)-1)+1))+MIN(1,(MAX(D18,INDEX(B1_N,1))-INDEX(B1_N,MIN(MATCH(MAX(D18,INDEX(B1_N,1)),B1_N,1),ROWS(B1_N)-1)))/(INDEX(B1_N,MIN(MATCH(MAX(D18,INDEX(B1_N,1)),B1_N,1),ROWS(B1_N)-1)+1)-INDEX(B1_N,MIN(MATCH(MAX(D18,INDEX(B1_N,1)),B1_N,1),ROWS(B1_N)-1))))*((1-MIN(1,($C$3-INDEX(B1_P,1,MIN(MATCH($C$3,B1_P,1),COLUMNS(B1_P)-1)))/(INDEX(B1_P,1,MIN(MATCH($C$3,B1_P,1),COLUMNS(B1_P)-1)+1)-INDEX(B1_P,1,MIN(MATCH($C$3,B1_P,1),COLUMNS(B1_P)-1)))))*INDEX(B1_G,MIN(MATCH(MAX(D18,INDEX(B1_N,1)),B1_N,1),ROWS(B1_N)-1)+1,MIN(MATCH($C$3,B1_P,1),COLUMNS(B1_P)-1))+MIN(1,($C$3-INDEX(B1_P,1,MIN(MATCH($C$3,B1_P,1),COLUMNS(B1_P)-1)))/(INDEX(B1_P,1,MIN(MATCH($C$3,B1_P,1),COLUMNS(B1_P)-1)+1)-INDEX(B1_P,1,MIN(MATCH($C$3,B1_P,1),COLUMNS(B1_P)-1))))*INDEX(B1_G,MIN(MATCH(MAX(D18,INDEX(B1_N,1)),B1_N,1),ROWS(B1_N)-1)+1,MIN(MATCH($C$3,B1_P,1),COLUMNS(B1_P)-1)+1))),IF((D18*$C$3)<INDEX(B2_NP,1),0.2,IF((D18*$C$3)>=INDEX(B2_NP,ROWS(B2_NP)),INDEX(B2_A,ROWS(B2_NP)),INDEX(B2_A,MATCH((D18*$C$3),B2_NP,1))+((D18*$C$3)-INDEX(B2_NP,MATCH((D18*$C$3),B2_NP,1)))*(INDEX(B2_A,MATCH((D18*$C$3),B2_NP,1)+1)-INDEX(B2_A,MATCH((D18*$C$3),B2_NP,1)))/(INDEX(B2_NP,MATCH((D18*$C$3),B2_NP,1)+1)-INDEX(B2_NP,MATCH((D18*$C$3),B2_NP,1)))))) -> 0.63170707 | G18: =5*$C$4*F18 -> 0.63170707 | H18: 25 | I18: =INDEX(VGP_DR,MATCH(H18,VGP_DN,0)) -> 26.1 | J18: =G18/1000/(PI()*(I18/1000)^2/4) -> 1.1807144 | K18: =1000*IF(J18<1.2,0.000912*J18^2/(I18/1000)^1.3*(1+0.867/J18)^0.3,0.00107*J18^2/(I18/1000)^1.3) -> 171.54941 | L18: =K18/1000*C18 -> 0.5489581 | M18: =L18*(1+$C$5) -> 0.71364553 | N18: =IF(AND(J18>=0.3,J18<=1.2),"да","нет") -> да
A19: 12 | B19: Ст.В1-4, эт. 3-2 | C19: 3.2 | D19: 72 | E19: =D19*$C$3 -> 0.48488636 | F19: =IF(AND($C$3>0.1,D19<=200),((1-MIN(1,(MAX(D19,INDEX(B1_N,1))-INDEX(B1_N,MIN(MATCH(MAX(D19,INDEX(B1_N,1)),B1_N,1),ROWS(B1_N)-1)))/(INDEX(B1_N,MIN(MATCH(MAX(D19,INDEX(B1_N,1)),B1_N,1),ROWS(B1_N)-1)+1)-INDEX(B1_N,MIN(MATCH(MAX(D19,INDEX(B1_N,1)),B1_N,1),ROWS(B1_N)-1)))))*((1-MIN(1,($C$3-INDEX(B1_P,1,MIN(MATCH($C$3,B1_P,1),COLUMNS(B1_P)-1)))/(INDEX(B1_P,1,MIN(MATCH($C$3,B1_P,1),COLUMNS(B1_P)-1)+1)-INDEX(B1_P,1,MIN(MATCH($C$3,B1_P,1),COLUMNS(B1_P)-1)))))*INDEX(B1_G,MIN(MATCH(MAX(D19,INDEX(B1_N,1)),B1_N,1),ROWS(B1_N)-1),MIN(MATCH($C$3,B1_P,1),COLUMNS(B1_P)-1))+MIN(1,($C$3-INDEX(B1_P,1,MIN(MATCH($C$3,B1_P,1),COLUMNS(B1_P)-1)))/(INDEX(B1_P,1,MIN(MATCH($C$3,B1_P,1),COLUMNS(B1_P)-1)+1)-INDEX(B1_P,1,MIN(MATCH($C$3,B1_P,1),COLUMNS(B1_P)-1))))*INDEX(B1_G,MIN(MATCH(MAX(D19,INDEX(B1_N,1)),B1_N,1),ROWS(B1_N)-1),MIN(MATCH($C$3,B1_P,1),COLUMNS(B1_P)-1)+1))+MIN(1,(MAX(D19,INDEX(B1_N,1))-INDEX(B1_N,MIN(MATCH(MAX(D19,INDEX(B1_N,1)),B1_N,1),ROWS(B1_N)-1)))/(INDEX(B1_N,MIN(MATCH(MAX(D19,INDEX(B1_N,1)),B1_N,1),ROWS(B1_N)-1)+1)-INDEX(B1_N,MIN(MATCH(MAX(D19,INDEX(B1_N,1)),B1_N,1),ROWS(B1_N)-1))))*((1-MIN(1,($C$3-INDEX(B1_P,1,MIN(MATCH($C$3,B1_P,1),COLUMNS(B1_P)-1)))/(INDEX(B1_P,1,MIN(MATCH($C$3,B1_P,1),COLUMNS(B1_P)-1)+1)-INDEX(B1_P,1,MIN(MATCH($C$3,B1_P,1),COLUMNS(B1_P)-1)))))*INDEX(B1_G,MIN(MATCH(MAX(D19,INDEX(B1_N,1)),B1_N,1),ROWS(B1_N)-1)+1,MIN(MATCH($C$3,B1_P,1),COLUMNS(B1_P)-1))+MIN(1,($C$3-INDEX(B1_P,1,MIN(MATCH($C$3,B1_P,1),COLUMNS(B1_P)-1)))/(INDEX(B1_P,1,MIN(MATCH($C$3,B1_P,1),COLUMNS(B1_P)-1)+1)-INDEX(B1_P,1,MIN(MATCH($C$3,B1_P,1),COLUMNS(B1_P)-1))))*INDEX(B1_G,MIN(MATCH(MAX(D19,INDEX(B1_N,1)),B1_N,1),ROWS(B1_N)-1)+1,MIN(MATCH($C$3,B1_P,1),COLUMNS(B1_P)-1)+1))),IF((D19*$C$3)<INDEX(B2_NP,1),0.2,IF((D19*$C$3)>=INDEX(B2_NP,ROWS(B2_NP)),INDEX(B2_A,ROWS(B2_NP)),INDEX(B2_A,MATCH((D19*$C$3),B2_NP,1))+((D19*$C$3)-INDEX(B2_NP,MATCH((D19*$C$3),B2_NP,1)))*(INDEX(B2_A,MATCH((D19*$C$3),B2_NP,1)+1)-INDEX(B2_A,MATCH((D19*$C$3),B2_NP,1)))/(INDEX(B2_NP,MATCH((D19*$C$3),B2_NP,1)+1)-INDEX(B2_NP,MATCH((D19*$C$3),B2_NP,1)))))) -> 0.66842045 | G19: =5*$C$4*F19 -> 0.66842045 | H19: 32 | I19: =INDEX(VGP_DR,MATCH(H19,VGP_DN,0)) -> 34.9 | J19: =G19/1000/(PI()*(I19/1000)^2/4) -> 0.69872937 | K19: =1000*IF(J19<1.2,0.000912*J19^2/(I19/1000)^1.3*(1+0.867/J19)^0.3,0.00107*J19^2/(I19/1000)^1.3) -> 44.469484 | L19: =K19/1000*C19 -> 0.14230235 | M19: =L19*(1+$C$5) -> 0.18499305 | N19: =IF(AND(J19>=0.3,J19<=1.2),"да","нет") -> да
A20: 13 | B20: Ст.В1-4, эт. 2-1 | C20: 3.2 | D20: 80 | E20: =D20*$C$3 -> 0.53876263 | F20: =IF(AND($C$3>0.1,D20<=200),((1-MIN(1,(MAX(D20,INDEX(B1_N,1))-INDEX(B1_N,MIN(MATCH(MAX(D20,INDEX(B1_N,1)),B1_N,1),ROWS(B1_N)-1)))/(INDEX(B1_N,MIN(MATCH(MAX(D20,INDEX(B1_N,1)),B1_N,1),ROWS(B1_N)-1)+1)-INDEX(B1_N,MIN(MATCH(MAX(D20,INDEX(B1_N,1)),B1_N,1),ROWS(B1_N)-1)))))*((1-MIN(1,($C$3-INDEX(B1_P,1,MIN(MATCH($C$3,B1_P,1),COLUMNS(B1_P)-1)))/(INDEX(B1_P,1,MIN(MATCH($C$3,B1_P,1),COLUMNS(B1_P)-1)+1)-INDEX(B1_P,1,MIN(MATCH($C$3,B1_P,1),COLUMNS(B1_P)-1)))))*INDEX(B1_G,MIN(MATCH(MAX(D20,INDEX(B1_N,1)),B1_N,1),ROWS(B1_N)-1),MIN(MATCH($C$3,B1_P,1),COLUMNS(B1_P)-1))+MIN(1,($C$3-INDEX(B1_P,1,MIN(MATCH($C$3,B1_P,1),COLUMNS(B1_P)-1)))/(INDEX(B1_P,1,MIN(MATCH($C$3,B1_P,1),COLUMNS(B1_P)-1)+1)-INDEX(B1_P,1,MIN(MATCH($C$3,B1_P,1),COLUMNS(B1_P)-1))))*INDEX(B1_G,MIN(MATCH(MAX(D20,INDEX(B1_N,1)),B1_N,1),ROWS(B1_N)-1),MIN(MATCH($C$3,B1_P,1),COLUMNS(B1_P)-1)+1))+MIN(1,(MAX(D20,INDEX(B1_N,1))-INDEX(B1_N,MIN(MATCH(MAX(D20,INDEX(B1_N,1)),B1_N,1),ROWS(B1_N)-1)))/(INDEX(B1_N,MIN(MATCH(MAX(D20,INDEX(B1_N,1)),B1_N,1),ROWS(B1_N)-1)+1)-INDEX(B1_N,MIN(MATCH(MAX(D20,INDEX(B1_N,1)),B1_N,1),ROWS(B1_N)-1))))*((1-MIN(1,($C$3-INDEX(B1_P,1,MIN(MATCH($C$3,B1_P,1),COLUMNS(B1_P)-1)))/(INDEX(B1_P,1,MIN(MATCH($C$3,B1_P,1),COLUMNS(B1_P)-1)+1)-INDEX(B1_P,1,MIN(MATCH($C$3,B1_P,1),COLUMNS(B1_P)-1)))))*INDEX(B1_G,MIN(MATCH(MAX(D20,INDEX(B1_N,1)),B1_N,1),ROWS(B1_N)-1)+1,MIN(MATCH($C$3,B1_P,1),COLUMNS(B1_P)-1))+MIN(1,($C$3-INDEX(B1_P,1,MIN(MATCH($C$3,B1_P,1),COLUMNS(B1_P)-1)))/(INDEX(B1_P,1,MIN(MATCH($C$3,B1_P,1),COLUMNS(B1_P)-1)+1)-INDEX(B1_P,1,MIN(MATCH($C$3,B1_P,1),COLUMNS(B1_P)-1))))*INDEX(B1_G,MIN(MATCH(MAX(D20,INDEX(B1_N,1)),B1_N,1),ROWS(B1_N)-1)+1,MIN(MATCH($C$3,B1_P,1),COLUMNS(B1_P)-1)+1))),IF((D20*$C$3)<INDEX(B2_NP,1),0.2,IF((D20*$C$3)>=INDEX(B2_NP,ROWS(B2_NP)),INDEX(B2_A,ROWS(B2_NP)),INDEX(B2_A,MATCH((D20*$C$3),B2_NP,1))+((D20*$C$3)-INDEX(B2_NP,MATCH((D20*$C$3),B2_NP,1)))*(INDEX(B2_A,MATCH((D20*$C$3),B2_NP,1)+1)-INDEX(B2_A,MATCH((D20*$C$3),B2_NP,1)))/(INDEX(B2_NP,MATCH((D20*$C$3),B2_NP,1)+1)-INDEX(B2_NP,MATCH((D20*$C$3),B2_NP,1)))))) -> 0.70325758 | G20: =5*$C$4*F20 -> 0.70325758 | H20: 32 | I20: =INDEX(VGP_DR,MATCH(H20,VGP_DN,0)) -> 34.9 | J20: =G20/1000/(PI()*(I20/1000)^2/4) -> 0.73514614 | K20: =1000*IF(J20<1.2,0.000912*J20^2/(I20/1000)^1.3*(1+0.867/J20)^0.3,0.00107*J20^2/(I20/1000)^1.3) -> 48.816618 | L20: =K20/1000*C20 -> 0.15621318 | M20: =L20*(1+$C$5) -> 0.20307713 | N20: =IF(AND(J20>=0.3,J20<=1.2),"да","нет") -> да
A21: 14 | B21: Ст.В1-4, эт. 1 - магистраль | C21: 1.3 | D21: 88 | E21: =D21*$C$3 -> 0.59263889 | F21: =IF(AND($C$3>0.1,D21<=200),((1-MIN(1,(MAX(D21,INDEX(B1_N,1))-INDEX(B1_N,MIN(MATCH(MAX(D21,INDEX(B1_N,1)),B1_N,1),ROWS(B1_N)-1)))/(INDEX(B1_N,MIN(MATCH(MAX(D21,INDEX(B1_N,1)),B1_N,1),ROWS(B1_N)-1)+1)-INDEX(B1_N,MIN(MATCH(MAX(D21,INDEX(B1_N,1)),B1_N,1),ROWS(B1_N)-1)))))*((1-MIN(1,($C$3-INDEX(B1_P,1,MIN(MATCH($C$3,B1_P,1),COLUMNS(B1_P)-1)))/(INDEX(B1_P,1,MIN(MATCH($C$3,B1_P,1),COLUMNS(B1_P)-1)+1)-INDEX(B1_P,1,MIN(MATCH($C$3,B1_P,1),COLUMNS(B1_P)-1)))))*INDEX(B1_G,MIN(MATCH(MAX(D21,INDEX(B1_N,1)),B1_N,1),ROWS(B1_N)-1),MIN(MATCH($C$3,B1_P,1),COLUMNS(B1_P)-1))+MIN(1,($C$3-INDEX(B1_P,1,MIN(MATCH($C$3,B1_P,1),COLUMNS(B1_P)-1)))/(INDEX(B1_P,1,MIN(MATCH($C$3,B1_P,1),COLUMNS(B1_P)-1)+1)-INDEX(B1_P,1,MIN(MATCH($C$3,B1_P,1),COLUMNS(B1_P)-1))))*INDEX(B1_G,MIN(MATCH(MAX(D21,INDEX(B1_N,1)),B1_N,1),ROWS(B1_N)-1),MIN(MATCH($C$3,B1_P,1),COLUMNS(B1_P)-1)+1))+MIN(1,(MAX(D21,INDEX(B1_N,1))-INDEX(B1_N,MIN(MATCH(MAX(D21,INDEX(B1_N,1)),B1_N,1),ROWS(B1_N)-1)))/(INDEX(B1_N,MIN(MATCH(MAX(D21,INDEX(B1_N,1)),B1_N,1),ROWS(B1_N)-1)+1)-INDEX(B1_N,MIN(MATCH(MAX(D21,INDEX(B1_N,1)),B1_N,1),ROWS(B1_N)-1))))*((1-MIN(1,($C$3-INDEX(B1_P,1,MIN(MATCH($C$3,B1_P,1),COLUMNS(B1_P)-1)))/(INDEX(B1_P,1,MIN(MATCH($C$3,B1_P,1),COLUMNS(B1_P)-1)+1)-INDEX(B1_P,1,MIN(MATCH($C$3,B1_P,1),COLUMNS(B1_P)-1)))))*INDEX(B1_G,MIN(MATCH(MAX(D21,INDEX(B1_N,1)),B1_N,1),ROWS(B1_N)-1)+1,MIN(MATCH($C$3,B1_P,1),COLUMNS(B1_P)-1))+MIN(1,($C$3-INDEX(B1_P,1,MIN(MATCH($C$3,B1_P,1),COLUMNS(B1_P)-1)))/(INDEX(B1_P,1,MIN(MATCH($C$3,B1_P,1),COLUMNS(B1_P)-1)+1)-INDEX(B1_P,1,MIN(MATCH($C$3,B1_P,1),COLUMNS(B1_P)-1))))*INDEX(B1_G,MIN(MATCH(MAX(D21,INDEX(B1_N,1)),B1_N,1),ROWS(B1_N)-1)+1,MIN(MATCH($C$3,B1_P,1),COLUMNS(B1_P)-1)+1))),IF((D21*$C$3)<INDEX(B2_NP,1),0.2,IF((D21*$C$3)>=INDEX(B2_NP,ROWS(B2_NP)),INDEX(B2_A,ROWS(B2_NP)),INDEX(B2_A,MATCH((D21*$C$3),B2_NP,1))+((D21*$C$3)-INDEX(B2_NP,MATCH((D21*$C$3),B2_NP,1)))*(INDEX(B2_A,MATCH((D21*$C$3),B2_NP,1)+1)-INDEX(B2_A,MATCH((D21*$C$3),B2_NP,1)))/(INDEX(B2_NP,MATCH((D21*$C$3),B2_NP,1)+1)-INDEX(B2_NP,MATCH((D21*$C$3),B2_NP,1)))))) -> 0.73758333 | G21: =5*$C$4*F21 -> 0.73758333 | H21: 32 | I21: =INDEX(VGP_DR,MATCH(H21,VGP_DN,0)) -> 34.9 | J21: =G21/1000/(PI()*(I21/1000)^2/4) -> 0.77102837 | K21: =1000*IF(J21<1.2,0.000912*J21^2/(I21/1000)^1.3*(1+0.867/J21)^0.3,0.00107*J21^2/(I21/1000)^1.3) -> 53.289031 | L21: =K21/1000*C21 -> 0.06927574 | M21: =L21*(1+$C$5) -> 0.090058462 | N21: =IF(AND(J21>=0.3,J21<=1.2),"да","нет") -> да
A22: 15 | B22: магистраль Ст.В1-4 – Ст.В1-3 | C22: 15.3 | D22: 88 | E22: =D22*$C$3 -> 0.59263889 | F22: =IF(AND($C$3>0.1,D22<=200),((1-MIN(1,(MAX(D22,INDEX(B1_N,1))-INDEX(B1_N,MIN(MATCH(MAX(D22,INDEX(B1_N,1)),B1_N,1),ROWS(B1_N)-1)))/(INDEX(B1_N,MIN(MATCH(MAX(D22,INDEX(B1_N,1)),B1_N,1),ROWS(B1_N)-1)+1)-INDEX(B1_N,MIN(MATCH(MAX(D22,INDEX(B1_N,1)),B1_N,1),ROWS(B1_N)-1)))))*((1-MIN(1,($C$3-INDEX(B1_P,1,MIN(MATCH($C$3,B1_P,1),COLUMNS(B1_P)-1)))/(INDEX(B1_P,1,MIN(MATCH($C$3,B1_P,1),COLUMNS(B1_P)-1)+1)-INDEX(B1_P,1,MIN(MATCH($C$3,B1_P,1),COLUMNS(B1_P)-1)))))*INDEX(B1_G,MIN(MATCH(MAX(D22,INDEX(B1_N,1)),B1_N,1),ROWS(B1_N)-1),MIN(MATCH($C$3,B1_P,1),COLUMNS(B1_P)-1))+MIN(1,($C$3-INDEX(B1_P,1,MIN(MATCH($C$3,B1_P,1),COLUMNS(B1_P)-1)))/(INDEX(B1_P,1,MIN(MATCH($C$3,B1_P,1),COLUMNS(B1_P)-1)+1)-INDEX(B1_P,1,MIN(MATCH($C$3,B1_P,1),COLUMNS(B1_P)-1))))*INDEX(B1_G,MIN(MATCH(MAX(D22,INDEX(B1_N,1)),B1_N,1),ROWS(B1_N)-1),MIN(MATCH($C$3,B1_P,1),COLUMNS(B1_P)-1)+1))+MIN(1,(MAX(D22,INDEX(B1_N,1))-INDEX(B1_N,MIN(MATCH(MAX(D22,INDEX(B1_N,1)),B1_N,1),ROWS(B1_N)-1)))/(INDEX(B1_N,MIN(MATCH(MAX(D22,INDEX(B1_N,1)),B1_N,1),ROWS(B1_N)-1)+1)-INDEX(B1_N,MIN(MATCH(MAX(D22,INDEX(B1_N,1)),B1_N,1),ROWS(B1_N)-1))))*((1-MIN(1,($C$3-INDEX(B1_P,1,MIN(MATCH($C$3,B1_P,1),COLUMNS(B1_P)-1)))/(INDEX(B1_P,1,MIN(MATCH($C$3,B1_P,1),COLUMNS(B1_P)-1)+1)-INDEX(B1_P,1,MIN(MATCH($C$3,B1_P,1),COLUMNS(B1_P)-1)))))*INDEX(B1_G,MIN(MATCH(MAX(D22,INDEX(B1_N,1)),B1_N,1),ROWS(B1_N)-1)+1,MIN(MATCH($C$3,B1_P,1),COLUMNS(B1_P)-1))+MIN(1,($C$3-INDEX(B1_P,1,MIN(MATCH($C$3,B1_P,1),COLUMNS(B1_P)-1)))/(INDEX(B1_P,1,MIN(MATCH($C$3,B1_P,1),COLUMNS(B1_P)-1)+1)-INDEX(B1_P,1,MIN(MATCH($C$3,B1_P,1),COLUMNS(B1_P)-1))))*INDEX(B1_G,MIN(MATCH(MAX(D22,INDEX(B1_N,1)),B1_N,1),ROWS(B1_N)-1)+1,MIN(MATCH($C$3,B1_P,1),COLUMNS(B1_P)-1)+1))),IF((D22*$C$3)<INDEX(B2_NP,1),0.2,IF((D22*$C$3)>=INDEX(B2_NP,ROWS(B2_NP)),INDEX(B2_A,ROWS(B2_NP)),INDEX(B2_A,MATCH((D22*$C$3),B2_NP,1))+((D22*$C$3)-INDEX(B2_NP,MATCH((D22*$C$3),B2_NP,1)))*(INDEX(B2_A,MATCH((D22*$C$3),B2_NP,1)+1)-INDEX(B2_A,MATCH((D22*$C$3),B2_NP,1)))/(INDEX(B2_NP,MATCH((D22*$C$3),B2_NP,1)+1)-INDEX(B2_NP,MATCH((D22*$C$3),B2_NP,1)))))) -> 0.73758333 | G22: =5*$C$4*F22 -> 0.73758333 | H22: 32 | I22: =INDEX(VGP_DR,MATCH(H22,VGP_DN,0)) -> 34.9 | J22: =G22/1000/(PI()*(I22/1000)^2/4) -> 0.77102837 | K22: =1000*IF(J22<1.2,0.000912*J22^2/(I22/1000)^1.3*(1+0.867/J22)^0.3,0.00107*J22^2/(I22/1000)^1.3) -> 53.289031 | L22: =K22/1000*C22 -> 0.81532217 | M22: =L22*(1+$C$5) -> 1.0599188 | N22: =IF(AND(J22>=0.3,J22<=1.2),"да","нет") -> да
... A25: 18 | B25: в насосной (после ответвления на ГВС) | C25: 3.5 | D25: 264 | E25: =D25*$C$3 -> 1.7779167 | F25: =IF(AND($C$3>0.1,D25<=200),((1-MIN(1,(MAX(D25,INDEX(B1_N,1))-INDEX(B1_N,MIN(MATCH(MAX(D25,INDEX(B1_N,1)),B1_N,1),ROWS(B1_N)-1)))/(INDEX(B1_N,MIN(MATCH(MAX(D25,INDEX(B1_N,1)),B1_N,1),ROWS(B1_N)-1)+1)-INDEX(B1_N,MIN(MATCH(MAX(D25,INDEX(B1_N,1)),B1_N,1),ROWS(B1_N)-1)))))*((1-MIN(1,($C$3-INDEX(B1_P,1,MIN(MATCH($C$3,B1_P,1),COLUMNS(B1_P)-1)))/(INDEX(B1_P,1,MIN(MATCH($C$3,B1_P,1),COLUMNS(B1_P)-1)+1)-INDEX(B1_P,1,MIN(MATCH($C$3,B1_P,1),COLUMNS(B1_P)-1)))))*INDEX(B1_G,MIN(MATCH(MAX(D25,INDEX(B1_N,1)),B1_N,1),ROWS(B1_N)-1),MIN(MATCH($C$3,B1_P,1),COLUMNS(B1_P)-1))+MIN(1,($C$3-INDEX(B1_P,1,MIN(MATCH($C$3,B1_P,1),COLUMNS(B1_P)-1)))/(INDEX(B1_P,1,MIN(MATCH($C$3,B1_P,1),COLUMNS(B1_P)-1)+1)-INDEX(B1_P,1,MIN(MATCH($C$3,B1_P,1),COLUMNS(B1_P)-1))))*INDEX(B1_G,MIN(MATCH(MAX(D25,INDEX(B1_N,1)),B1_N,1),ROWS(B1_N)-1),MIN(MATCH($C$3,B1_P,1),COLUMNS(B1_P)-1)+1))+MIN(1,(MAX(D25,INDEX(B1_N,1))-INDEX(B1_N,MIN(MATCH(MAX(D25,INDEX(B1_N,1)),B1_N,1),ROWS(B1_N)-1)))/(INDEX(B1_N,MIN(MATCH(MAX(D25,INDEX(B1_N,1)),B1_N,1),ROWS(B1_N)-1)+1)-INDEX(B1_N,MIN(MATCH(MAX(D25,INDEX(B1_N,1)),B1_N,1),ROWS(B1_N)-1))))*((1-MIN(1,($C$3-INDEX(B1_P,1,MIN(MATCH($C$3,B1_P,1),COLUMNS(B1_P)-1)))/(INDEX(B1_P,1,MIN(MATCH($C$3,B1_P,1),COLUMNS(B1_P)-1)+1)-INDEX(B1_P,1,MIN(MATCH($C$3,B1_P,1),COLUMNS(B1_P)-1)))))*INDEX(B1_G,MIN(MATCH(MAX(D25,INDEX(B1_N,1)),B1_N,1),ROWS(B1_N)-1)+1,MIN(MATCH($C$3,B1_P,1),COLUMNS(B1_P)-1))+MIN(1,($C$3-INDEX(B1_P,1,MIN(MATCH($C$3,B1_P,1),COLUMNS(B1_P)-1)))/(INDEX(B1_P,1,MIN(MATCH($C$3,B1_P,1),COLUMNS(B1_P)-1)+1)-INDEX(B1_P,1,MIN(MATCH($C$3,B1_P,1),COLUMNS(B1_P)-1))))*INDEX(B1_G,MIN(MATCH(MAX(D25,INDEX(B1_N,1)),B1_N,1),ROWS(B1_N)-1)+1,MIN(MATCH($C$3,B1_P,1),COLUMNS(B1_P)-1)+1))),IF((D25*$C$3)<INDEX(B2_NP,1),0.2,IF((D25*$C$3)>=INDEX(B2_NP,ROWS(B2_NP)),INDEX(B2_A,ROWS(B2_NP)),INDEX(B2_A,MATCH((D25*$C$3),B2_NP,1))+((D25*$C$3)-INDEX(B2_NP,MATCH((D25*$C$3),B2_NP,1)))*(INDEX(B2_A,MATCH((D25*$C$3),B2_NP,1)+1)-INDEX(B2_A,MATCH((D25*$C$3),B2_NP,1)))/(INDEX(B2_NP,MATCH((D25*$C$3),B2_NP,1)+1)-INDEX(B2_NP,MATCH((D25*$C$3),B2_NP,1)))))) -> 1.3402833 | G25: =5*$C$4*F25 -> 1.3402833 | H25: 40 | I25: =INDEX(VGP_DR,MATCH(H25,VGP_DN,0)) -> 40 | J25: =G25/1000/(PI()*(I25/1000)^2/4) -> 1.0665636 | K25: =1000*IF(J25<1.2,0.000912*J25^2/(I25/1000)^1.3*(1+0.867/J25)^0.3,0.00107*J25^2/(I25/1000)^1.3) -> 81.433269 | L25: =K25/1000*C25 -> 0.28501644 | M25: =L25*(1+$C$5) -> 0.37052137 | N25: =IF(AND(J25>=0.3,J25<=1.2),"да","нет") -> да
L26: Σh, м | M26: =SUM(M8:M25) -> 9.3150721
A27: Потери по Шевелёву для неновых стальных труб: v < 1,2 м/с — i = 0,000912·v²/d^1,3·(1 + 0,867/v)^0,3; v ≥ 1,2 м/с — i = 0,00107·v²/d^1,3 (d — расчётный диаметр, м). Скорость: магистраль и стояки до 1,2 м/с, подводки до 1,5 м/с.
B29: Ввод (общий расход — ГВС готовится в ИТП здания)
B30: q^tot, л/с | C30: =Расходы!N4 -> 2.5835556
B31: Ø ПЭ100 SDR17, мм | C31: 63
B32: d_вн, мм | C32: =INDEX(PE_DV,MATCH(C31,PE_DN,0)) -> 55.4
B33: v, м/с | C33: =C30/1000/(PI()*(C32/1000)^2/4) -> 1.0717868
B34: Re (ν = 1,31·10⁻⁶ м²/с) | C34: =C33*C32/1000/0.00000131 -> 45325.945
B35: λ (Свами–Джейн, Δ = 0,01 мм) | C35: =0.25/LOG10(0.00001/(3.7*C32/1000)+5.74/C34^0.9)^2 -> 0.021908772
B36: i | C36: =C35/(C32/1000)*C33^2/(2*9.81) -> 0.023154002
B37: Длина ввода L, м | C37: 25
B38: h_ввод = i·L·(1 + K_м.с), м | C38: =C36*C37*(1+$C$5) -> 0.75250506

Sheet Напор
A1: Счётчики воды, требуемый напор и насосная установка
A3: Общедомовой счётчик (пп. 12.14–12.16)
A5: Среднечасовой расход q_T^tot, м³/ч | C5: =Расходы!J4 -> 1.8825
A6: Секундный расход q^tot, л/с | C6: =Расходы!N4 -> 2.5835556
A7: Принят DN (наименьший подходящий по табл. 12.1) | C7: =INDEX(T121_DN,MATCH(TRUE(),T121_OK,0)) -> 40
A8: S, м/(л/с)² | C8: =INDEX(T121_S,MATCH(C7,T121_DN,0)) -> 0.5
A9: h_сч = S·q², м | C9: =C8*C6^2 -> 3.3373797
A11: Квартирный счётчик холодной воды
A12: Приборов в квартире (холодная вода) | C12: =Исходные!C15 -> 4
