Workbook

Sheet Содержание
A1: Курсовая работа по ТСП «Технологическая карта на производство земляных работ», вариант 2: таблицы расчёта
A3: № | B3: Лист | C3: Содержание
A4: 1 | B4: Исходные данные | C4: Рабочие отметки варианта 2, коэффициенты kо.р и kр
A5: 2 | B5: ЛНР (черн.) | C5: Точки нулевых работ (п. 2.2.1), черновик
A6: 3 | B6: Табл. 1 объёмы (черн.) | C6: Ведомость объёмов работ по вертикальной планировке (табл. 1), черновик
A7: 4 | B7: Котлован (черн.) | C7: Контуры, размеры и объём котлована (п. 2.2.2), черновик
A8: 5 | B8: Табл. 2 баланс (черн.) | C8: Сводная ведомость объёмов грунта (табл. 2) и поправка Δh (п. 2.2.3)
A9: 6 | B9: Отметки (оконч.) | C9: Окончательные рабочие отметки h + Δh
A10: 7 | B10: ЛНР (оконч.) | C10: Точки нулевых работ по окончательным отметкам
A11: 8 | B11: Табл. 1 объёмы (оконч.) | C11: Ведомость объёмов работ по вертикальной планировке (табл. 1), окончательная
A12: 9 | B12: Котлован (оконч.) | C12: Котлован по окончательным отметкам: съезд, обратная засыпка
A13: 10 | B13: Табл. 2 баланс (оконч.) | C13: Сводная ведомость объёмов грунта (табл. 2), окончательная
A14: 11 | B14: Табл. 3 котлован | C14: Баланс земляных работ по котловану (табл. 3, п. 2.2.4)
A15: 12 | B15: Табл. 4 распределение | C15: Баланс распределения земляных масс (табл. 4, п. 2.2.5)
... A20: 17 | B20: 2.3.2 Экскаватор, самосвалы | C20: Выбор экскаватора и автосамосвалов (п. 2.3.2)

Sheet Исходные данные
A1: Курсовая работа «Технологическая карта на производство земляных работ». Вариант 2
A3: Сторона квадрата сетки a, м | B3: 100 | D3: Редактировать можно только синие ячейки (жёлтая — принятое допущение).
A4: Коэффициент остаточного разрыхления Kор | B4: 1.04 | D4: Рабочая отметка h = Hкр − Hчёрн: «−» — выемка (ПВ), «+» — насыпь (ПН).
A5: Грунт | B5: супесь | D5: Отметки — вариант 2. Вершины нумеруются построчно слева направо, сверху вниз.
A6: Число квадратов | B6: 15
A7: Коэффициент первоначального разрыхления kр | B7: 1.15
A8: № вершины | B8: h, м | D8: Схема сетки (вид в плане, квадрат 100×100 м)
A9: h1 | B9: -0.25 | D9: h1 | E9: h2 | F9: h3 | G9: h4 | H9: h5 | I9: h6
A10: h2 | B10: 0.15 | D10: =B9 -> -0.25 | E10: =B10 -> 0.15 | F10: =B11 -> 0.34 | G10: =B12 -> 0.47 | H10: =B13 -> 0.66 | I10: =B14 -> 0.85
A11: h3 | B11: 0.34 | D11: h7 | E11: h8 | F11: h9 | G11: h10 | H11: h11 | I11: h12
A12: h4 | B12: 0.47 | D12: =B15 -> -0.49 | E12: =B16 -> -0.31 | F12: =B17 -> 0.28 | G12: =B18 -> 0.52 | H12: =B19 -> 0.84 | I12: =B20 -> 0.47
A13: h5 | B13: 0.66 | D13: h13 | E13: h14 | F13: h15 | G13: h16 | H13: h17 | I13: h18
A14: h6 | B14: 0.85 | D14: =B21 -> -0.24 | E14: =B22 -> -0.43 | F14: =B23 -> -0.28 | G14: =B24 -> 0.14 | H14: =B25 -> 0.36 | I14: =B26 -> 0.76
A15: h7 | B15: -0.49 | D15: h19 | E15: h20 | F15: h21 | G15: h22 | H15: h23 | I15: h24
A16: h8 | B16: -0.31 | D16: =B27 -> -0.4 | E16: =B28 -> -0.65 | F16: =B29 -> -0.52 | G16: =B30 -> -0.28 | H16: =B31 -> -0.43 | I16: =B32 -> 0.14
A17: h9 | B17: 0.28
A18: h10 | B18: 0.52
A19: h11 | B19: 0.84
A20: h12 | B20: 0.47
A21: h13 | B21: -0.24
A22: h14 | B22: -0.43
A23: h15 | B23: -0.28
A24: h16 | B24: 0.14
A25: h17 | B25: 0.36
A26: h18 | B26: 0.76
A27: h19 | B27: -0.4
A28: h20 | B28: -0.65
... A32: h24 | B32: 0.14

Sheet ЛНР (черн.)
A1: Точки нулевых работ на сторонах квадратов (черновик)
A2: x1 = a·|h1| / (|h1| + |h2|) — расстояние от вершины 1 до точки нуля; x2 = a − x1
A4: № т.0 | B4: Сторона | C4: Вершина 1 | D4: h1, м | E4: Вершина 2 | F4: h2, м | G4: x1 (от верш. 1), м | H4: x2 (от верш. 2), м
A5: 1 | B5: горизонтальная | C5: h1 | D5: ='Исходные данные'!$B$9 -> -0.25 | E5: h2 | F5: ='Исходные данные'!$B$10 -> 0.15 | G5: ='Исходные данные'!$B$3*ABS(D5)/(ABS(D5)+ABS(F5)) -> 62.5 | H5: ='Исходные данные'!$B$3-G5 -> 37.5
A6: 2 | B6: вертикальная | C6: h2 | D6: ='Исходные данные'!$B$10 -> 0.15 | E6: h8 | F6: ='Исходные данные'!$B$16 -> -0.31 | G6: ='Исходные данные'!$B$3*ABS(D6)/(ABS(D6)+ABS(F6)) -> 32.608696 | H6: ='Исходные данные'!$B$3-G6 -> 67.391304
A7: 3 | B7: горизонтальная | C7: h8 | D7: ='Исходные данные'!$B$16 -> -0.31 | E7: h9 | F7: ='Исходные данные'!$B$17 -> 0.28 | G7: ='Исходные данные'!$B$3*ABS(D7)/(ABS(D7)+ABS(F7)) -> 52.542373 | H7: ='Исходные данные'!$B$3-G7 -> 47.457627
A8: 4 | B8: вертикальная | C8: h9 | D8: ='Исходные данные'!$B$17 -> 0.28 | E8: h15 | F8: ='Исходные данные'!$B$23 -> -0.28 | G8: ='Исходные данные'!$B$3*ABS(D8)/(ABS(D8)+ABS(F8)) -> 50 | H8: ='Исходные данные'!$B$3-G8 -> 50
A9: 5 | B9: горизонтальная | C9: h15 | D9: ='Исходные данные'!$B$23 -> -0.28 | E9: h16 | F9: ='Исходные данные'!$B$24 -> 0.14 | G9: ='Исходные данные'!$B$3*ABS(D9)/(ABS(D9)+ABS(F9)) -> 66.666667 | H9: ='Исходные данные'!$B$3-G9 -> 33.333333
A10: 6 | B10: вертикальная | C10: h16 | D10: ='Исходные данные'!$B$24 -> 0.14 | E10: h22 | F10: ='Исходные данные'!$B$30 -> -0.28 | G10: ='Исходные данные'!$B$3*ABS(D10)/(ABS(D10)+ABS(F10)) -> 33.333333 | H10: ='Исходные данные'!$B$3-G10 -> 66.666667
A11: 7 | B11: вертикальная | C11: h17 | D11: ='Исходные данные'!$B$25 -> 0.36 | E11: h23 | F11: ='Исходные данные'!$B$31 -> -0.43 | G11: ='Исходные данные'!$B$3*ABS(D11)/(ABS(D11)+ABS(F11)) -> 45.56962 | H11: ='Исходные данные'!$B$3-G11 -> 54.43038
A12: 8 | B12: горизонтальная | C12: h23 | D12: ='Исходные данные'!$B$31 -> -0.43 | E12: h24 | F12: ='Исходные данные'!$B$32 -> 0.14 | G12: ='Исходные данные'!$B$3*ABS(D12)/(ABS(D12)+ABS(F12)) -> 75.438596 | H12: ='Исходные данные'!$B$3-G12 -> 24.561404

Sheet Табл. 1 объёмы (черн.)
A1: Объёмы планировочных работ (метод квадратов), черновик
A2: Vi = Fi · hср,i; hср,i = (|h1| + |h2| + … + |hn|) / n, в точках нуля h = 0
A4: Планировочная выемка (ПВ) | E4: Планировочная насыпь (ПН)
A5: № фигуры | B5: Fi, м² | C5: hср, м | D5: Vi, м³ | E5: № фигуры | F5: Fi, м² | G5: hср, м | H5: Vi, м³ | I5: Vгр = Vi / Kор, м³
A6: 1 | B6: ='Исходные данные'!$B$3^2-$F$6 -> 9388.587 | C6: =(0+ABS('Исходные данные'!$B$9)+ABS('Исходные данные'!$B$15)+ABS('Исходные данные'!$B$16)+0)/5 -> 0.21 | D6: =B6*C6 -> 1971.6033 | E6: 1' | F6: ='ЛНР (черн.)'!$G$6*'ЛНР (черн.)'!$H$5/2 -> 611.41304 | G6: =(0+ABS('Исходные данные'!$B$10)+0)/3 -> 0.05 | H6: =F6*G6 -> 30.570652 | I6: =H6/'Исходные данные'!$B$4 -> 29.394858
A7: 2 | B7: ='ЛНР (черн.)'!$H$6*'ЛНР (черн.)'!$G$7/2 -> 1770.4495 | C7: =(0+ABS('Исходные данные'!$B$16)+0)/3 -> 0.10333333 | D7: =B7*C7 -> 182.94645 | E7: 2' | F7: ='Исходные данные'!$B$3^2-$B$7 -> 8229.5505 | G7: =(0+ABS('Исходные данные'!$B$17)+ABS('Исходные данные'!$B$11)+ABS('Исходные данные'!$B$10)+0)/5 -> 0.154 | H7: =F7*G7 -> 1267.3508 | I7: =H7/'Исходные данные'!$B$4 -> 1218.6065
A8: — | B8: — | C8: — | D8: — | E8: 3 | F8: ='Исходные данные'!$B$3^2 -> 10000 | G8: =(ABS('Исходные данные'!$B$17)+ABS('Исходные данные'!$B$18)+ABS('Исходные данные'!$B$12)+ABS('Исходные данные'!$B$11))/4 -> 0.4025 | H8: =F8*G8 -> 4025 | I8: =H8/'Исходные данные'!$B$4 -> 3870.1923
A9: — | B9: — | C9: — | D9: — | E9: 4 | F9: ='Исходные данные'!$B$3^2 -> 10000 | G9: =(ABS('Исходные данные'!$B$18)+ABS('Исходные данные'!$B$19)+ABS('Исходные данные'!$B$13)+ABS('Исходные данные'!$B$12))/4 -> 0.6225 | H9: =F9*G9 -> 6225 | I9: =H9/'Исходные данные'!$B$4 -> 5985.5769
A10: — | B10: — | C10: — | D10: — | E10: 5 | F10: ='Исходные данные'!$B$3^2 -> 10000 | G10: =(ABS('Исходные данные'!$B$19)+ABS('Исходные данные'!$B$20)+ABS('Исходные данные'!$B$14)+ABS('Исходные данные'!$B$13))/4 -> 0.705 | H10: =F10*G10 -> 7050 | I10: =H10/'Исходные данные'!$B$4 -> 6778.8462
A11: 6 | B11: ='Исходные данные'!$B$3^2 -> 10000 | C11: =(ABS('Исходные данные'!$B$21)+ABS('Исходные данные'!$B$22)+ABS('Исходные данные'!$B$16)+ABS('Исходные данные'!$B$15))/4 -> 0.3675 | D11: =B11*C11 -> 3675 | E11: — | F11: — | G11: — | H11: — | I11: —
A12: 7 | B12: ='Исходные данные'!$B$3^2-$F$12 -> 8813.5593 | C12: =(0+ABS('Исходные данные'!$B$16)+ABS('Исходные данные'!$B$22)+ABS('Исходные данные'!$B$23)+0)/5 -> 0.204 | D12: =B12*C12 -> 1797.9661 | E12: 7' | F12: ='ЛНР (черн.)'!$G$8*'ЛНР (черн.)'!$H$7/2 -> 1186.4407 | G12: =(0+ABS('Исходные данные'!$B$17)+0)/3 -> 0.093333333 | H12: =F12*G12 -> 110.73446 | I12: =H12/'Исходные данные'!$B$4 -> 106.47545
A13: 8 | B13: ='ЛНР (черн.)'!$H$8*'ЛНР (черн.)'!$G$9/2 -> 1666.6667 | C13: =(0+ABS('Исходные данные'!$B$23)+0)/3 -> 0.093333333 | D13: =B13*C13 -> 155.55556 | E13: 8' | F13: ='Исходные данные'!$B$3^2-$B$13 -> 8333.3333 | G13: =(0+ABS('Исходные данные'!$B$24)+ABS('Исходные данные'!$B$18)+ABS('Исходные данные'!$B$17)+0)/5 -> 0.188 | H13: =F13*G13 -> 1566.6667 | I13: =H13/'Исходные данные'!$B$4 -> 1506.4103
A14: — | B14: — | C14: — | D14: — | E14: 9 | F14: ='Исходные данные'!$B$3^2 -> 10000 | G14: =(ABS('Исходные данные'!$B$24)+ABS('Исходные данные'!$B$25)+ABS('Исходные данные'!$B$19)+ABS('Исходные данные'!$B$18))/4 -> 0.465 | H14: =F14*G14 -> 4650 | I14: =H14/'Исходные данные'!$B$4 -> 4471.1538
A15: — | B15: — | C15: — | D15: — | E15: 10 | F15: ='Исходные данные'!$B$3^2 -> 10000 | G15: =(ABS('Исходные данные'!$B$25)+ABS('Исходные данные'!$B$26)+ABS('Исходные данные'!$B$20)+ABS('Исходные данные'!$B$19))/4 -> 0.6075 | H15: =F15*G15 -> 6075 | I15: =H15/'Исходные данные'!$B$4 -> 5841.3462
A16: 11 | B16: ='Исходные данные'!$B$3^2 -> 10000 | C16: =(ABS('Исходные данные'!$B$27)+ABS('Исходные данные'!$B$28)+ABS('Исходные данные'!$B$22)+ABS('Исходные данные'!$B$21))/4 -> 0.43 | D16: =B16*C16 -> 4300 | E16: — | F16: — | G16: — | H16: — | I16: —
A17: 12 | B17: ='Исходные данные'!$B$3^2 -> 10000 | C17: =(ABS('Исходные данные'!$B$28)+ABS('Исходные данные'!$B$29)+ABS('Исходные данные'!$B$23)+ABS('Исходные данные'!$B$22))/4 -> 0.47 | D17: =B17*C17 -> 4700 | E17: — | F17: — | G17: — | H17: — | I17: —
A18: 13 | B18: ='Исходные данные'!$B$3^2-$F$18 -> 9444.4444 | C18: =(0+ABS('Исходные данные'!$B$23)+ABS('Исходные данные'!$B$29)+ABS('Исходные данные'!$B$30)+0)/5 -> 0.216 | D18: =B18*C18 -> 2040 | E18: 13' | F18: ='ЛНР (черн.)'!$G$10*'ЛНР (черн.)'!$H$9/2 -> 555.55556 | G18: =(0+ABS('Исходные данные'!$B$24)+0)/3 -> 0.046666667 | H18: =F18*G18 -> 25.925926 | I18: =H18/'Исходные данные'!$B$4 -> 24.928775
A19: 14 | B19: =('ЛНР (черн.)'!$H$10+'ЛНР (черн.)'!$H$11)/2*'Исходные данные'!$B$3 -> 6054.8523 | C19: =(0+ABS('Исходные данные'!$B$30)+ABS('Исходные данные'!$B$31)+0)/4 -> 0.1775 | D19: =B19*C19 -> 1074.7363 | E19: 14' | F19: =('ЛНР (черн.)'!$G$11+'ЛНР (черн.)'!$G$10)/2*'Исходные данные'!$B$3 -> 3945.1477 | G19: =(0+ABS('Исходные данные'!$B$25)+ABS('Исходные данные'!$B$24)+0)/4 -> 0.125 | H19: =F19*G19 -> 493.14346 | I19: =H19/'Исходные данные'!$B$4 -> 474.1764
A20: 15 | B20: ='ЛНР (черн.)'!$H$11*'ЛНР (черн.)'!$G$12/2 -> 2053.0757 | C20: =(0+ABS('Исходные данные'!$B$31)+0)/3 -> 0.14333333 | D20: =B20*C20 -> 294.27419 | E20: 15' | F20: ='Исходные данные'!$B$3^2-$B$20 -> 7946.9243 | G20: =(0+ABS('Исходные данные'!$B$32)+ABS('Исходные данные'!$B$26)+ABS('Исходные данные'!$B$25)+0)/5 -> 0.252 | H20: =F20*G20 -> 2002.6249 | I20: =H20/'Исходные данные'!$B$4 -> 1925.6009
A21: Σ | B21: =SUM(B6:B20) -> 69191.635 | D21: =SUM(D6:D20) -> 20192.082 | E21: Σ | F21: =SUM(F6:F20) -> 80808.365 | H21: =SUM(H6:H20) -> 33522.017 | I21: =SUM(I6:I20) -> 32232.709
A23: Откосы по контуру площадки: ΣV = (Σh / n)² · Σl · m / 2 (с. 10 методички)
A24: Зона | B24: Σh, м | C24: n | D24: Σl, м | E24: m | F24: V, м³
A25: выемка | B25: =ABS('Исходные данные'!$B$9)+ABS('Исходные данные'!$B$31)+ABS('Исходные данные'!$B$30)+ABS('Исходные данные'!$B$29)+ABS('Исходные данные'!$B$28)+ABS('Исходные данные'!$B$27)+ABS('Исходные данные'!$B$21)+ABS('Исходные данные'!$B$15) -> 3.26 | C25: 8 | D25: ='ЛНР (черн.)'!$G$5+'ЛНР (черн.)'!$G$12+'Исходные данные'!$B$3+'Исходные данные'!$B$3+'Исходные данные'!$B$3+'Исходные данные'!$B$3+'Исходные данные'!$B$3+'Исходные данные'!$B$3+'Исходные данные'!$B$3 -> 837.9386 | E25: 0.25 | F25: =(B25/C25)^2*D25*E25/2 -> 17.393118
A26: насыпь | B26: =ABS('Исходные данные'!$B$10)+ABS('Исходные данные'!$B$11)+ABS('Исходные данные'!$B$12)+ABS('Исходные данные'!$B$13)+ABS('Исходные данные'!$B$14)+ABS('Исходные данные'!$B$20)+ABS('Исходные данные'!$B$26)+ABS('Исходные данные'!$B$32) -> 3.84 | C26: 8 | D26: ='ЛНР (черн.)'!$H$5+'Исходные данные'!$B$3+'Исходные данные'!$B$3+'Исходные данные'!$B$3+'Исходные данные'!$B$3+'Исходные данные'!$B$3+'Исходные данные'!$B$3+'Исходные данные'!$B$3+'ЛНР (черн.)'!$H$12 -> 762.0614 | E26: 0.25 | F26: =(B26/C26)^2*D26*E26/2 -> 21.947368
A28: Итого с откосами (ΣVв.геом, ΣVн.геом в табл. 2)
A29: Площадь ПВ + ПН, м² (проверка) | F29: =B21+F21 -> 150000
A30: Площадь площадки 5 × 3 × a², м² | F30: ='Исходные данные'!$B$6*'Исходные данные'!$B$3^2 -> 150000
A31: ΣVв.геом — выемка: фигуры + откосы, м³ | F31: =D21+F25 -> 20209.475
A32: ΣVн.геом — насыпь: фигуры + откосы, м³ | F32: =H21+F26 -> 33543.964
A33: ΣVн.геом / Kор — грунта в плотном теле на насыпь, м³ | F33: =F32/'Исходные данные'!$B$4 -> 32253.812

Sheet Котлован (черн.)
A1: Котлован по черновику: контуры, размеры, объём (п. 2.2.2 методички)
A2: Задание 4, вариант 2 — только габариты; грунт — супесь. Здание — вариант размещения 8: центр здания в центре квадрата 8.
A4: Параметр | B4: Обозн. | C4: Значение | D4: Ед. | E4: Формула / источник
A5: Исходные данные — Задание 4, вариант 2
A6: Глубина котлована по заданию (от планировочной отметки) | B6: Нк | C6: 2.4 | D6: м
A7: Высота фундаментной плиты | B7: Нф.п | C7: 0.4 | D7: м
A8: Толщина бетонной подготовки | B8: hб.п | C8: 0.15 | D8: м
A9: Толщина подсыпки (щебень) | B9: hподс | C9: 0.1 | D9: м
A10: Толщина растительного слоя | B10: hр.сл | C10: 0.2 | D10: м | E10: методичка, с. 11: 200 мм
A11: Толщина стены подвала (по оси) | B11: Bп | C11: 0.4 | D11: м | E11: схема размещения фундамента
A12: Вылет плиты за наружную грань стены | C12: 0.5 | D12: м | E12: схема: 500
A13: Выход бетонной подготовки за плиту | C13: 0.2 | D13: м | E13: схема: 200; методичка — не менее 0,2
A14: От края подготовки до низа откоса | C14: 0.5 | D14: м | E14: схема: 500
A15: Длина здания по осям | C15: 60 | D15: м
A16: Ширина здания по осям | C16: 30 | D16: м
A17: Вырез (правый нижний угол): длина | C17: 42 | D17: м
A18: Вырез: ширина | C18: 12 | D18: м
A19: Левый нижний угол квадрата 8: x | C19: 200 | D19: м
A20: Левый нижний угол квадрата 8: y | C20: 100 | D20: м
A21: Левая ось здания (центр в центре квадрата 8) | B21: X0 | C21: =$C$19+'Исходные данные'!$B$3/2-$C$15/2 -> 220 | D21: м
A22: Нижняя ось здания | B22: Y0 | C22: =$C$20+'Исходные данные'!$B$3/2-$C$16/2 -> 135 | D22: м
A23: Привязки от осей здания
A24: Ось → наружная грань стены | C24: =$C$11/2 -> 0.2 | D24: м
A25: Ось → край фундаментной плиты | B25: A | C25: =$C$24+$C$12 -> 0.7 | D25: м
A26: Ось → край бетонной подготовки | C26: =$C$25+$C$13 -> 0.9 | D26: м
A27: Ось → низ откоса (подошва котлована) | C27: =$C$26+$C$14 -> 1.4 | D27: м
A28: Рабочая зона от плиты до откоса | B28: C | C28: =$C$27-$C$25 -> 0.7 | D28: м | E28: не менее 0,6 м
A29: Радиус поворотной платформы крана | B29: r | C29: 2.5 | D29: м | E29: лекция
A30: Со стороны съезда: от плиты до низа откоса | B30: c | C30: =1+2*$C$29+1 -> 7 | D30: м | E30: лекция: c = 1 + 2r + 1 - место для крана на дне
A31: Ось → низ откоса со стороны съезда (правая) | C31: =$C$25+$C$30 -> 7.7 | D31: м
A32: Положение котлована относительно ЛНР
A33: Крутизна откоса при Нк (предварительно) | B33: m0 | C33: =IF($C$6<=1.5,0.25,IF($C$6<=3,0.67,0.85)) -> 0.67 | E33: прил. 3, супесь: до 1,5 — 0,25; до 3 — 0,67; до 5 — 0,85
A34: Ось → бровка (предварительно) | C34: =$C$27+$C$6*$C$33 -> 3.008 | D34: м
A35: Ось → бровка со стороны съезда (предварительно) | C35: =$C$31+$C$6*$C$33 -> 9.308 | D35: м
A36: Среднее рабочих отметок по углам котлована | B36: hср.углов | C36: =AVERAGE(H75:H80) -> 0.15056332 | D36: м | E36: таблица углов ниже; «+» — насыпь
A37: Котлован в зоне | C37: =IF($C$36>0,"насыпи","выемки") -> насыпи | E37: ЛНР пересекает котлован — по среднему
A38: Рабочая отметка в центре котлована (центр квадрата 8) | B38: hр | C38: =('Исходные данные'!$B$17+'Исходные данные'!$B$18+'Исходные данные'!$B$23+'Исходные данные'!$B$24)/4 -> 0.165 | D38: м | E38: билинейно; в центре квадрата = среднее h9, h10, h15, h16
A39: Фактическая глубина котлована | B39: hк | C39: =IF($C$37="насыпи",$C$6-$C$10-$C$38,$C$6-$C$10) -> 2.035 | D39: м | E39: hк = Нк − hр.сл − hр (с. 11; hр — только в насыпи)
A40: Откосы и контуры
A41: Коэффициент откоса (супесь) | B41: m | C41: =IF($C$39<=1.5,0.25,IF($C$39<=3,0.67,0.85)) -> 0.67 | E41: прил. 3
...

Sheet Табл. 2 баланс (черн.)
A1: Сводная ведомость объёмов разрабатываемого грунта (табл. 2)
A2: По черновику — до корректировки средней отметки планировки
A4: № | B4: Вид работы | C4: Выемка Vв, м³ | D4: Насыпь Vн, м³ | E4: Vн / Kор, м³
A5: 1 | B5: В призмах (планировка с откосами) | C5: ='Табл. 1 объёмы (черн.)'!$F$31 -> 20209.475 | D5: ='Табл. 1 объёмы (черн.)'!$F$32 -> 33543.964 | E5: =D5/'Исходные данные'!$B$4 -> 32253.812
A6: 2 | B6: В котловане (Vк; засыпка грунтом площадки ΣVн котл = 0 — супесь не песок, пазухи и съезд — привозной песок) | C6: ='Котлован (черн.)'!$C$60 -> 3851.619 | D6: 0 | E6: =D6/'Исходные данные'!$B$4 -> 0
B7: Суммарные объёмы | C7: =SUM(C5:C6) -> 24061.094 | D7: =SUM(D5:D6) -> 33543.964 | E7: =SUM(E5:E6) -> 32253.812
B8: Баланс Vв − Vн/Kор («−» — грунта не хватает) | C8: =C7-E7 -> -8192.7178
A10: Расхождение, % (методичка - не более 5 %, лекция 23.10 - до 10 %) | D10: =ABS(C8)/MAX(C7,E7) -> 0.25400774
A11: Вывод | D11: =IF(D10<=0.05,"баланс соблюдён",IF(C8<0,"не хватает грунта — нужен перерасчёт Нср (Δh)","излишек грунта — нужен перерасчёт Нср (Δh)")) -> не хватает грунта — нужен перерасчёт Нср (Δh)
A12: Площадь строительной площадки F = 300 × 500, м² | D12: ='Исходные данные'!$B$6*'Исходные данные'!$B$3^2 -> 150000
A13: Поправка Δh = (Vв − Vн/Kор) · Kор / F, м (лекция 23.10; «−» — понижение) | D13: =C8*'Исходные данные'!$B$4/D12 -> -0.056802844
A14: Δh, принятое (до 0,0001 м) | D14: =ROUND(D13,4) -> -0.0568

Sheet Отметки (оконч.)
A1: Окончательные рабочие отметки: h' = h + Δh (п. 2.2.3 методички)
A3: Поправка Δh, м | B3: ='Табл. 2 баланс (черн.)'!$D$14 -> -0.0568
A8: № вершины | B8: h, м | C8: Δh, м | D8: h' = h + Δh, м | F8: Схема сетки (вид в плане)
A9: h1 | B9: ='Исходные данные'!$B$9 -> -0.25 | C9: =$B$3 -> -0.0568 | D9: =B9+C9 -> -0.3068 | F9: h1 | G9: h2 | H9: h3 | I9: h4 | J9: h5 | K9: h6
A10: h2 | B10: ='Исходные данные'!$B$10 -> 0.15 | C10: =$B$3 -> -0.0568 | D10: =B10+C10 -> 0.0932 | F10: =D9 -> -0.3068 | G10: =D10 -> 0.0932 | H10: =D11 -> 0.2832 | I10: =D12 -> 0.4132 | J10: =D13 -> 0.6032 | K10: =D14 -> 0.7932
A11: h3 | B11: ='Исходные данные'!$B$11 -> 0.34 | C11: =$B$3 -> -0.0568 | D11: =B11+C11 -> 0.2832 | F11: h7 | G11: h8 | H11: h9 | I11: h10 | J11: h11 | K11: h12
A12: h4 | B12: ='Исходные данные'!$B$12 -> 0.47 | C12: =$B$3 -> -0.0568 | D12: =B12+C12 -> 0.4132 | F12: =D15 -> -0.5468 | G12: =D16 -> -0.3668 | H12: =D17 -> 0.2232 | I12: =D18 -> 0.4632 | J12: =D19 -> 0.7832 | K12: =D20 -> 0.4132
A13: h5 | B13: ='Исходные данные'!$B$13 -> 0.66 | C13: =$B$3 -> -0.0568 | D13: =B13+C13 -> 0.6032 | F13: h13 | G13: h14 | H13: h15 | I13: h16 | J13: h17 | K13: h18
A14: h6 | B14: ='Исходные данные'!$B$14 -> 0.85 | C14: =$B$3 -> -0.0568 | D14: =B14+C14 -> 0.7932 | F14: =D21 -> -0.2968 | G14: =D22 -> -0.4868 | H14: =D23 -> -0.3368 | I14: =D24 -> 0.0832 | J14: =D25 -> 0.3032 | K14: =D26 -> 0.7032
A15: h7 | B15: ='Исходные данные'!$B$15 -> -0.49 | C15: =$B$3 -> -0.0568 | D15: =B15+C15 -> -0.5468 | F15: h19 | G15: h20 | H15: h21 | I15: h22 | J15: h23 | K15: h24
A16: h8 | B16: ='Исходные данные'!$B$16 -> -0.31 | C16: =$B$3 -> -0.0568 | D16: =B16+C16 -> -0.3668 | F16: =D27 -> -0.4568 | G16: =D28 -> -0.7068 | H16: =D29 -> -0.5768 | I16: =D30 -> -0.3368 | J16: =D31 -> -0.4868 | K16: =D32 -> 0.0832
A17: h9 | B17: ='Исходные данные'!$B$17 -> 0.28 | C17: =$B$3 -> -0.0568 | D17: =B17+C17 -> 0.2232
A18: h10 | B18: ='Исходные данные'!$B$18 -> 0.52 | C18: =$B$3 -> -0.0568 | D18: =B18+C18 -> 0.4632
A19: h11 | B19: ='Исходные данные'!$B$19 -> 0.84 | C19: =$B$3 -> -0.0568 | D19: =B19+C19 -> 0.7832
A20: h12 | B20: ='Исходные данные'!$B$20 -> 0.47 | C20: =$B$3 -> -0.0568 | D20: =B20+C20 -> 0.4132
A21: h13 | B21: ='Исходные данные'!$B$21 -> -0.24 | C21: =$B$3 -> -0.0568 | D21: =B21+C21 -> -0.2968
A22: h14 | B22: ='Исходные данные'!$B$22 -> -0.43 | C22: =$B$3 -> -0.0568 | D22: =B22+C22 -> -0.4868
A23: h15 | B23: ='Исходные данные'!$B$23 -> -0.28 | C23: =$B$3 -> -0.0568 | D23: =B23+C23 -> -0.3368
A24: h16 | B24: ='Исходные данные'!$B$24 -> 0.14 | C24: =$B$3 -> -0.0568 | D24: =B24+C24 -> 0.0832
A25: h17 | B25: ='Исходные данные'!$B$25 -> 0.36 | C25: =$B$3 -> -0.0568 | D25: =B25+C25 -> 0.3032
A26: h18 | B26: ='Исходные данные'!$B$26 -> 0.76 | C26: =$B$3 -> -0.0568 | D26: =B26+C26 -> 0.7032
A27: h19 | B27: ='Исходные данные'!$B$27 -> -0.4 | C27: =$B$3 -> -0.0568 | D27: =B27+C27 -> -0.4568
A28: h20 | B28: ='Исходные данные'!$B$28 -> -0.65 | C28: =$B$3 -> -0.0568 | D28: =B28+C28 -> -0.7068
A29: h21 | B29: ='Исходные данные'!$B$29 -> -0.52 | C29: =$B$3 -> -0.0568 | D29: =B29+C29 -> -0.5768
A30: h22 | B30: ='Исходные данные'!$B$30 -> -0.28 | C30: =$B$3 -> -0.0568 | D30: =B30+C30 -> -0.3368
A31: h23 | B31: ='Исходные данные'!$B$31 -> -0.43 | C31: =$B$3 -> -0.0568 | D31: =B31+C31 -> -0.4868
A32: h24 | B32: ='Исходные данные'!$B$32 -> 0.14 | C32: =$B$3 -> -0.0568 | D32: =B32+C32 -> 0.0832

Sheet ЛНР (оконч.)
A1: Точки нулевых работ по окончательным отметкам
A2: x1 = a·|h1| / (|h1| + |h2|) — расстояние от вершины 1 до точки нуля; x2 = a − x1
A4: № т.0 | B4: Сторона | C4: Вершина 1 | D4: h1, м | E4: Вершина 2 | F4: h2, м | G4: x1 (от верш. 1), м | H4: x2 (от верш. 2), м
A5: 1 | B5: горизонтальная | C5: h1 | D5: ='Отметки (оконч.)'!$D$9 -> -0.3068 | E5: h2 | F5: ='Отметки (оконч.)'!$D$10 -> 0.0932 | G5: ='Исходные данные'!$B$3*ABS(D5)/(ABS(D5)+ABS(F5)) -> 76.7 | H5: ='Исходные данные'!$B$3-G5 -> 23.3
A6: 2 | B6: вертикальная | C6: h2 | D6: ='Отметки (оконч.)'!$D$10 -> 0.0932 | E6: h8 | F6: ='Отметки (оконч.)'!$D$16 -> -0.3668 | G6: ='Исходные данные'!$B$3*ABS(D6)/(ABS(D6)+ABS(F6)) -> 20.26087 | H6: ='Исходные данные'!$B$3-G6 -> 79.73913
A7: 3 | B7: горизонтальная | C7: h8 | D7: ='Отметки (оконч.)'!$D$16 -> -0.3668 | E7: h9 | F7: ='Отметки (оконч.)'!$D$17 -> 0.2232 | G7: ='Исходные данные'!$B$3*ABS(D7)/(ABS(D7)+ABS(F7)) -> 62.169492 | H7: ='Исходные данные'!$B$3-G7 -> 37.830508
A8: 4 | B8: вертикальная | C8: h9 | D8: ='Отметки (оконч.)'!$D$17 -> 0.2232 | E8: h15 | F8: ='Отметки (оконч.)'!$D$23 -> -0.3368 | G8: ='Исходные данные'!$B$3*ABS(D8)/(ABS(D8)+ABS(F8)) -> 39.857143 | H8: ='Исходные данные'!$B$3-G8 -> 60.142857
A9: 5 | B9: горизонтальная | C9: h15 | D9: ='Отметки (оконч.)'!$D$23 -> -0.3368 | E9: h16 | F9: ='Отметки (оконч.)'!$D$24 -> 0.0832 | G9: ='Исходные данные'!$B$3*ABS(D9)/(ABS(D9)+ABS(F9)) -> 80.190476 | H9: ='Исходные данные'!$B$3-G9 -> 19.809524
A10: 6 | B10: вертикальная | C10: h16 | D10: ='Отметки (оконч.)'!$D$24 -> 0.0832 | E10: h22 | F10: ='Отметки (оконч.)'!$D$30 -> -0.3368 | G10: ='Исходные данные'!$B$3*ABS(D10)/(ABS(D10)+ABS(F10)) -> 19.809524 | H10: ='Исходные данные'!$B$3-G10 -> 80.190476
A11: 7 | B11: вертикальная | C11: h17 | D11: ='Отметки (оконч.)'!$D$25 -> 0.3032 | E11: h23 | F11: ='Отметки (оконч.)'!$D$31 -> -0.4868 | G11: ='Исходные данные'!$B$3*ABS(D11)/(ABS(D11)+ABS(F11)) -> 38.379747 | H11: ='Исходные данные'!$B$3-G11 -> 61.620253
A12: 8 | B12: горизонтальная | C12: h23 | D12: ='Отметки (оконч.)'!$D$31 -> -0.4868 | E12: h24 | F12: ='Отметки (оконч.)'!$D$32 -> 0.0832 | G12: ='Исходные данные'!$B$3*ABS(D12)/(ABS(D12)+ABS(F12)) -> 85.403509 | H12: ='Исходные данные'!$B$3-G12 -> 14.596491

Sheet Табл. 1 объёмы (оконч.)
A1: Объёмы планировочных работ по окончательным отметкам
A2: Vi = Fi · hср,i; hср,i = (|h1| + |h2| + … + |hn|) / n, в точках нуля h = 0
A4: Планировочная выемка (ПВ) | E4: Планировочная насыпь (ПН)
A5: № фигуры | B5: Fi, м² | C5: hср, м | D5: Vi, м³ | E5: № фигуры | F5: Fi, м² | G5: hср, м | H5: Vi, м³ | I5: Vгр = Vi / Kор, м³
A6: 1 | B6: ='Исходные данные'!$B$3^2-$F$6 -> 9763.9609 | C6: =(0+ABS('Отметки (оконч.)'!$D$9)+ABS('Отметки (оконч.)'!$D$15)+ABS('Отметки (оконч.)'!$D$16)+0)/5 -> 0.24408 | D6: =B6*C6 -> 2383.1876 | E6: 1' | F6: ='ЛНР (оконч.)'!$G$6*'ЛНР (оконч.)'!$H$5/2 -> 236.03913 | G6: =(0+ABS('Отметки (оконч.)'!$D$10)+0)/3 -> 0.031066667 | H6: =F6*G6 -> 7.332949 | I6: =H6/'Исходные данные'!$B$4 -> 7.0509125
A7: 2 | B7: ='ЛНР (оконч.)'!$H$6*'ЛНР (оконч.)'!$G$7/2 -> 2478.6706 | C7: =(0+ABS('Отметки (оконч.)'!$D$16)+0)/3 -> 0.12226667 | D7: =B7*C7 -> 303.05879 | E7: 2' | F7: ='Исходные данные'!$B$3^2-$B$7 -> 7521.3294 | G7: =(0+ABS('Отметки (оконч.)'!$D$17)+ABS('Отметки (оконч.)'!$D$11)+ABS('Отметки (оконч.)'!$D$10)+0)/5 -> 0.11992 | H7: =F7*G7 -> 901.95782 | I7: =H7/'Исходные данные'!$B$4 -> 867.26714
A8: — | B8: — | C8: — | D8: — | E8: 3 | F8: ='Исходные данные'!$B$3^2 -> 10000 | G8: =(ABS('Отметки (оконч.)'!$D$17)+ABS('Отметки (оконч.)'!$D$18)+ABS('Отметки (оконч.)'!$D$12)+ABS('Отметки (оконч.)'!$D$11))/4 -> 0.3457 | H8: =F8*G8 -> 3457 | I8: =H8/'Исходные данные'!$B$4 -> 3324.0385
A9: — | B9: — | C9: — | D9: — | E9: 4 | F9: ='Исходные данные'!$B$3^2 -> 10000 | G9: =(ABS('Отметки (оконч.)'!$D$18)+ABS('Отметки (оконч.)'!$D$19)+ABS('Отметки (оконч.)'!$D$13)+ABS('Отметки (оконч.)'!$D$12))/4 -> 0.5657 | H9: =F9*G9 -> 5657 | I9: =H9/'Исходные данные'!$B$4 -> 5439.4231
A10: — | B10: — | C10: — | D10: — | E10: 5 | F10: ='Исходные данные'!$B$3^2 -> 10000 | G10: =(ABS('Отметки (оконч.)'!$D$19)+ABS('Отметки (оконч.)'!$D$20)+ABS('Отметки (оконч.)'!$D$14)+ABS('Отметки (оконч.)'!$D$13))/4 -> 0.6482 | H10: =F10*G10 -> 6482 | I10: =H10/'Исходные данные'!$B$4 -> 6232.6923
A11: 6 | B11: ='Исходные данные'!$B$3^2 -> 10000 | C11: =(ABS('Отметки (оконч.)'!$D$21)+ABS('Отметки (оконч.)'!$D$22)+ABS('Отметки (оконч.)'!$D$16)+ABS('Отметки (оконч.)'!$D$15))/4 -> 0.4243 | D11: =B11*C11 -> 4243 | E11: — | F11: — | G11: — | H11: — | I11: —
A12: 7 | B12: ='Исходные данные'!$B$3^2-$F$12 -> 9246.092 | C12: =(0+ABS('Отметки (оконч.)'!$D$16)+ABS('Отметки (оконч.)'!$D$22)+ABS('Отметки (оконч.)'!$D$23)+0)/5 -> 0.23808 | D12: =B12*C12 -> 2201.3096 | E12: 7' | F12: ='ЛНР (оконч.)'!$G$8*'ЛНР (оконч.)'!$H$7/2 -> 753.90799 | G12: =(0+ABS('Отметки (оконч.)'!$D$17)+0)/3 -> 0.0744 | H12: =F12*G12 -> 56.090754 | I12: =H12/'Исходные данные'!$B$4 -> 53.933418
A13: 8 | B13: ='ЛНР (оконч.)'!$H$8*'ЛНР (оконч.)'!$G$9/2 -> 2411.4422 | C13: =(0+ABS('Отметки (оконч.)'!$D$23)+0)/3 -> 0.11226667 | D13: =B13*C13 -> 270.72458 | E13: 8' | F13: ='Исходные данные'!$B$3^2-$B$13 -> 7588.5578 | G13: =(0+ABS('Отметки (оконч.)'!$D$24)+ABS('Отметки (оконч.)'!$D$18)+ABS('Отметки (оконч.)'!$D$17)+0)/5 -> 0.15392 | H13: =F13*G13 -> 1168.0308 | I13: =H13/'Исходные данные'!$B$4 -> 1123.1066
A14: — | B14: — | C14: — | D14: — | E14: 9 | F14: ='Исходные данные'!$B$3^2 -> 10000 | G14: =(ABS('Отметки (оконч.)'!$D$24)+ABS('Отметки (оконч.)'!$D$25)+ABS('Отметки (оконч.)'!$D$19)+ABS('Отметки (оконч.)'!$D$18))/4 -> 0.4082 | H14: =F14*G14 -> 4082 | I14: =H14/'Исходные данные'!$B$4 -> 3925
A15: — | B15: — | C15: — | D15: — | E15: 10 | F15: ='Исходные данные'!$B$3^2 -> 10000 | G15: =(ABS('Отметки (оконч.)'!$D$25)+ABS('Отметки (оконч.)'!$D$26)+ABS('Отметки (оконч.)'!$D$20)+ABS('Отметки (оконч.)'!$D$19))/4 -> 0.5507 | H15: =F15*G15 -> 5507 | I15: =H15/'Исходные данные'!$B$4 -> 5295.1923
A16: 11 | B16: ='Исходные данные'!$B$3^2 -> 10000 | C16: =(ABS('Отметки (оконч.)'!$D$27)+ABS('Отметки (оконч.)'!$D$28)+ABS('Отметки (оконч.)'!$D$22)+ABS('Отметки (оконч.)'!$D$21))/4 -> 0.4868 | D16: =B16*C16 -> 4868 | E16: — | F16: — | G16: — | H16: — | I16: —
A17: 12 | B17: ='Исходные данные'!$B$3^2 -> 10000 | C17: =(ABS('Отметки (оконч.)'!$D$28)+ABS('Отметки (оконч.)'!$D$29)+ABS('Отметки (оконч.)'!$D$23)+ABS('Отметки (оконч.)'!$D$22))/4 -> 0.5268 | D17: =B17*C17 -> 5268 | E17: — | F17: — | G17: — | H17: — | I17: —
A18: 13 | B18: ='Исходные данные'!$B$3^2-$F$18 -> 9803.7914 | C18: =(0+ABS('Отметки (оконч.)'!$D$23)+ABS('Отметки (оконч.)'!$D$29)+ABS('Отметки (оконч.)'!$D$30)+0)/5 -> 0.25008 | D18: =B18*C18 -> 2451.7321 | E18: 13' | F18: ='ЛНР (оконч.)'!$G$10*'ЛНР (оконч.)'!$H$9/2 -> 196.20862 | G18: =(0+ABS('Отметки (оконч.)'!$D$24)+0)/3 -> 0.027733333 | H18: =F18*G18 -> 5.441519 | I18: =H18/'Исходные данные'!$B$4 -> 5.2322298
A19: 14 | B19: =('ЛНР (оконч.)'!$H$10+'ЛНР (оконч.)'!$H$11)/2*'Исходные данные'!$B$3 -> 7090.5365 | C19: =(0+ABS('Отметки (оконч.)'!$D$30)+ABS('Отметки (оконч.)'!$D$31)+0)/4 -> 0.2059 | D19: =B19*C19 -> 1459.9415 | E19: 14' | F19: =('ЛНР (оконч.)'!$G$11+'ЛНР (оконч.)'!$G$10)/2*'Исходные данные'!$B$3 -> 2909.4635 | G19: =(0+ABS('Отметки (оконч.)'!$D$25)+ABS('Отметки (оконч.)'!$D$24)+0)/4 -> 0.0966 | H19: =F19*G19 -> 281.05418 | I19: =H19/'Исходные данные'!$B$4 -> 270.2444
A20: 15 | B20: ='ЛНР (оконч.)'!$H$11*'ЛНР (оконч.)'!$G$12/2 -> 2631.2929 | C20: =(0+ABS('Отметки (оконч.)'!$D$31)+0)/3 -> 0.16226667 | D20: =B20*C20 -> 426.97113 | E20: 15' | F20: ='Исходные данные'!$B$3^2-$B$20 -> 7368.7071 | G20: =(0+ABS('Отметки (оконч.)'!$D$32)+ABS('Отметки (оконч.)'!$D$26)+ABS('Отметки (оконч.)'!$D$25)+0)/5 -> 0.21792 | H20: =F20*G20 -> 1605.7886 | I20: =H20/'Исходные данные'!$B$4 -> 1544.0275
A21: Σ | B21: =SUM(B6:B20) -> 73425.786 | D21: =SUM(D6:D20) -> 23875.925 | E21: Σ | F21: =SUM(F6:F20) -> 76574.214 | H21: =SUM(H6:H20) -> 29210.697 | I21: =SUM(I6:I20) -> 28087.208
A23: Откосы по контуру площадки: ΣV = (Σh / n)² · Σl · m / 2 (с. 10 методички)
A24: Зона | B24: Σh, м | C24: n | D24: Σl, м | E24: m | F24: V, м³
A25: выемка | B25: =ABS('Отметки (оконч.)'!$D$9)+ABS('Отметки (оконч.)'!$D$31)+ABS('Отметки (оконч.)'!$D$30)+ABS('Отметки (оконч.)'!$D$29)+ABS('Отметки (оконч.)'!$D$28)+ABS('Отметки (оконч.)'!$D$27)+ABS('Отметки (оконч.)'!$D$21)+ABS('Отметки (оконч.)'!$D$15) -> 3.7144 | C25: 8 | D25: ='ЛНР (оконч.)'!$G$5+'ЛНР (оконч.)'!$G$12+'Исходные данные'!$B$3+'Исходные данные'!$B$3+'Исходные данные'!$B$3+'Исходные данные'!$B$3+'Исходные данные'!$B$3+'Исходные данные'!$B$3+'Исходные данные'!$B$3 -> 862.10351 | E25: 0.25 | F25: =(B25/C25)^2*D25*E25/2 -> 23.230941
A26: насыпь | B26: =ABS('Отметки (оконч.)'!$D$10)+ABS('Отметки (оконч.)'!$D$11)+ABS('Отметки (оконч.)'!$D$12)+ABS('Отметки (оконч.)'!$D$13)+ABS('Отметки (оконч.)'!$D$14)+ABS('Отметки (оконч.)'!$D$20)+ABS('Отметки (оконч.)'!$D$26)+ABS('Отметки (оконч.)'!$D$32) -> 3.3856 | C26: 8 | D26: ='ЛНР (оконч.)'!$H$5+'Исходные данные'!$B$3+'Исходные данные'!$B$3+'Исходные данные'!$B$3+'Исходные данные'!$B$3+'Исходные данные'!$B$3+'Исходные данные'!$B$3+'Исходные данные'!$B$3+'ЛНР (оконч.)'!$H$12 -> 737.89649 | E26: 0.25 | F26: =(B26/C26)^2*D26*E26/2 -> 16.519495
A28: Итого с откосами (ΣVв.геом, ΣVн.геом в табл. 2)
A29: Площадь ПВ + ПН, м² (проверка) | F29: =B21+F21 -> 150000
A30: Площадь площадки 5 × 3 × a², м² | F30: ='Исходные данные'!$B$6*'Исходные данные'!$B$3^2 -> 150000
A31: ΣVв.геом — выемка: фигуры + откосы, м³ | F31: =D21+F25 -> 23899.156
A32: ΣVн.геом — насыпь: фигуры + откосы, м³ | F32: =H21+F26 -> 29227.216
A33: ΣVн.геом / Kор — грунта в плотном теле на насыпь, м³ | F33: =F32/'Исходные данные'!$B$4 -> 28103.092

Sheet Котлован (оконч.)
A1: Котлован по окончательным отметкам (котлован в насыпи — пересчёт)
A2: Задание 4, вариант 2 — только габариты; грунт — супесь. Здание — вариант размещения 8: центр здания в центре квадрата 8.
A4: Параметр | B4: Обозн. | C4: Значение | D4: Ед. | E4: Формула / источник
A5: Исходные данные — Задание 4, вариант 2
A6: Глубина котлована по заданию (от планировочной отметки) | B6: Нк | C6: 2.4 | D6: м
A7: Высота фундаментной плиты | B7: Нф.п | C7: 0.4 | D7: м
A8: Толщина бетонной подготовки | B8: hб.п | C8: 0.15 | D8: м
A9: Толщина подсыпки (щебень) | B9: hподс | C9: 0.1 | D9: м
A10: Толщина растительного слоя | B10: hр.сл | C10: 0.2 | D10: м | E10: методичка, с. 11: 200 мм
A11: Толщина стены подвала (по оси) | B11: Bп | C11: 0.4 | D11: м | E11: схема размещения фундамента
A12: Вылет плиты за наружную грань стены | C12: 0.5 | D12: м | E12: схема: 500
A13: Выход бетонной подготовки за плиту | C13: 0.2 | D13: м | E13: схема: 200; методичка — не менее 0,2
A14: От края подготовки до низа откоса | C14: 0.5 | D14: м | E14: схема: 500
A15: Длина здания по осям | C15: 60 | D15: м
A16: Ширина здания по осям | C16: 30 | D16: м
A17: Вырез (правый нижний угол): длина | C17: 42 | D17: м
A18: Вырез: ширина | C18: 12 | D18: м
A19: Левый нижний угол квадрата 8: x | C19: 200 | D19: м
A20: Левый нижний угол квадрата 8: y | C20: 100 | D20: м
A21: Левая ось здания (центр в центре квадрата 8) | B21: X0 | C21: =$C$19+'Исходные данные'!$B$3/2-$C$15/2 -> 220 | D21: м
A22: Нижняя ось здания | B22: Y0 | C22: =$C$20+'Исходные данные'!$B$3/2-$C$16/2 -> 135 | D22: м
A23: Привязки от осей здания
A24: Ось → наружная грань стены | C24: =$C$11/2 -> 0.2 | D24: м
A25: Ось → край фундаментной плиты | B25: A | C25: =$C$24+$C$12 -> 0.7 | D25: м
A26: Ось → край бетонной подготовки | C26: =$C$25+$C$13 -> 0.9 | D26: м
A27: Ось → низ откоса (подошва котлована) | C27: =$C$26+$C$14 -> 1.4 | D27: м
A28: Рабочая зона от плиты до откоса | B28: C | C28: =$C$27-$C$25 -> 0.7 | D28: м | E28: не менее 0,6 м
A29: Радиус поворотной платформы крана | B29: r | C29: 2.5 | D29: м | E29: лекция
A30: Со стороны съезда: от плиты до низа откоса | B30: c | C30: =1+2*$C$29+1 -> 7 | D30: м | E30: лекция: c = 1 + 2r + 1 - место для крана на дне
A31: Ось → низ откоса со стороны съезда (правая) | C31: =$C$25+$C$30 -> 7.7 | D31: м
A32: Положение котлована относительно ЛНР
A33: Крутизна откоса при Нк (предварительно) | B33: m0 | C33: =IF($C$6<=1.5,0.25,IF($C$6<=3,0.67,0.85)) -> 0.67 | E33: прил. 3, супесь: до 1,5 — 0,25; до 3 — 0,67; до 5 — 0,85
A34: Ось → бровка (предварительно) | C34: =$C$27+$C$6*$C$33 -> 3.008 | D34: м
A35: Ось → бровка со стороны съезда (предварительно) | C35: =$C$31+$C$6*$C$33 -> 9.308 | D35: м
A36: Среднее рабочих отметок по углам котлована | B36: hср.углов | C36: =AVERAGE(H75:H80) -> 0.093763323 | D36: м | E36: таблица углов ниже; «+» — насыпь
A37: Котлован в зоне | C37: =IF($C$36>0,"насыпи","выемки") -> насыпи | E37: ЛНР пересекает котлован — по среднему
A38: Рабочая отметка в центре котлована (центр квадрата 8) | B38: hр | C38: =('Отметки (оконч.)'!$D$17+'Отметки (оконч.)'!$D$18+'Отметки (оконч.)'!$D$23+'Отметки (оконч.)'!$D$24)/4 -> 0.1082 | D38: м | E38: билинейно; в центре квадрата = среднее h9, h10, h15, h16
A39: Фактическая глубина котлована | B39: hк | C39: =IF($C$37="насыпи",$C$6-$C$10-$C$38,$C$6-$C$10) -> 2.0918 | D39: м | E39: hк = Нк − hр.сл − hр (с. 11; hр — только в насыпи)
A40: Откосы и контуры
A41: Коэффициент откоса (супесь) | B41: m | C41: =IF($C$39<=1.5,0.25,IF($C$39<=3,0.67,0.85)) -> 0.67 | E41: прил. 3
...

Sheet Табл. 2 баланс (оконч.)
A1: Сводная ведомость объёмов разрабатываемого грунта (табл. 2)
A2: По окончательным отметкам — после поправки Δh
A4: № | B4: Вид работы | C4: Выемка Vв, м³ | D4: Насыпь Vн, м³ | E4: Vн / Kор, м³
A5: 1 | B5: В призмах (планировка с откосами) | C5: ='Табл. 1 объёмы (оконч.)'!$F$31 -> 23899.156 | D5: ='Табл. 1 объёмы (оконч.)'!$F$32 -> 29227.216 | E5: =D5/'Исходные данные'!$B$4 -> 28103.092
A6: 2 | B6: В котловане (Vк; засыпка грунтом площадки ΣVн котл = 0 — супесь не песок, пазухи и съезд — привозной песок) | C6: ='Котлован (оконч.)'!$C$60 -> 3971.7375 | D6: 0 | E6: =D6/'Исходные данные'!$B$4 -> 0
B7: Суммарные объёмы | C7: =SUM(C5:C6) -> 27870.894 | D7: =SUM(D5:D6) -> 29227.216 | E7: =SUM(E5:E6) -> 28103.092
B8: Баланс Vв − Vн/Kор («−» — грунта не хватает) | C8: =C7-E7 -> -232.1988
A10: Расхождение, % (методичка - не более 5 %, лекция 23.10 - до 10 %) | D10: =ABS(C8)/MAX(C7,E7) -> 0.0082623931
A11: Вывод | D11: =IF(D10<=0.05,"баланс соблюдён",IF(C8<0,"не хватает грунта — нужен перерасчёт Нср (Δh)","излишек грунта — нужен перерасчёт Нср (Δh)")) -> баланс соблюдён
A12: Площадь строительной площадки F = 300 × 500, м² | D12: ='Исходные данные'!$B$6*'Исходные данные'!$B$3^2 -> 150000
A13: Поправка Δh = (Vв − Vн/Kор) · Kор / F, м (лекция 23.10; «−» — понижение) | D13: =C8*'Исходные данные'!$B$4/D12 -> -0.0016099117
A14: Δh, принятое (до 0,0001 м) | D14: =ROUND(D13,4) -> -0.0016

Sheet Табл. 3 котлован
A1: Баланс земляных работ по котловану (табл. 3; форма - с доски), по окончательным отметкам
A2: Грунт площадки - супесь, не песок: пазухи и съезд засыпаются привозным песком, ΣVн местного грунта = 0 (лекция 23.10), отвала у котлована нет; весь грунт котлована - в транспортные средства: в насыпь планировки, излишек - на вывоз (с. 16).
A4: Выемка | G4: Насыпь
A5: № п/п | B5: Место разработки грунта | C5: Объём разработки грунта, м³ (плотное тело) | D5: Место укладки грунта и его объём, м³ (с kр) | G5: № п/п | H5: Место устройства насыпи | I5: Геометрический объём насыпи, м³ | J5: Потребный объём грунта V / kо.р, м³
A6: 1 | B6: Котлован | C6: ='Котлован (оконч.)'!$C$59 -> 3831.4695 | D6: Отвал (не требуется) | E6: =J8*'Исходные данные'!$B$7 -> 0 | G6: 1 | H6: Пазухи сооружения - песок из карьера | I6: ='Котлован (оконч.)'!$C$69 -> 953.30324 | J6: =I6/'Исходные данные'!$B$4 -> 916.63773
A7: 2 | B7: Съезд | C7: ='Котлован (оконч.)'!$C$70 -> 140.26796 | D7: Транспортные средства | E7: =(C8-J8)*'Исходные данные'!$B$7 -> 4567.4981 | G7: 2 | H7: Съезд - песок из карьера | I7: ='Котлован (оконч.)'!$C$70 -> 140.26796 | J7: =I7/'Исходные данные'!$B$4 -> 134.87304
B8: ΣVв | C8: =C6+C7 -> 3971.7375 | D8: Σ (с kр) | E8: =E6+E7 -> 4567.4981 | H8: ΣVн местного грунта (засыпка - привозной песок) | J8: 0
A10: Объём грунта в отвал: ΣVн · kр, м³ | E10: =E6 -> 0
A11: В транспортные средства: (ΣVв − ΣVн) · kр, м³ | E11: =E7 -> 4567.4981
A12: из них в насыпь планировки (табл. 4), с kр, м³ | E12: =MIN(C8-J8,'Табл. 4 распределение'!B19-SUM('Табл. 4 распределение'!C5:L5))*'Исходные данные'!$B$7 -> 4567.4981
A13: вывоз (лишний грунт), с kр, м³ | E13: =E11-E12 -> 0
A14: Привозится из карьера: песок для засыпки пазух, плотное тело / с kр, м³ | E14: =J6 -> 916.63773 | F14: =E14*'Исходные данные'!$B$7 -> 1054.1334
A15: Привозится из карьера: песок для засыпки съезда, плотное тело / с kр, м³ | E15: =J7 -> 134.87304 | F15: =E15*'Исходные данные'!$B$7 -> 155.10399
A16: Привозится из карьера: щебень для подсыпки Vподс / kо.р, м³ | E16: ='Котлован (оконч.)'!$C$61/'Исходные данные'!$B$4 -> 162.2 | F16: =E16*'Исходные данные'!$B$7 -> 186.53
A17: Проверка: отвал + транспорт − ΣVв · kр (должно быть 0) | E17: =E6+E7-C8*'Исходные данные'!$B$7 -> 0

Sheet Табл. 4 распределение
A1: Баланс распределения земляных масс (табл. 4 методички): из выемок и котлована в насыпь, м³
A2: Минимум моментов V·l (l - между центрами тяжести фигур): сначала выемки (ЗТМ), затем котлован (самосвалы); остаток - недостача, подвоз из карьера. Выемка - плотное тело, насыпь - Vн / kо.р.
A4: Выемка | B4: № | C4: 1 | D4: 2 | E4: 6 | F4: 7 | G4: 8 | H4: 11 | I4: 12 | J4: 13 | K4: 14 | L4: 15 | M4: Котлован | N4: Недостача
B5: Объём | C5: 2383.1876 | D5: 303.05879 | E5: 4243 | F5: 2201.3096 | G5: 270.72458 | H5: 4868 | I5: 5268 | J5: 2451.7321 | K5: 1459.9415 | L5: 426.97113 | M5: 3971.7375 | N5: 239.54561
A6: Насыпь № | B6: Объём | O6: Проверка: Σ по строке − объём
A7: 1' | B7: 7.0509125 | C7: 7.0509125 | O7: =SUM(C7:N7)-B7 -> 0
A8: 2' | B8: 867.26714 | C8: 867.26714 | O8: =SUM(C8:N8)-B8 -> 0
A9: 3 | B9: 3324.0385 | C9: 1508.8695 | D9: 303.05879 | E9: 1512.1101 | O9: =SUM(C9:N9)-B9 -> 0
A10: 4 | B10: 5439.4231 | E10: 2676.9564 | F10: 2201.3096 | H10: 561.15706 | O10: =SUM(C10:N10)-B10 -> 0
A11: 5 | B11: 6232.6923 | H11: 2021.4092 | M11: 3971.7375 | N11: 239.54561 | O11: =SUM(C11:N11)-B11 -> 0
A12: 7' | B12: 53.933418 | E12: 53.933418 | O12: =SUM(C12:N12)-B12 -> 0
A13: 8' | B13: 1123.1066 | H13: 1123.1066 | O13: =SUM(C13:N13)-B13 -> 0
A14: 9 | B14: 3925 | G14: 270.72458 | H14: 1162.3272 | I14: 2491.9483 | O14: =SUM(C14:N14)-B14 -> 0
A15: 10 | B15: 5295.1923 | I15: 2770.8195 | J15: 2181.4877 | K15: 342.88504 | O15: =SUM(C15:N15)-B15 -> 0
A16: 13' | B16: 5.2322298 | I16: 5.2322298 | O16: =SUM(C16:N16)-B16 -> 0
A17: 14' | B17: 270.2444 | J17: 270.2444 | O17: =SUM(C17:N17)-B17 -> 0
A18: 15' | B18: 1544.0275 | K18: 1117.0564 | L18: 426.97113 | O18: =SUM(C18:N18)-B18 -> 0
A19: Σ | B19: =SUM(B7:B18) -> 28087.208 | C19: =SUM(C7:C18) -> 2383.1876 | D19: =SUM(D7:D18) -> 303.05879 | E19: =SUM(E7:E18) -> 4243 | F19: =SUM(F7:F18) -> 2201.3096 | G19: =SUM(G7:G18) -> 270.72458 | H19: =SUM(H7:H18) -> 4868 | I19: =SUM(I7:I18) -> 5268 | ... N19: =SUM(N7:N18) -> 239.54561
A20: Проверка: Σ по столбцу − объём | C20: =C19-C5 -> 0 | D20: =D19-D5 -> 0 | E20: =E19-E5 -> 0 | F20: =F19-F5 -> 0 | G20: =G19-G5 -> 0 | H20: =H19-H5 -> 0 | I20: =I19-I5 -> 0 | J20: =J19-J5 -> 0 | ... N20: =N19-N5 -> 0

Sheet Табл. 5 скрепер
A1: Средняя дальность перемещения грунта скрепером (бульдозером): выемка — насыпь (табл. 5)
B2: Выемка | C2: Выемка | D2: Выемка | E2: Выемка | F2: Выемка | G2: Выемка | H2: Выемка | I2: Выемка | J2: Выемка | K2: Выемка | L2: Насыпь | M2: Насыпь | N2: Насыпь | O2: Насыпь | P2: Насыпь | Q2: Насыпь | R2: Насыпь | S2: Насыпь | T2: Насыпь | U2: Насыпь | V2: Насыпь | W2: Насыпь
A3: № фигур | B3: 1 | C3: 2 | D3: 6 | E3: 7 | F3: 8 | G3: 11 | H3: 12 | I3: 13 | J3: 14 | K3: 15 | L3: 1' | M3: 2' | N3: 3 | O3: 4 | P3: 5 | Q3: 7' | R3: 8' | S3: 9 | T3: 10 | U3: 13' | V3: 14' | W3: 15'
A4: V, м³ | B4: 2383.1876 | C4: 303.05879 | D4: 4243 | E4: 2201.3096 | F4: 270.72458 | G4: 4868 | H4: 5268 | I4: 2451.7321 | J4: 1459.9415 | K4: 426.97113 | L4: 7.0509125 | M4: 867.26714 | N4: 3324.0385 | O4: 5439.4231 | P4: 2021.4092 | Q4: 53.933418 | R4: 1123.1066 | S4: 3925 | T4: 5295.1923 | U4: 5.2322298 | V4: 270.2444 | W4: 1544.0275
A5: x, м | B5: 48.979029 | C5: 120.72316 | D5: 50 | E5: 146.95131 | F5: 226.73016 | G5: 50 | H5: 150 | I5: 249.13148 | J5: 347.81749 | K5: 428.46784 | L5: 92.233333 | M5: 159.64825 | N5: 250 | O5: 350 | P5: 450 | Q5: 187.38983 | R5: 257.39454 | S5: 350 | T5: 450 | U5: 293.39683 | V5: 355.31891 | W5: 457.68892
A6: y, м | B6: 248.95454 | C6: 226.57971 | D6: 150 | E6: 147.00639 | F6: 120.04762 | G6: 50 | H6: 50 | I6: 49.131476 | J6: 35.655331 | K6: 20.540084 | L6: 293.24638 | M6: 257.71821 | N6: 250 | O6: 250 | P6: 250 | Q6: 186.71429 | R6: 159.51807 | S6: 150 | T6: 150 | U6: 93.396825 | V6: 84.958815 | W6: 60.519846
A7: Mx = x·V | B7: =B5*B4 -> 116726.21 | C7: =C5*C4 -> 36586.216 | D7: =D5*D4 -> 212150 | E7: =E5*E4 -> 323485.32 | F7: =F5*F4 -> 61381.426 | G7: =G5*G4 -> 243400 | H7: =H5*H4 -> 790200 | I7: =I5*I4 -> 610803.65 | ... W7: =W5*W4 -> 706684.31
A8: My = y·V | B8: =B6*B4 -> 593305.36 | C8: =C6*C4 -> 68666.973 | D8: =D6*D4 -> 636450 | E8: =E6*E4 -> 323606.58 | F8: =F6*F4 -> 32499.841 | G8: =G6*G4 -> 243400 | H8: =H6*H4 -> 263400 | I8: =I6*I4 -> 120457.22 | ... W8: =W6*W4 -> 93444.31
A11: Центр тяжести «Выемка»: Lx = ΣMx / ΣV, м | C11: =SUM(B7:K7)/SUM(B4:K4) -> 129.22931
A12: Центр тяжести «Выемка»: Ly = ΣMy / ΣV, м | C12: =SUM(B8:K8)/SUM(B4:K4) -> 98.116017
A13: Центр тяжести «Насыпь»: Lx, м | C13: =SUM(L7:W7)/SUM(L4:W4) -> 362.02018
A14: Центр тяжести «Насыпь»: Ly, м | C14: =SUM(L8:W8)/SUM(L4:W4) -> 193.12103
A15: Средняя дальность Lср = √((Lxв − Lxн)² + (Lyв − Lyн)²), м | C15: =SQRT((C11-C13)^2+(C12-C14)^2) -> 251.43099

Sheet Табл. 6 самосвал
A1: Средняя дальность перемещения грунта автосамосвалом: котлован — насыпь (табл. 6)
B2: Котлован | C2: Насыпь
A3: № фигур | B3: котлован | C3: 5
A4: V, м³ | B4: 3971.7375 | C4: 3971.7375
A5: x, м | B5: 250 | C5: 450
A6: y, м | B6: 150 | C6: 250
A7: Mx = x·V | B7: =B5*B4 -> 992934.37 | C7: =C5*C4 -> 1787281.9
A8: My = y·V | B8: =B6*B4 -> 595760.62 | C8: =C6*C4 -> 992934.37
A11: Центр тяжести «Котлован»: Lx = ΣMx / ΣV, м | C11: =SUM(B7:B7)/SUM(B4:B4) -> 250
A12: Центр тяжести «Котлован»: Ly = ΣMy / ΣV, м | C12: =SUM(B8:B8)/SUM(B4:B4) -> 150
A13: Центр тяжести «Насыпь»: Lx, м | C13: =SUM(C7:C7)/SUM(C4:C4) -> 450
A14: Центр тяжести «Насыпь»: Ly, м | C14: =SUM(C8:C8)/SUM(C4:C4) -> 250
A15: Средняя дальность Lср = √((Lxв − Lxн)² + (Lyв − Lyн)²), м | C15: =SQRT((C11-C13)^2+(C12-C14)^2) -> 223.6068

Sheet 2.3 Грунт и нормы ЕНиР
A1: Назначение комплекта машин (п. 2.3 методички): грунт и нормы времени ЕНиР Е2-1
A3: Наименование и краткая характеристика грунта | B3: Супесь без примесей (ЕНиР Е2-1, техчасть, табл. 1, п. 22)
A4: Группа грунта в зависимости от трудности разработки | B4: одноковшовые экскаваторы — I; скреперы — II; бульдозеры — II
A5: Средняя плотность в естественном залегании, кг/м³ | B5: 1650
A7: Машина | B7: Марка | C7: Обоснование (ЕНиР Е2-1) | D7: Нвр, маш.-ч на 100 м³ | E7: Добавлять на каждые следующие 10 м | F7: Нвр дана до, м | G7: Условия
A8: Бульдозер (ведущая, вариант 1) | B8: ДЗ-34С (Д-572С), трактор ДЭТ-250 | C8: Е2-1-22, табл. 2, № 9б, 9д | D8: 0.24 | E8: 0.21 | F8: 10 | G8: тяжёлый (прил. 4); грунт II группы
A9: Скрепер прицепной (ведущая, вариант 2) | B9: ДЗ-20 (Д-498), ковш 6,7 м3, трактор Т-100 | C9: Е2-1-21, табл. 2, № 2б, 2г | D9: 1.7 | E9: 0.1 | F9: 100 | G9: ковш 6 м3 - 100-350 м (прил. 5); грунт II группы
A10: Трактор-рыхлитель | B10: ДП-22С на бульдозере ДЗ-35С, трактор Т-180 | C10: Е2-1-1, табл. 2, № 3в | D10: 0.06 | E10: — | F10: — | G10: рыхление слоями 0,35 м, участок св. 200 м
A11: Бульдозер (разравнивание) | B11: ДЗ-35С (Д-575С), трактор Т-180 | C11: Е2-1-28, № 6д | D11: 0.27 | E11: — | F11: — | G11: разравнивание слоями до 0,6 м (отсыпка скрепером 0,35 м)
A12: Каток | B12: ДУ-16В (Д-551В), на пневматических шинах | C12: Е2-1-29, табл. 4, № 2в | D12: 0.25 | E12: — | F12: — | G12: слой 0,2-0,35 м, 4 прохода по следу, гон св. 200 м
A13: Трактор-толкач | B13: Т-180 | C13: Е2-1-21, примеч. 2: Нвр скрепера / число скреперов | D13: Нвр скрепера / k | E13: — | F13: — | G13: 3 скрепера на толкач (прил. 5)
A15: Добавка на расстояние сверх указанного в норме - пропорционально: Нвр = Нвр.до + добавка · (Lср − L) / 10. Толкач: Нвр скрепера, делённая на число обслуживаемых скреперов (Е2-1-21, примеч. 2; прил. 5).

Sheet Табл. 7 варианты
A1: Варианты с различными ведущими машинами (табл. 7 методички), вертикальная планировка
A2: Vдн = 100·N·8 / Нвр; Mсм = Нвр·V / (100·8); nвед = Mсм / (m·t); n = nвед·Vдн.вед / Vдн.об (с. 25-27; Нвр - на 100 м³). Ведущая машина и толкач - V с kр, рыхлитель - V в плотном теле.
A4: Средняя дальность перемещения грунта Lср (табл. 5), м | C4: ='Табл. 5 скрепер'!$C$15 -> 251.43099
A5: Грунт выемок в насыпь (табл. 4), в плотном теле V, м³ | C5: =SUM('Табл. 4 распределение'!C5:L5) -> 23875.925
A6: То же с коэффициентом первоначального разрыхления V·kр, м³ | C6: =C5*'Исходные данные'!$B$7 -> 27457.314
A7: Объём насыпи - разравнивание и уплотнение Vн, м³ | C7: ='Табл. 4 распределение'!B19*'Исходные данные'!$B$4 -> 29210.697
A8: Число смен в сутках m (N), по 8 ч | C8: 2
A9: Срок планировочных работ t, дн. (5-20, для обоих вариантов) | C9: 20
A10: Скреперов на один трактор-толкач (прил. 5) | C10: 3
A12: Вариант 1 | E12: Вариант 2
A13: Ведущая машина — бульдозер | B13: ДЗ-34С (Д-572С), трактор ДЭТ-250 | E13: Ведущая машина — скрепер | F13: ДЗ-20 (Д-498), ковш 6,7 м3, трактор Т-100
A14: V, м³ | B14: объём с коэффициентом первоначального разрыхления | C14: =$C$6 -> 27457.314 | E14: V, м³ | G14: =$C$6 -> 27457.314
A15: Нвр вед, маш.-ч | C15: ='2.3 Грунт и нормы ЕНиР'!$D$8+'2.3 Грунт и нормы ЕНиР'!$E$8*($C$4-'2.3 Грунт и нормы ЕНиР'!$F$8)/10 -> 5.3100508 | E15: Нвр вед, маш.-ч | G15: ='2.3 Грунт и нормы ЕНиР'!$D$9+'2.3 Грунт и нормы ЕНиР'!$E$9*($C$4-'2.3 Грунт и нормы ЕНиР'!$F$9)/10 -> 3.2143099
A16: Mсм вед, маш.-см | C16: =C15*C14/800 -> 182.24966 | E16: Mсм вед, маш.-см | G16: =G15*G14/800 -> 110.32039
A17: Vдн вед, м³/дн | C17: =100*$C$8*8/C15 -> 301.31539 | E17: Vдн вед, м³/дн | G17: =100*$C$8*8/G15 -> 497.77403
A18: n, шт. | B18: =C16/($C$8*$C$9) -> 4.5562416 | C18: =ROUNDUP(ROUND(B18,6),0) -> 5 | E18: n, шт. | F18: =G16/($C$8*$C$9) -> 2.7580099 | G18: =ROUNDUP(ROUND(F18,6),0) -> 3
A19: Обеспечивающие машины | E19: Обеспечивающие машины
A20: Трактор-рыхлитель | B20: ДП-22С на бульдозере ДЗ-35С, трактор Т-180 | E20: Трактор-рыхлитель | F20: ДП-22С на бульдозере ДЗ-35С, трактор Т-180
A21: V, м³ | B21: объём в плотном теле | C21: =$C$5 -> 23875.925 | E21: V, м³ | G21: =$C$5 -> 23875.925
A22: Нвр об, маш.-ч | C22: ='2.3 Грунт и нормы ЕНиР'!$D$10 -> 0.06 | E22: Нвр об, маш.-ч | G22: ='2.3 Грунт и нормы ЕНиР'!$D$10 -> 0.06
A23: Mсм об, маш.-см | C23: =C22*C21/800 -> 1.7906944 | E23: Mсм об, маш.-см | G23: =G22*G21/800 -> 1.7906944
A24: Vдн об, м³/дн | C24: =100*$C$8*8/C22 -> 26666.667 | E24: Vдн об, м³/дн | G24: =100*$C$8*8/G22 -> 26666.667
A25: n, шт. | B25: =C18*C17/C24 -> 0.056496635 | C25: =ROUNDUP(ROUND(B25,6),0) -> 1 | E25: n, шт. | F25: =G18*G17/G24 -> 0.055999579 | G25: =ROUNDUP(ROUND(F25,6),0) -> 1
A26: Каток | B26: ДУ-16В (Д-551В), на пневматических шинах | E26: Бульдозер | F26: ДЗ-35С (Д-575С), трактор Т-180
A27: V, м³ | C27: =$C$7 -> 29210.697 | E27: V, м³ | G27: =$C$7 -> 29210.697
A28: Нвр об, маш.-ч | C28: ='2.3 Грунт и нормы ЕНиР'!$D$12 -> 0.25 | E28: Нвр об, маш.-ч | G28: ='2.3 Грунт и нормы ЕНиР'!$D$11 -> 0.27
A29: Mсм об, маш.-см | C29: =C28*C27/800 -> 9.1283427 | E29: Mсм об, маш.-см | G29: =G28*G27/800 -> 9.8586101
A30: Vдн об, м³/дн | C30: =100*$C$8*8/C28 -> 6400 | E30: Vдн об, м³/дн | G30: =100*$C$8*8/G28 -> 5925.9259
A31: n, шт. | B31: =C18*C17/C30 -> 0.23540265 | C31: =ROUNDUP(ROUND(B31,6),0) -> 1 | E31: n, шт. | F31: =G18*G17/G30 -> 0.25199811 | G31: =ROUNDUP(ROUND(F31,6),0) -> 1
E32: Каток | F32: ДУ-16В (Д-551В), на пневматических шинах
E33: V, м³ | G33: =$C$7 -> 29210.697
E34: Нвр об, маш.-ч | G34: ='2.3 Грунт и нормы ЕНиР'!$D$12 -> 0.25
E35: Mсм об, маш.-см | G35: =G34*G33/800 -> 9.1283427
E36: Vдн об, м³/дн | G36: =100*$C$8*8/G34 -> 6400
E37: n, шт. | F37: =G18*G17/G36 -> 0.23333158 | G37: =ROUNDUP(ROUND(F37,6),0) -> 1
E38: Трактор-толкач | F38: Т-180
E39: V, м³ | G39: =$C$6 -> 27457.314
E40: Нвр об, маш.-ч | G40: =G15/$C$10 -> 1.0714366
E41: Mсм об, маш.-см | G41: =G40*G39/800 -> 36.773465
E42: Vдн об, м³/дн | G42: =100*$C$8*8/G40 -> 1493.3221
...

Sheet 2.3.2 Экскаватор, самосвалы
A1: Машины для разработки грунта в котловане (п. 2.3.2): экскаватор и автосамосвалы
A3: Объём котлована Vк, м³ | C3: ='Котлован (оконч.)'!$C$60 -> 3971.7375
A4: Глубина котлована hк, м | C4: ='Котлован (оконч.)'!$C$39 -> 2.0918
A5: Число смен в сутках m | C5: ='Табл. 7 варианты'!$C$8 -> 2
A7: Экскаватор (обратная лопата) | B7: Привод | C7: Ковш q, м³ | D7: Обоснование (ЕНиР Е2-1) | E7: Нвр, маш.-ч на 100 м³ (I гр., с погрузкой) | F7: Псм = 100·8 / Нвр, м³/смену | G7: Hк max для котлованов, м | H7: Rmax, м | I7: Высота выгрузки, м | J7: Недобор (прил. 7), см
A8: Э-505 | B8: механический | C8: 0.5 | D8: Е2-1-11, табл. 3, № 4а | E8: 2.9 | F8: =100*8/E8 -> 275.86207 | G8: 4 | H8: 9.2 | I8: 1.7 | J8: 15
A9: Э-652 | B9: механический | C9: 0.65 | D9: Е2-1-11, табл. 3, № 5а | E9: 2.3 | F9: =100*8/E9 -> 347.82609 | G9: 4 | H9: 9.2 | I9: 2.3 | J9: 15
A10: ЭО-4121А | B10: гидравлический | C10: 0.65 | D10: Е2-1-11, табл. 7, № 4а | E10: 2.1 | F10: =100*8/E10 -> 380.95238 | G10: 5.8 | H10: 9 | I10: 5 | J10: 10
E11: Прил. 6: ёмкость ковша по объёму сооружения
A12: Принят экскаватор - наибольшая производительность | C12: =INDEX($A$8:$A$10,MATCH(MAX($F$8:$F$10),$F$8:$F$10,0)) -> ЭО-4121А | E12: Ковш, м³ | F12: Vк от, м³ | G12: Vк до, м³ | H12: Подходит
A13: Ковш q, м³ | C13: =INDEX($C$8:$C$10,MATCH(MAX($F$8:$F$10),$F$8:$F$10,0)) -> 0.65 | E13: 0,15 | F13: 0 | G13: 500 | H13: =IF(AND($C$3>=F13,$C$3<=IF(ISNUMBER(G13),G13,1E+99)),"да","")
A14: Нвр, маш.-ч на 100 м³ | C14: =INDEX($E$8:$E$10,MATCH(MAX($F$8:$F$10),$F$8:$F$10,0)) -> 2.1 | E14: 0,25 и 0,30 | F14: 500 | G14: 1500 | H14: =IF(AND($C$3>=F14,$C$3<=IF(ISNUMBER(G14),G14,1E+99)),"да","")
A15: Недобор, м | C15: =INDEX($J$8:$J$10,MATCH(MAX($F$8:$F$10),$F$8:$F$10,0))/100 -> 0.1 | E15: 0,5 | F15: 1500 | G15: 5000 | H15: =IF(AND($C$3>=F15,$C$3<=IF(ISNUMBER(G15),G15,1E+99)),"да","") -> да
A16: Глубина копания экскаватором hк − недобор, м | C16: =C4-C15 -> 1.9918 | E16: 0,65 | F16: 2000 | G16: 8000 | H16: =IF(AND($C$3>=F16,$C$3<=IF(ISNUMBER(G16),G16,1E+99)),"да","") -> да
A17: Проверка: Hк max не меньше глубины копания | C17: =IF(INDEX($G$8:$G$10,MATCH(MAX($F$8:$F$10),$F$8:$F$10,0))>=C16,"выполняется","НЕТ") -> выполняется | E17: 0,8 | F17: 6000 | G17: 11000 | H17: =IF(AND($C$3>=F17,$C$3<=IF(ISNUMBER(G17),G17,1E+99)),"да","")
A18: Mсм = Нвр·Vк / (100·8), маш.-см | C18: =C14*C3/800 -> 10.425811 | E18: 1 | F18: 11000 | G18: 15000 | H18: =IF(AND($C$3>=F18,$C$3<=IF(ISNUMBER(G18),G18,1E+99)),"да","")
A19: Продолжительность одним экскаватором Mсм / m, дн. | C19: =C18/C5 -> 5.2129055 | E19: 1,25 | F19: 13000 | G19: 18000 | H19: =IF(AND($C$3>=F19,$C$3<=IF(ISNUMBER(G19),G19,1E+99)),"да","")
E20: 1,50 и более | F20: 17000 | G20: — | H20: =IF(AND($C$3>=F20,$C$3<=IF(ISNUMBER(G20),G20,1E+99)),"да","")
A21: Автосамосвалы (с. 28-29, прил. 8)
A22: Коэффициент наполнения ковша kнап (табл. 8: 0,8-1,0) | C22: 0.9
A23: Коэффициент первоначального разрыхления kр | C23: ='Исходные данные'!$B$7 -> 1.15
A24: Плотность грунта γ, т/м³ | C24: ='2.3 Грунт и нормы ЕНиР'!$B$5/1000 -> 1.65
A25: Грунт в ковше в плотном теле Vгр.к = q·kнап / kр, м³ | C25: =C13*C22/C23 -> 0.50869565
A26: Масса грунта в ковше Mковша = Vгр.к·γ, т | C26: =C25*C24 -> 0.83934783
A27: Дальность транспортирования L, км (до карьера, отвала) | C27: 10
A28: Установка под погрузку Ту.п, мин | C28: 0.3
A29: Установка под разгрузку Ту.р, мин | C29: 0.6
A30: Разгрузка Тр, мин | C30: 1
A31: Маневрирование Тм, мин | C31: 2
A33: Модель | B33: Va, м³ | C33: Па, т | D33: Погрузочная высота, м | E33: Uгр, км/ч | F33: Uпор, км/ч | G33: Па / Mковша | H33: Va / q | I33: n (целое меньшее) | J33: 6 ≤ n ≤ 11 | K33: Va пл = n·Vгр.к, м³ | L33: Тп = Va пл·Нвр / 100 · 60, мин | M33: Тпр гр = L / Uгр · 60, мин | N33: Тпр пор = L / Uпор · 60, мин | O33: Тцикла, мин | P33: Тцикла / Тп | Q33: N, шт. | R33: Va р = q·kнап·n, м³ | S33: Нвр а = Тцикла / (Va р·60), маш.-ч/м³ | T33: Нвр а подходящих
A34: ГАЗ-САЗ-35072 | B34: 4.5 | C34: 4.1 | D34: 2.48 | E34: 45 | F34: 60 | G34: =C34/$C$26 -> 4.8847449 | H34: =B34/$C$13 -> 6.9230769 | I34: =INT(ROUND(MIN(G34,H34),6)) -> 4 | J34: =IF(AND(I34>=6,I34<=11),"да","нет") -> нет | K34: =I34*$C$25 -> 2.0347826 | L34: =K34*$C$14/100*60 -> 2.5638261 | M34: =$C$27/E34*60 -> 13.333333 | N34: =$C$27/F34*60 -> 10 | O34: =$C$28+L34+M34+N34+$C$29+$C$30+$C$31 -> 29.797159 | P34: =O34/L34 -> 11.622145 | Q34: =ROUNDUP(ROUND(P34,6),0) -> 12 | R34: =$C$13*$C$22*I34 -> 2.34 | S34: =O34/(R34*60) -> 0.21223048 | T34: =IF(J34="да",S34,"")
A35: ГАЗ-САЗ-35072-10 | B35: 4.5 | C35: 3.95 | D35: 2.48 | E35: 47 | F35: 60 | G35: =C35/$C$26 -> 4.7060347 | H35: =B35/$C$13 -> 6.9230769 | I35: =INT(ROUND(MIN(G35,H35),6)) -> 4 | J35: =IF(AND(I35>=6,I35<=11),"да","нет") -> нет | K35: =I35*$C$25 -> 2.0347826 | L35: =K35*$C$14/100*60 -> 2.5638261 | M35: =$C$27/E35*60 -> 12.765957 | N35: =$C$27/F35*60 -> 10 | O35: =$C$28+L35+M35+N35+$C$29+$C$30+$C$31 -> 29.229784 | P35: =O35/L35 -> 11.400845 | Q35: =ROUNDUP(ROUND(P35,6),0) -> 12 | R35: =$C$13*$C$22*I35 -> 2.34 | S35: =O35/(R35*60) -> 0.20818934 | T35: =IF(J35="да",S35,"")
A36: ЗИЛ-ММЗ-45085 | B36: 3.8 | C36: 5.5 | D36: 2.81 | E36: 42 | F36: 60 | G36: =C36/$C$26 -> 6.5527066 | H36: =B36/$C$13 -> 5.8461538 | I36: =INT(ROUND(MIN(G36,H36),6)) -> 5 | J36: =IF(AND(I36>=6,I36<=11),"да","нет") -> нет | K36: =I36*$C$25 -> 2.5434783 | L36: =K36*$C$14/100*60 -> 3.2047826 | M36: =$C$27/E36*60 -> 14.285714 | N36: =$C$27/F36*60 -> 10 | O36: =$C$28+L36+M36+N36+$C$29+$C$30+$C$31 -> 31.390497 | P36: =O36/L36 -> 9.7948912 | Q36: =ROUNDUP(ROUND(P36,6),0) -> 10 | R36: =$C$13*$C$22*I36 -> 2.925 | S36: =O36/(R36*60) -> 0.17886323 | T36: =IF(J36="да",S36,"")
A37: МАЗ-555102-220 | B37: 5.4 | C37: 10 | D37: 2.15 | E37: 48 | F37: 60 | G37: =C37/$C$26 -> 11.914012 | H37: =B37/$C$13 -> 8.3076923 | I37: =INT(ROUND(MIN(G37,H37),6)) -> 8 | J37: =IF(AND(I37>=6,I37<=11),"да","нет") -> да | K37: =I37*$C$25 -> 4.0695652 | L37: =K37*$C$14/100*60 -> 5.1276522 | M37: =$C$27/E37*60 -> 12.5 | N37: =$C$27/F37*60 -> 10 | O37: =$C$28+L37+M37+N37+$C$29+$C$30+$C$31 -> 31.527652 | P37: =O37/L37 -> 6.1485551 | Q37: =ROUNDUP(ROUND(P37,6),0) -> 7 | R37: =$C$13*$C$22*I37 -> 4.68 | S37: =O37/(R37*60) -> 0.11227796 | T37: =IF(J37="да",S37,"") -> 0.11227796
A38: МАЗ-555130-2120 | B38: 5.5 | C38: 9 | D38: 2.15 | E38: 40 | F38: 60 | G38: =C38/$C$26 -> 10.722611 | H38: =B38/$C$13 -> 8.4615385 | I38: =INT(ROUND(MIN(G38,H38),6)) -> 8 | J38: =IF(AND(I38>=6,I38<=11),"да","нет") -> да | K38: =I38*$C$25 -> 4.0695652 | L38: =K38*$C$14/100*60 -> 5.1276522 | M38: =$C$27/E38*60 -> 15 | N38: =$C$27/F38*60 -> 10 | O38: =$C$28+L38+M38+N38+$C$29+$C$30+$C$31 -> 34.027652 | P38: =O38/L38 -> 6.6361077 | Q38: =ROUNDUP(ROUND(P38,6),0) -> 7 | R38: =$C$13*$C$22*I38 -> 4.68 | S38: =O38/(R38*60) -> 0.1211811 | T38: =IF(J38="да",S38,"") -> 0.1211811
A39: МАЗ-555402-220 | B39: 5.5 | C39: 7 | D39: 2.15 | E39: 42 | F39: 60 | G39: =C39/$C$26 -> 8.3398083 | H39: =B39/$C$13 -> 8.4615385 | I39: =INT(ROUND(MIN(G39,H39),6)) -> 8 | J39: =IF(AND(I39>=6,I39<=11),"да","нет") -> да | K39: =I39*$C$25 -> 4.0695652 | L39: =K39*$C$14/100*60 -> 5.1276522 | M39: =$C$27/E39*60 -> 14.285714 | N39: =$C$27/F39*60 -> 10 | O39: =$C$28+L39+M39+N39+$C$29+$C$30+$C$31 -> 33.313366 | P39: =O39/L39 -> 6.496807 | Q39: =ROUNDUP(ROUND(P39,6),0) -> 7 | R39: =$C$13*$C$22*I39 -> 4.68 | S39: =O39/(R39*60) -> 0.11863734 | T39: =IF(J39="да",S39,"") -> 0.11863734
A40: МАЗ-551603-2121 | B40: 10.5 | C40: 20 | D40: 2.6 | E40: 50 | F40: 60 | G40: =C40/$C$26 -> 23.828024 | H40: =B40/$C$13 -> 16.153846 | I40: =INT(ROUND(MIN(G40,H40),6)) -> 16 | J40: =IF(AND(I40>=6,I40<=11),"да","нет") -> нет | K40: =I40*$C$25 -> 8.1391304 | L40: =K40*$C$14/100*60 -> 10.255304 | M40: =$C$27/E40*60 -> 12 | N40: =$C$27/F40*60 -> 10 | O40: =$C$28+L40+M40+N40+$C$29+$C$30+$C$31 -> 36.155304 | P40: =O40/L40 -> 3.5255223 | Q40: =ROUNDUP(ROUND(P40,6),0) -> 4 | R40: =$C$13*$C$22*I40 -> 9.36 | S40: =O40/(R40*60) -> 0.064379103 | T40: =IF(J40="да",S40,"")
A41: МАЗ-551605-2125 | B41: 11 | C41: 20 | D41: 2.53 | E41: 48 | F41: 60 | G41: =C41/$C$26 -> 23.828024 | H41: =B41/$C$13 -> 16.923077 | I41: =INT(ROUND(MIN(G41,H41),6)) -> 16 | J41: =IF(AND(I41>=6,I41<=11),"да","нет") -> нет | K41: =I41*$C$25 -> 8.1391304 | L41: =K41*$C$14/100*60 -> 10.255304 | M41: =$C$27/E41*60 -> 12.5 | N41: =$C$27/F41*60 -> 10 | O41: =$C$28+L41+M41+N41+$C$29+$C$30+$C$31 -> 36.655304 | P41: =O41/L41 -> 3.5742776 | Q41: =ROUNDUP(ROUND(P41,6),0) -> 4 | R41: =$C$13*$C$22*I41 -> 9.36 | S41: =O41/(R41*60) -> 0.065269417 | T41: =IF(J41="да",S41,"")
A42: КамАЗ-6520 | B42: 12 | C42: 14.4 | D42: 3.2 | E42: 55 | F42: 60 | G42: =C42/$C$26 -> 17.156177 | H42: =B42/$C$13 -> 18.461538 | I42: =INT(ROUND(MIN(G42,H42),6)) -> 17 | J42: =IF(AND(I42>=6,I42<=11),"да","нет") -> нет | K42: =I42*$C$25 -> 8.6478261 | L42: =K42*$C$14/100*60 -> 10.896261 | M42: =$C$27/E42*60 -> 10.909091 | N42: =$C$27/F42*60 -> 10 | O42: =$C$28+L42+M42+N42+$C$29+$C$30+$C$31 -> 35.705352 | P42: =O42/L42 -> 3.2768444 | Q42: =ROUNDUP(ROUND(P42,6),0) -> 4 | R42: =$C$13*$C$22*I42 -> 9.945 | S42: =O42/(R42*60) -> 0.059838029 | T42: =IF(J42="да",S42,"")
A43: КамАЗ-6540 | B43: 11 | C43: 18.5 | D43: 3.02 | E43: 55 | F43: 60 | G43: =C43/$C$26 -> 22.040922 | H43: =B43/$C$13 -> 16.923077 | I43: =INT(ROUND(MIN(G43,H43),6)) -> 16 | J43: =IF(AND(I43>=6,I43<=11),"да","нет") -> нет | K43: =I43*$C$25 -> 8.1391304 | L43: =K43*$C$14/100*60 -> 10.255304 | M43: =$C$27/E43*60 -> 10.909091 | N43: =$C$27/F43*60 -> 10 | O43: =$C$28+L43+M43+N43+$C$29+$C$30+$C$31 -> 35.064395 | P43: =O43/L43 -> 3.4191472 | Q43: =ROUNDUP(ROUND(P43,6),0) -> 4 | R43: =$C$13*$C$22*I43 -> 9.36 | S43: =O43/(R43*60) -> 0.062436601 | T43: =IF(J43="да",S43,"")
...
