Workbook
Name A2_B: 'Табл. А.2'!$B$3:$B$9
Name A2_C: 'Табл. А.2'!$C$3:$C$9
Name A2_D: 'Табл. А.2'!$D$3:$D$9
Name A2_E: 'Табл. А.2'!$E$3:$E$9
Name A2_F: 'Табл. А.2'!$F$3:$F$9
Name A2_G: 'Табл. А.2'!$G$3:$G$9
Name A2_H: 'Табл. А.2'!$H$3:$H$9
Name A2_I: 'Табл. А.2'!$I$3:$I$9
Name A2_IMYA: 'Табл. А.2'!$A$3:$A$9
Name A2_J: 'Табл. А.2'!$J$3:$J$9
Name B1_N: 'Табл. Б.1'!$A$3:$A$54
Name B1_P: 'Табл. Б.1'!$B$2:$K$2
Name B1_T: 'Табл. Б.1'!$B$3:$K$54
Name B2_A: 'Табл. Б.2'!$B$3:$B$583
Name B2_NP: 'Табл. Б.2'!$A$3:$A$583

Sheet Расчёт
B1: Расчёт расходов воды по СП 30.13330.2020 (п. 5, табл. А.2, Б.1, Б.2)
B2: Вписывайте данные только в жёлтые ячейки. Голубые — нормы из табл. А.2, подставляются сами по виду здания (можно исправить вручную). Зелёные — α по табл. Б.2/Б.1 и результаты. Ниже, в разделе 7, — запись решения с подставленными числами.
B4: 1. Исходные данные
B5: Число этажей, n_эт | C5: 12
B6: Число секций (квартиры ниже — на этаже одной секции) | C6: 1
B7: Заселённость, чел./кв. — если дана в задании (иначе оставить пустой: U считается по типам квартир) | C7: 3.4
B8: Вид жилого здания (табл. А.2 СП 30.13330.2020) — выбрать из списка | C8: с ваннами длиной 1500–1700 мм, оборудованными душами
B9: Как брать α по табл. Б.2 — выбрать из списка | C9: интерполяция | E9: интерполяция — как в таблице преподавателя; «ближайшее меньшее» — как в примерах методички 2024
B11: 2. Квартиры на этаже (в одной секции)
B12: Тип квартиры | C12: Квартир на этаже, n_кв | D12: Комнат, K | E12: Жителей в квартире, N_кв.жит (= K + 1) | F12: Приборов в квартире всего, n_пр (ХВС) | G12: из них с горячей водой (ГВС) | H12: Жителей на этаже | I12: Приборов ХВС на этаже | J12: Приборов ГВС на этаже
B13: 1-комнатная | D13: 1 | E13: =IF(OR(C13="",D13=""),0,D13+1) -> 0 | H13: =C13*E13 -> 0 | I13: =C13*F13 -> 0 | J13: =C13*G13 -> 0
B14: 2-комнатная | C14: 4 | D14: 2 | E14: =IF(OR(C14="",D14=""),0,D14+1) -> 3 | F14: 4 | G14: 3 | H14: =C14*E14 -> 12 | I14: =C14*F14 -> 16 | J14: =C14*G14 -> 12
B15: 3-комнатная | C15: 4 | D15: 3 | E15: =IF(OR(C15="",D15=""),0,D15+1) -> 4 | F15: 4 | G15: 3 | H15: =C15*E15 -> 16 | I15: =C15*F15 -> 16 | J15: =C15*G15 -> 12
B16: 4-комнатная | D16: 4 | E16: =IF(OR(C16="",D16=""),0,D16+1) -> 0 | H16: =C16*E16 -> 0 | I16: =C16*F16 -> 0 | J16: =C16*G16 -> 0
B17: другая | E17: =IF(OR(C17="",D17=""),0,D17+1) -> 0 | H17: =C17*E17 -> 0 | I17: =C17*F17 -> 0 | J17: =C17*G17 -> 0
B18: Итого на этаже секции | C18: =SUM(C13:C17) -> 8 | H18: =SUM(H13:H17) -> 28 | I18: =SUM(I13:I17) -> 32 | J18: =SUM(J13:J17) -> 24
B20: 3. Число водопотребителей U и приборов N | D20: Задано в задании
B21: U по типам квартир = Σ(N_кв.жит · n_кв) · n_эт · n_сек, чел. | C21: =H18*C5*C6 -> 336
B22: U по заселённости = заселённость · n_кв · n_эт · n_сек, чел. | C22: =IF(C7="","",C7*C18*C5*C6) -> 326.4
B23: U, принятое в расчёте (задано; иначе по заселённости — округление вверх), чел. | C23: =IF(D23<>"",D23,IF(C7="",C21,ROUNDUP(C22,0))) -> 288 | D23: 288 | E23: ← если U, N, N_h даны в задании готовыми числами — вписать сюда (разделы 1–2 тогда не нужны); N_h пусто — принимается равным N
B24: N — приборов с холодной водой (ХВС) = Σ(n_пр · n_кв) · n_эт · n_сек, шт. | C24: =IF(D24<>"",D24,I18*C5*C6) -> 316 | D24: 316
B25: N_h — приборов с горячей водой (ГВС), шт. | C25: =IF(D25<>"",D25,IF(D24<>"",D24,J18*C5*C6)) -> 316
B27: 4. Нормы водопотребления по табл. А.2 СП 30.13330.2020 (на 1 жителя / на 1 прибор)
B28: Норма | C28: tot (общий) | D28: h (горячей) | E28: c (холодной) | F28: ед. изм.
B29: q_u — расход в сутки наибольшего водопотребления | C29: =INDEX(A2_B,MATCH($C$8,A2_IMYA,0)) -> 180 | D29: =INDEX(A2_C,MATCH($C$8,A2_IMYA,0)) -> 70 | E29: =C29-D29 -> 110 | F29: л/сут
B30: q_hr,u — расход в час наибольшего водопотребления | C30: =INDEX(A2_D,MATCH($C$8,A2_IMYA,0)) -> 11.6 | D30: =INDEX(A2_E,MATCH($C$8,A2_IMYA,0)) -> 6.5 | E30: =C30-D30 -> 5.1 | F30: л/ч
B31: q_0 — секундный расход воды прибором | C31: =INDEX(A2_F,MATCH($C$8,A2_IMYA,0)) -> 0.3 | D31: =INDEX(A2_G,MATCH($C$8,A2_IMYA,0)) -> 0.2 | E31: =D31 -> 0.2 | F31: л/с
B32: q_0,hr — часовой расход воды прибором | C32: =INDEX(A2_H,MATCH($C$8,A2_IMYA,0)) -> 300 | D32: =INDEX(A2_I,MATCH($C$8,A2_IMYA,0)) -> 200 | E32: =D32 -> 200 | F32: л/ч
B33: T — время водопотребления | C33: =INDEX(A2_J,MATCH($C$8,A2_IMYA,0)) -> 24 | D33: =INDEX(A2_J,MATCH($C$8,A2_IMYA,0)) -> 24 | E33: =D33 -> 24 | F33: ч
B34: q_u^c = q_u^tot − q_u^h; q_hr,u^c = q_hr,u^tot − q_hr,u^h; q_0^c = q_0^h; q_0,hr^c = q_0,hr^h (табл. А.2). Нормы можно вписать вручную поверх голубых ячеек.
B36: 5. Расчёт расходов воды (п. 5 СП 30.13330.2020)
C37: T, ч | D37: U, чел. | E37: N, шт. | F37: q_u, л/сут | G37: q_hr,u, л/ч | H37: q_0, л/с | I37: q_0,hr, л/ч | J37: q_u,m — сут., м³/сут | K37: q_T — ср.-час., м³/ч | L37: P | M37: NP | N37: α | O37: q — сек., л/с | P37: P_hr | Q37: NP_hr | R37: α_hr | S37: q_hr — час., м³/ч
B38: tot (общий) | C38: =C33 -> 24 | D38: =$C$23 -> 288 | E38: =$C$24 -> 316 | F38: =C29 -> 180 | G38: =C30 -> 11.6 | H38: =C31 -> 0.3 | I38: =C32 -> 300 | J38: =F38*D38/1000 -> 51.84 | K38: =IF(C38=0,0,J38/C38) -> 2.16 | L38: =IF(OR(E38=0,H38=0),0,G38*D38/(H38*E38*3600)) -> 0.0097890295 | M38: =E38*L38 -> 3.0933333 | N38: =α!AA2 -> 1.8764 | O38: =IF(L38=0,0,5*H38*N38) -> 2.8146 | P38: =IF(I38=0,0,3600*L38*H38/I38) -> 0.035240506 | Q38: =E38*P38 -> 11.136 | R38: =α!AA5 -> 4.45844 | S38: =IF(P38=0,0,0.005*I38*R38) -> 6.68766
B39: h (горячей) | C39: =D33 -> 24 | D39: =$C$23 -> 288 | E39: =$C$25 -> 316 | F39: =D29 -> 70 | G39: =D30 -> 6.5 | H39: =D31 -> 0.2 | I39: =D32 -> 200 | J39: =F39*D39/1000 -> 20.16 | K39: =IF(C39=0,0,J39/C39) -> 0.84 | L39: =IF(OR(E39=0,H39=0),0,G39*D39/(H39*E39*3600)) -> 0.0082278481 | M39: =E39*L39 -> 2.6 | N39: =α!AA3 -> 1.684 | O39: =IF(L39=0,0,5*H39*N39) -> 1.684 | P39: =IF(I39=0,0,3600*L39*H39/I39) -> 0.029620253 | Q39: =E39*P39 -> 9.36 | R39: =α!AA6 -> 3.936 | S39: =IF(P39=0,0,0.005*I39*R39) -> 3.936
B40: c (холодной) | C40: =E33 -> 24 | D40: =$C$23 -> 288 | E40: =$C$24 -> 316 | F40: =E29 -> 110 | G40: =E30 -> 5.1 | H40: =E31 -> 0.2 | I40: =E32 -> 200 | J40: =F40*D40/1000 -> 31.68 | K40: =IF(C40=0,0,J40/C40) -> 1.32 | L40: =IF(OR(E40=0,H40=0),0,G40*D40/(H40*E40*3600)) -> 0.0064556962 | M40: =E40*L40 -> 2.04 | N40: =α!AA4 -> 1.4538 | O40: =IF(L40=0,0,5*H40*N40) -> 1.4538 | P40: =IF(I40=0,0,3600*L40*H40/I40) -> 0.023240506 | Q40: =E40*P40 -> 7.344 | R40: =α!AA7 -> 3.32064 | S40: =IF(P40=0,0,0.005*I40*R40) -> 3.32064
B41: P = q_hr,u·U/(q_0·N·3600); q = 5·q_0·α; P_hr = 3600·P·q_0/q_0,hr; q_hr = 0,005·q_0,hr·α_hr; q_u,m = q_u·U/1000; q_T = q_u,m/T. Для c: q_hr,u^c = q_hr,u^tot − q_hr,u^h.
B43: 6. Определение α: y = y₁ + (x − x₁)·(y₂ − y₁)/(x₂ − x₁) (при P > 0,1 и N ≤ 200 — по табл. Б.1)
B44: Случай | C44: Таблица | D44: NP₁ (x₁) | E44: α₁ (y₁) | F44: NP₂ (x₂) | G44: α₂ (y₂) | H44: NP (x) | I44: α (y) | J44: Примечание
B45: секундный tot | C45: =α!AB2 -> Б.2 | D45: =α!G2 -> 3 | E45: =α!H2 -> 1.84 | F45: =α!I2 -> 3.1 | G45: =α!J2 -> 1.879 | H45: =α!D2 -> 3.0933333 | I45: =α!AA2 -> 1.8764 | J45: =α!AC2
B46: секундный h | C46: =α!AB3 -> Б.2 | D46: =α!G3 -> 2.6 | E46: =α!H3 -> 1.684 | F46: =α!I3 -> 2.7 | G46: =α!J3 -> 1.724 | H46: =α!D3 -> 2.6 | I46: =α!AA3 -> 1.684 | J46: =α!AC3
...

Sheet α
A1: Случай | B1: N | C1: P | D1: NP | E1: по Б.1? | F1: i (Б.2) | G1: NP1 | H1: α1 | I1: NP2 | J1: α2 | K1: α по Б.2 | L1: r (Б.1) | M1: r2 | N1: c (Б.1) | O1: c2 | P1: N1 | Q1: N2 | R1: P1 | S1: P2 | T1: α11 | U1: α12 | V1: α21 | W1: α22 | X1: tP | Y1: tN | Z1: α по Б.1 | AA1: α | AB1: табл. | AC1: примечание
A2: секундный tot | B2: =Расчёт!E38 -> 316 | C2: =Расчёт!L38 -> 0.0097890295 | D2: =B2*C2 -> 3.0933333 | E2: =AND(C2>0.1,B2<=200,B2>=2) -> FALSE | F2: =IF(D2<0.015,0,MATCH(D2,B2_NP,1)) -> 166 | G2: =IF(F2=0,0,INDEX(B2_NP,F2)) -> 3 | H2: =IF(F2=0,0.2,INDEX(B2_A,F2)) -> 1.84 | I2: =IF(F2=0,0.015,INDEX(B2_NP,MIN(F2+1,581))) -> 3.1 | J2: =IF(F2=0,0.2,INDEX(B2_A,MIN(F2+1,581))) -> 1.879 | K2: =IF(OR(F2=0,I2=G2,Расчёт!$C$9="ближайшее меньшее"),H2,H2+(D2-G2)*(J2-H2)/(I2-G2)) -> 1.8764 | L2: =IF(E2,MATCH(B2,B1_N,1),1) -> 1 | M2: =MIN(L2+1,52) -> 2 | N2: =IF(E2,MATCH(C2,B1_P,1),1) -> 1 | O2: =MIN(N2+1,10) -> 2 | P2: =INDEX(B1_N,L2) -> 2 | Q2: =INDEX(B1_N,M2) -> 4 | R2: =INDEX(B1_P,N2) -> 0.1 | S2: =INDEX(B1_P,O2) -> 0.125 | T2: =INDEX(B1_T,L2,N2) -> 0.39 | U2: =INDEX(B1_T,L2,O2) -> 0.39 | V2: =INDEX(B1_T,M2,N2) -> 0.58 | W2: =INDEX(B1_T,M2,O2) -> 0.62 | X2: =IF(OR(S2=R2,Расчёт!$C$9="ближайшее меньшее"),0,(MIN(C2,S2)-R2)/(S2-R2)) -> -3.6084388 | Y2: =IF(OR(Q2=P2,Расчёт!$C$9="ближайшее меньшее"),0,(B2-P2)/(Q2-P2)) -> 157 | Z2: =(T2+(U2-T2)*X2)*(1-Y2)+(V2+(W2-V2)*X2)*Y2 -> 7.5590042 | AA2: =IF(E2,Z2,K2) -> 1.8764 | AB2: =IF(E2,"Б.1","Б.2") -> Б.2 | AC2: =IF(E2,"P > 0,1 и N ≤ 200 — α по табл. Б.1: N = "&P2&"…"&Q2&", P = "&R2&"…"&S2,IF(F2=0,"NP < 0,015 — α = 0,2 (табл. Б.2)",""))
A3: секундный h | B3: =Расчёт!E39 -> 316 | C3: =Расчёт!L39 -> 0.0082278481 | D3: =B3*C3 -> 2.6 | E3: =AND(C3>0.1,B3<=200,B3>=2) -> FALSE | F3: =IF(D3<0.015,0,MATCH(D3,B2_NP,1)) -> 162 | G3: =IF(F3=0,0,INDEX(B2_NP,F3)) -> 2.6 | H3: =IF(F3=0,0.2,INDEX(B2_A,F3)) -> 1.684 | I3: =IF(F3=0,0.015,INDEX(B2_NP,MIN(F3+1,581))) -> 2.7 | J3: =IF(F3=0,0.2,INDEX(B2_A,MIN(F3+1,581))) -> 1.724 | K3: =IF(OR(F3=0,I3=G3,Расчёт!$C$9="ближайшее меньшее"),H3,H3+(D3-G3)*(J3-H3)/(I3-G3)) -> 1.684 | L3: =IF(E3,MATCH(B3,B1_N,1),1) -> 1 | M3: =MIN(L3+1,52) -> 2 | N3: =IF(E3,MATCH(C3,B1_P,1),1) -> 1 | O3: =MIN(N3+1,10) -> 2 | P3: =INDEX(B1_N,L3) -> 2 | Q3: =INDEX(B1_N,M3) -> 4 | R3: =INDEX(B1_P,N3) -> 0.1 | S3: =INDEX(B1_P,O3) -> 0.125 | T3: =INDEX(B1_T,L3,N3) -> 0.39 | U3: =INDEX(B1_T,L3,O3) -> 0.39 | V3: =INDEX(B1_T,M3,N3) -> 0.58 | W3: =INDEX(B1_T,M3,O3) -> 0.62 | X3: =IF(OR(S3=R3,Расчёт!$C$9="ближайшее меньшее"),0,(MIN(C3,S3)-R3)/(S3-R3)) -> -3.6708861 | Y3: =IF(OR(Q3=P3,Расчёт!$C$9="ближайшее меньшее"),0,(B3-P3)/(Q3-P3)) -> 157 | Z3: =(T3+(U3-T3)*X3)*(1-Y3)+(V3+(W3-V3)*X3)*Y3 -> 7.1668354 | AA3: =IF(E3,Z3,K3) -> 1.684 | AB3: =IF(E3,"Б.1","Б.2") -> Б.2 | AC3: =IF(E3,"P > 0,1 и N ≤ 200 — α по табл. Б.1: N = "&P3&"…"&Q3&", P = "&R3&"…"&S3,IF(F3=0,"NP < 0,015 — α = 0,2 (табл. Б.2)",""))
A4: секундный c | B4: =Расчёт!E40 -> 316 | C4: =Расчёт!L40 -> 0.0064556962 | D4: =B4*C4 -> 2.04 | E4: =AND(C4>0.1,B4<=200,B4>=2) -> FALSE | F4: =IF(D4<0.015,0,MATCH(D4,B2_NP,1)) -> 156 | G4: =IF(F4=0,0,INDEX(B2_NP,F4)) -> 2 | H4: =IF(F4=0,0.2,INDEX(B2_A,F4)) -> 1.437 | I4: =IF(F4=0,0.015,INDEX(B2_NP,MIN(F4+1,581))) -> 2.1 | J4: =IF(F4=0,0.2,INDEX(B2_A,MIN(F4+1,581))) -> 1.479 | K4: =IF(OR(F4=0,I4=G4,Расчёт!$C$9="ближайшее меньшее"),H4,H4+(D4-G4)*(J4-H4)/(I4-G4)) -> 1.4538 | L4: =IF(E4,MATCH(B4,B1_N,1),1) -> 1 | M4: =MIN(L4+1,52) -> 2 | N4: =IF(E4,MATCH(C4,B1_P,1),1) -> 1 | O4: =MIN(N4+1,10) -> 2 | P4: =INDEX(B1_N,L4) -> 2 | Q4: =INDEX(B1_N,M4) -> 4 | R4: =INDEX(B1_P,N4) -> 0.1 | S4: =INDEX(B1_P,O4) -> 0.125 | T4: =INDEX(B1_T,L4,N4) -> 0.39 | U4: =INDEX(B1_T,L4,O4) -> 0.39 | V4: =INDEX(B1_T,M4,N4) -> 0.58 | W4: =INDEX(B1_T,M4,O4) -> 0.62 | X4: =IF(OR(S4=R4,Расчёт!$C$9="ближайшее меньшее"),0,(MIN(C4,S4)-R4)/(S4-R4)) -> -3.7417722 | Y4: =IF(OR(Q4=P4,Расчёт!$C$9="ближайшее меньшее"),0,(B4-P4)/(Q4-P4)) -> 157 | Z4: =(T4+(U4-T4)*X4)*(1-Y4)+(V4+(W4-V4)*X4)*Y4 -> 6.7216709 | AA4: =IF(E4,Z4,K4) -> 1.4538 | AB4: =IF(E4,"Б.1","Б.2") -> Б.2 | AC4: =IF(E4,"P > 0,1 и N ≤ 200 — α по табл. Б.1: N = "&P4&"…"&Q4&", P = "&R4&"…"&S4,IF(F4=0,"NP < 0,015 — α = 0,2 (табл. Б.2)",""))
A5: часовой tot | B5: =Расчёт!E38 -> 316 | C5: =Расчёт!P38 -> 0.035240506 | D5: =B5*C5 -> 11.136 | E5: =AND(C5>0.1,B5<=200,B5>=2) -> FALSE | F5: =IF(D5<0.015,0,MATCH(D5,B2_NP,1)) -> 241 | G5: =IF(F5=0,0,INDEX(B2_NP,F5)) -> 11 | H5: =IF(F5=0,0.2,INDEX(B2_A,F5)) -> 4.419 | I5: =IF(F5=0,0.015,INDEX(B2_NP,MIN(F5+1,581))) -> 11.2 | J5: =IF(F5=0,0.2,INDEX(B2_A,MIN(F5+1,581))) -> 4.477 | K5: =IF(OR(F5=0,I5=G5,Расчёт!$C$9="ближайшее меньшее"),H5,H5+(D5-G5)*(J5-H5)/(I5-G5)) -> 4.45844 | L5: =IF(E5,MATCH(B5,B1_N,1),1) -> 1 | M5: =MIN(L5+1,52) -> 2 | N5: =IF(E5,MATCH(C5,B1_P,1),1) -> 1 | O5: =MIN(N5+1,10) -> 2 | P5: =INDEX(B1_N,L5) -> 2 | Q5: =INDEX(B1_N,M5) -> 4 | R5: =INDEX(B1_P,N5) -> 0.1 | S5: =INDEX(B1_P,O5) -> 0.125 | T5: =INDEX(B1_T,L5,N5) -> 0.39 | U5: =INDEX(B1_T,L5,O5) -> 0.39 | V5: =INDEX(B1_T,M5,N5) -> 0.58 | W5: =INDEX(B1_T,M5,O5) -> 0.62 | X5: =IF(OR(S5=R5,Расчёт!$C$9="ближайшее меньшее"),0,(MIN(C5,S5)-R5)/(S5-R5)) -> -2.5903797 | Y5: =IF(OR(Q5=P5,Расчёт!$C$9="ближайшее меньшее"),0,(B5-P5)/(Q5-P5)) -> 157 | Z5: =(T5+(U5-T5)*X5)*(1-Y5)+(V5+(W5-V5)*X5)*Y5 -> 13.952415 | AA5: =IF(E5,Z5,K5) -> 4.45844 | AB5: =IF(E5,"Б.1","Б.2") -> Б.2 | AC5: =IF(E5,"P > 0,1 и N ≤ 200 — α по табл. Б.1: N = "&P5&"…"&Q5&", P = "&R5&"…"&S5,IF(F5=0,"NP < 0,015 — α = 0,2 (табл. Б.2)",""))
A6: часовой h | B6: =Расчёт!E39 -> 316 | C6: =Расчёт!P39 -> 0.029620253 | D6: =B6*C6 -> 9.36 | E6: =AND(C6>0.1,B6<=200,B6>=2) -> FALSE | F6: =IF(D6<0.015,0,MATCH(D6,B2_NP,1)) -> 229 | G6: =IF(F6=0,0,INDEX(B2_NP,F6)) -> 9.3 | H6: =IF(F6=0,0.2,INDEX(B2_A,F6)) -> 3.918 | I6: =IF(F6=0,0.015,INDEX(B2_NP,MIN(F6+1,581))) -> 9.4 | J6: =IF(F6=0,0.2,INDEX(B2_A,MIN(F6+1,581))) -> 3.948 | K6: =IF(OR(F6=0,I6=G6,Расчёт!$C$9="ближайшее меньшее"),H6,H6+(D6-G6)*(J6-H6)/(I6-G6)) -> 3.936 | L6: =IF(E6,MATCH(B6,B1_N,1),1) -> 1 | M6: =MIN(L6+1,52) -> 2 | N6: =IF(E6,MATCH(C6,B1_P,1),1) -> 1 | O6: =MIN(N6+1,10) -> 2 | P6: =INDEX(B1_N,L6) -> 2 | Q6: =INDEX(B1_N,M6) -> 4 | R6: =INDEX(B1_P,N6) -> 0.1 | S6: =INDEX(B1_P,O6) -> 0.125 | T6: =INDEX(B1_T,L6,N6) -> 0.39 | U6: =INDEX(B1_T,L6,O6) -> 0.39 | V6: =INDEX(B1_T,M6,N6) -> 0.58 | W6: =INDEX(B1_T,M6,O6) -> 0.62 | X6: =IF(OR(S6=R6,Расчёт!$C$9="ближайшее меньшее"),0,(MIN(C6,S6)-R6)/(S6-R6)) -> -2.8151899 | Y6: =IF(OR(Q6=P6,Расчёт!$C$9="ближайшее меньшее"),0,(B6-P6)/(Q6-P6)) -> 157 | Z6: =(T6+(U6-T6)*X6)*(1-Y6)+(V6+(W6-V6)*X6)*Y6 -> 12.540608 | AA6: =IF(E6,Z6,K6) -> 3.936 | AB6: =IF(E6,"Б.1","Б.2") -> Б.2 | AC6: =IF(E6,"P > 0,1 и N ≤ 200 — α по табл. Б.1: N = "&P6&"…"&Q6&", P = "&R6&"…"&S6,IF(F6=0,"NP < 0,015 — α = 0,2 (табл. Б.2)",""))
A7: часовой c | B7: =Расчёт!E40 -> 316 | C7: =Расчёт!P40 -> 0.023240506 | D7: =B7*C7 -> 7.344 | E7: =AND(C7>0.1,B7<=200,B7>=2) -> FALSE | F7: =IF(D7<0.015,0,MATCH(D7,B2_NP,1)) -> 209 | G7: =IF(F7=0,0,INDEX(B2_NP,F7)) -> 7.3 | H7: =IF(F7=0,0.2,INDEX(B2_A,F7)) -> 3.307 | I7: =IF(F7=0,0.015,INDEX(B2_NP,MIN(F7+1,581))) -> 7.4 | J7: =IF(F7=0,0.2,INDEX(B2_A,MIN(F7+1,581))) -> 3.338 | K7: =IF(OR(F7=0,I7=G7,Расчёт!$C$9="ближайшее меньшее"),H7,H7+(D7-G7)*(J7-H7)/(I7-G7)) -> 3.32064 | L7: =IF(E7,MATCH(B7,B1_N,1),1) -> 1 | M7: =MIN(L7+1,52) -> 2 | N7: =IF(E7,MATCH(C7,B1_P,1),1) -> 1 | O7: =MIN(N7+1,10) -> 2 | P7: =INDEX(B1_N,L7) -> 2 | Q7: =INDEX(B1_N,M7) -> 4 | R7: =INDEX(B1_P,N7) -> 0.1 | S7: =INDEX(B1_P,O7) -> 0.125 | T7: =INDEX(B1_T,L7,N7) -> 0.39 | U7: =INDEX(B1_T,L7,O7) -> 0.39 | V7: =INDEX(B1_T,M7,N7) -> 0.58 | W7: =INDEX(B1_T,M7,O7) -> 0.62 | X7: =IF(OR(S7=R7,Расчёт!$C$9="ближайшее меньшее"),0,(MIN(C7,S7)-R7)/(S7-R7)) -> -3.0703797 | Y7: =IF(OR(Q7=P7,Расчёт!$C$9="ближайшее меньшее"),0,(B7-P7)/(Q7-P7)) -> 157 | Z7: =(T7+(U7-T7)*X7)*(1-Y7)+(V7+(W7-V7)*X7)*Y7 -> 10.938015 | AA7: =IF(E7,Z7,K7) -> 3.32064 | AB7: =IF(E7,"Б.1","Б.2") -> Б.2 | AC7: =IF(E7,"P > 0,1 и N ≤ 200 — α по табл. Б.1: N = "&P7&"…"&Q7&", P = "&R7&"…"&S7,IF(F7=0,"NP < 0,015 — α = 0,2 (табл. Б.2)",""))
A10: Вспомогательный лист: подбор α по табл. Б.2 (интерполяция или ближайшее меньшее) и Б.1 (двойная интерполяция по N и P).

Sheet Табл. Б.2
A1: Табл. Б.2 СП 30.13330.2020: α при P ≤ 0,1 и любом N, а также при P > 0,1 и N > 200 (NP < 0,015 → α = 0,2)
A2: NP | B2: α
A3: 0.015 | B3: 0.202
A4: 0.016 | B4: 0.205
A5: 0.017 | B5: 0.207
A6: 0.018 | B6: 0.21
A7: 0.019 | B7: 0.212
A8: 0.02 | B8: 0.215
A9: 0.021 | B9: 0.217
A10: 0.022 | B10: 0.219
A11: 0.023 | B11: 0.222
A12: 0.024 | B12: 0.224
A13: 0.025 | B13: 0.226
A14: 0.026 | B14: 0.228
... A583: 2000 | B583: 426.8

Sheet Табл. Б.1
A1: Табл. Б.1 СП 30.13330.2020: α при P > 0,1 и N ≤ 200 (строки — N, столбцы — P)
A2: N \ P | B2: 0.1 | C2: 0.125 | D2: 0.16 | E2: 0.2 | F2: 0.25 | G2: 0.316 | H2: 0.4 | I2: 0.5 | J2: 0.63 | K2: 0.8
A3: 2 | B3: 0.39 | C3: 0.39 | D3: 0.4 | E3: 0.4 | F3: 0.4 | G3: 0.4 | H3: 0.4 | I3: 0.4 | J3: 0.4 | K3: 0.4
A4: 4 | B4: 0.58 | C4: 0.62 | D4: 0.65 | E4: 0.69 | F4: 0.72 | G4: 0.76 | H4: 0.78 | I4: 0.8 | J4: 0.8 | K4: 0.8
A5: 6 | B5: 0.72 | C5: 0.78 | D5: 0.83 | E5: 0.9 | F5: 0.97 | G5: 1.04 | H5: 1.11 | I5: 1.16 | J5: 1.2 | K5: 1.2
A6: 8 | B6: 0.84 | C6: 0.91 | D6: 0.99 | E6: 1.08 | F6: 1.18 | G6: 1.29 | H6: 1.39 | I6: 1.5 | J6: 1.58 | K6: 1.59
A7: 10 | B7: 0.95 | C7: 1.04 | D7: 1.14 | E7: 1.25 | F7: 1.38 | G7: 1.52 | H7: 1.66 | I7: 1.81 | J7: 1.94 | K7: 1.97
A8: 12 | B8: 1.05 | C8: 1.15 | D8: 1.28 | E8: 1.41 | F8: 1.57 | G8: 1.74 | H8: 1.92 | I8: 2.11 | J8: 2.29 | K8: 2.36
A9: 14 | B9: 1.14 | C9: 1.27 | D9: 1.41 | E9: 1.57 | F9: 1.75 | G9: 1.95 | H9: 2.17 | I9: 2.4 | J9: 2.63 | K9: 2.75
A10: 16 | B10: 1.25 | C10: 1.37 | D10: 1.53 | E10: 1.71 | F10: 1.92 | G10: 2.15 | H10: 2.41 | I10: 2.69 | J10: 2.96 | K10: 3.14
A11: 18 | B11: 1.32 | C11: 1.47 | D11: 1.65 | E11: 1.85 | F11: 2.09 | G11: 2.35 | H11: 2.55 | I11: 2.97 | J11: 3.24 | K11: 3.53
A12: 20 | B12: 1.41 | C12: 1.57 | D12: 1.77 | E12: 1.99 | F12: 2.25 | G12: 2.55 | H12: 2.88 | I12: 3.24 | J12: 3.6 | K12: 3.92
A13: 22 | B13: 1.49 | C13: 1.67 | D13: 1.88 | E13: 2.13 | F13: 2.41 | G13: 2.74 | H13: 3.11 | I13: 3.51 | J13: 3.94 | K13: 4.33
A14: 24 | B14: 1.57 | C14: 1.77 | D14: 2 | E14: 2.26 | F14: 2.57 | G14: 2.93 | H14: 3.33 | I14: 3.78 | J14: 4.27 | K14: 4.7
... A54: 200 | B54: 6.89 | C54: 8.19 | D54: 9.96 | E54: 11.9 | F54: 14.3 | G54: 17.4 | H54: 21.3 | I54: 25.9 | J54: 31.8 | K54: 39.5

Sheet Табл. А.2
A1: Табл. А.2 СП 30.13330.2020, п. 1 «Жилые здания квартирного типа» — нормы на 1 жителя
A2: Жилые здания квартирного типа | B2: q_u tot, л/сут | C2: q_u h, л/сут | D2: q_hr,u tot, л/ч | E2: q_hr,u h, л/ч | F2: q_0 tot, л/с | G2: q_0 (c, h), л/с | H2: q_0,hr tot, л/ч | I2: q_0,hr (c, h), л/ч | J2: T, ч
A3: с водопроводом и канализацией без ванн | B3: 70 | C3: 0 | D3: 5 | E3: 0 | F3: 0.2 | G3: 0.2 | H3: 50 | I3: 50 | J3: 24
A4: с ваннами и водонагревателями на твёрдом топливе | B4: 110 | C4: 0 | D4: 8.1 | E4: 0 | F4: 0.3 | G4: 0.3 | H4: 300 | I4: 300 | J4: 24
A5: с ваннами и газовыми водонагревателями | B5: 120 | C5: 0 | D5: 8.7 | E5: 0 | F5: 0.3 | G5: 0.3 | H5: 300 | I5: 300 | J5: 24
A6: с ЦГВ, с умывальниками, мойками и душами | B6: 130 | C6: 50 | D6: 8.2 | E6: 4.5 | F6: 0.2 | G6: 0.14 | H6: 100 | I6: 60 | J6: 24
A7: с сидячими ваннами, оборудованными душами | B7: 160 | C7: 65 | D7: 10.3 | E7: 5.7 | F7: 0.3 | G7: 0.2 | H7: 300 | I7: 200 | J7: 24
A8: с ваннами длиной 1500–1700 мм, оборудованными душами | B8: 180 | C8: 70 | D8: 11.6 | E8: 6.5 | F8: 0.3 | G8: 0.2 | H8: 300 | I8: 200 | J8: 24
A9: свои значения (вписать в эту строку)
A11: Источник: СП 30.13330.2020, прил. А, табл. А.2 (значения сверены с методическими указаниями НИУ МГСУ 2024). Для другого вида здания впишите нормы в строку «свои значения» и выберите её на листе «Расчёт».
